{
  "version": 8,
  "blockIdVersion": 11,
  "anchorX": 0,
  "anchorY": 0,
  "anchorZ": 0,
  "blocks": [
    {
      "x": -8,
      "y": 2,
      "z": -4,
      "name": "Barrier"
    },
    {
      "x": -8,
      "y": 3,
      "z": -4,
      "name": "Barrier"
    },
    {
      "x": -8,
      "y": 2,
      "z": -3,
      "name": "Barrier"
    },
    {
      "x": -8,
      "y": 3,
      "z": -3,
      "name": "Barrier"
    },
    {
      "x": -8,
      "y": 1,
      "z": 0,
      "name": "Cloth_Block_Wool_Black"
    },
    {
      "x": -8,
      "y": 2,
      "z": 0,
      "name": "Cloth_Block_Wool_Black"
    },
    {
      "x": -8,
      "y": 3,
      "z": 0,
      "name": "Cloth_Block_Wool_Black"
    },
    {
      "x": -8,
      "y": 4,
      "z": 0,
      "name": "Cloth_Block_Wool_Black"
    },
    {
      "x": -8,
      "y": 2,
      "z": 3,
      "name": "Barrier"
    },
    {
      "x": -8,
      "y": 3,
      "z": 3,
      "name": "Barrier"
    },
    {
      "x": -8,
      "y": 2,
      "z": 4,
      "name": "Barrier"
    },
    {
      "x": -8,
      "y": 3,
      "z": 4,
      "name": "Barrier"
    },
    {
      "x": -7,
      "y": -1,
      "z": -7,
      "name": "Cloth_Block_Wool_Black"
    },
    {
      "x": -7,
      "y": 0,
      "z": -7,
      "name": "Cloth_Block_Wool_Black"
    },
    {
      "x": -7,
      "y": 1,
      "z": -7,
      "name": "Cloth_Block_Wool_Black"
    },
    {
      "x": -7,
      "y": 2,
      "z": -7,
      "name": "Cloth_Block_Wool_Black"
    },
    {
      "x": -7,
      "y": 3,
      "z": -7,
      "name": "Cloth_Block_Wool_Black"
    },
    {
      "x": -7,
      "y": 4,
      "z": -7,
      "name": "Cloth_Block_Wool_Black"
    },
    {
      "x": -7,
      "y": 5,
      "z": -7,
      "name": "Cloth_Block_Wool_Black"
    },
    {
      "x": -7,
      "y": 6,
      "z": -7,
      "name": "Cloth_Block_Wool_Black"
    },
    {
      "x": -7,
      "y": -1,
      "z": -6,
      "name": "Cloth_Block_Wool_Black"
    },
    {
      "x": -7,
      "y": 0,
      "z": -6,
      "name": "Cloth_Block_Wool_Black"
    },
    {
      "x": -7,
      "y": 1,
      "z": -6,
      "name": "Cloth_Block_Wool_Black"
    },
    {
      "x": -7,
      "y": 2,
      "z": -6,
      "name": "Cloth_Block_Wool_Black"
    },
    {
      "x": -7,
      "y": 3,
      "z": -6,
      "name": "Cloth_Block_Wool_Black"
    },
    {
      "x": -7,
      "y": 4,
      "z": -6,
      "name": "Cloth_Block_Wool_Black"
    },
    {
      "x": -7,
      "y": 5,
      "z": -6,
      "name": "Cloth_Block_Wool_Black"
    },
    {
      "x": -7,
      "y": 6,
      "z": -6,
      "name": "Cloth_Block_Wool_Black"
    },
    {
      "x": -7,
      "y": -2,
      "z": -5,
      "name": "Cloth_Block_Wool_Black"
    },
    {
      "x": -7,
      "y": -1,
      "z": -5,
      "name": "Cloth_Block_Wool_Black"
    },
    {
      "x": -7,
      "y": 0,
      "z": -5,
      "name": "Cloth_Block_Wool_Black"
    },
    {
      "x": -7,
      "y": 1,
      "z": -5,
      "name": "Wood_Blackwood_Beam",
      "rotation": 4
    },
    {
      "x": -7,
      "y": 2,
      "z": -5,
      "name": "Wood_Blackwood_Beam",
      "rotation": 4
    },
    {
      "x": -7,
      "y": 3,
      "z": -5,
      "name": "Wood_Blackwood_Beam",
      "rotation": 4
    },
    {
      "x": -7,
      "y": 4,
      "z": -5,
      "name": "Wood_Blackwood_Beam",
      "rotation": 4
    },
    {
      "x": -7,
      "y": 5,
      "z": -5,
      "name": "Cloth_Block_Wool_Black"
    },
    {
      "x": -7,
      "y": 6,
      "z": -5,
      "name": "Cloth_Block_Wool_Black"
    },
    {
      "x": -7,
      "y": 7,
      "z": -5,
      "name": "Cloth_Block_Wool_Black"
    },
    {
      "x": -7,
      "y": -2,
      "z": -4,
      "name": "Cloth_Block_Wool_Black"
    },
    {
      "x": -7,
      "y": -1,
      "z": -4,
      "name": "Cloth_Block_Wool_Black"
    },
    {
      "x": -7,
      "y": 0,
      "z": -4,
      "name": "Cloth_Block_Wool_Black"
    },
    {
      "x": -7,
      "y": 1,
      "z": -4,
      "name": "Wood_Blackwood_Beam",
      "rotation": 4
    },
    {
      "x": -7,
      "y": 2,
      "z": -4,
      "name": "Wood_Blackwood_Beam"
    },
    {
      "x": -7,
      "y": 3,
      "z": -4,
      "name": "Wood_Blackwood_Beam"
    },
    {
      "x": -7,
      "y": 4,
      "z": -4,
      "name": "Wood_Blackwood_Beam",
      "rotation": 4
    },
    {
      "x": -7,
      "y": 5,
      "z": -4,
      "name": "Cloth_Block_Wool_Black"
    },
    {
      "x": -7,
      "y": 6,
      "z": -4,
      "name": "Cloth_Block_Wool_Black"
    },
    {
      "x": -7,
      "y": 7,
      "z": -4,
      "name": "Cloth_Block_Wool_Black"
    },
    {
      "x": -7,
      "y": -2,
      "z": -3,
      "name": "Cloth_Block_Wool_Black"
    },
    {
      "x": -7,
      "y": -1,
      "z": -3,
      "name": "Cloth_Block_Wool_Black"
    },
    {
      "x": -7,
      "y": 0,
      "z": -3,
      "name": "Cloth_Block_Wool_Black"
    },
    {
      "x": -7,
      "y": 1,
      "z": -3,
      "name": "Wood_Blackwood_Beam",
      "rotation": 4
    },
    {
      "x": -7,
      "y": 2,
      "z": -3,
      "name": "Wood_Blackwood_Beam"
    },
    {
      "x": -7,
      "y": 3,
      "z": -3,
      "name": "Wood_Blackwood_Beam"
    },
    {
      "x": -7,
      "y": 4,
      "z": -3,
      "name": "Wood_Blackwood_Beam",
      "rotation": 4
    },
    {
      "x": -7,
      "y": 5,
      "z": -3,
      "name": "Cloth_Block_Wool_Black"
    },
    {
      "x": -7,
      "y": 6,
      "z": -3,
      "name": "Cloth_Block_Wool_Black"
    },
    {
      "x": -7,
      "y": 7,
      "z": -3,
      "name": "Cloth_Block_Wool_Black"
    },
    {
      "x": -7,
      "y": -2,
      "z": -2,
      "name": "Cloth_Block_Wool_Black"
    },
    {
      "x": -7,
      "y": -1,
      "z": -2,
      "name": "Cloth_Block_Wool_Black"
    },
    {
      "x": -7,
      "y": 0,
      "z": -2,
      "name": "Cloth_Block_Wool_Black"
    },
    {
      "x": -7,
      "y": 1,
      "z": -2,
      "name": "Wood_Blackwood_Beam",
      "rotation": 4
    },
    {
      "x": -7,
      "y": 2,
      "z": -2,
      "name": "Wood_Blackwood_Beam",
      "rotation": 4
    },
    {
      "x": -7,
      "y": 3,
      "z": -2,
      "name": "Wood_Blackwood_Beam",
      "rotation": 4
    },
    {
      "x": -7,
      "y": 4,
      "z": -2,
      "name": "Wood_Blackwood_Beam",
      "rotation": 4
    },
    {
      "x": -7,
      "y": 5,
      "z": -2,
      "name": "Cloth_Block_Wool_Black"
    },
    {
      "x": -7,
      "y": 6,
      "z": -2,
      "name": "Cloth_Block_Wool_Black"
    },
    {
      "x": -7,
      "y": 7,
      "z": -2,
      "name": "Cloth_Block_Wool_Black"
    },
    {
      "x": -7,
      "y": -2,
      "z": -1,
      "name": "Cloth_Block_Wool_Black"
    },
    {
      "x": -7,
      "y": -1,
      "z": -1,
      "name": "Cloth_Block_Wool_Black"
    },
    {
      "x": -7,
      "y": 0,
      "z": -1,
      "name": "Cloth_Block_Wool_Black"
    },
    {
      "x": -7,
      "y": 1,
      "z": -1,
      "name": "Cloth_Block_Wool_Black"
    },
    {
      "x": -7,
      "y": 2,
      "z": -1,
      "name": "Cloth_Block_Wool_Black"
    },
    {
      "x": -7,
      "y": 3,
      "z": -1,
      "name": "Cloth_Block_Wool_Black"
    },
    {
      "x": -7,
      "y": 4,
      "z": -1,
      "name": "Cloth_Block_Wool_Black"
    },
    {
      "x": -7,
      "y": 5,
      "z": -1,
      "name": "Cloth_Block_Wool_Black"
    },
    {
      "x": -7,
      "y": 6,
      "z": -1,
      "name": "Cloth_Block_Wool_Black"
    },
    {
      "x": -7,
      "y": 7,
      "z": -1,
      "name": "Cloth_Block_Wool_Black"
    },
    {
      "x": -7,
      "y": -1,
      "z": 0,
      "name": "Cloth_Block_Wool_Black"
    },
    {
      "x": -7,
      "y": 0,
      "z": 0,
      "name": "Cloth_Block_Wool_Black"
    },
    {
      "x": -7,
      "y": 1,
      "z": 0,
      "name": "Blue_Led_Beam"
    },
    {
      "x": -7,
      "y": 2,
      "z": 0,
      "name": "Blue_Led_Beam"
    },
    {
      "x": -7,
      "y": 3,
      "z": 0,
      "name": "Blue_Led_Beam"
    },
    {
      "x": -7,
      "y": 4,
      "z": 0,
      "name": "Blue_Led_Beam"
    },
    {
      "x": -7,
      "y": 5,
      "z": 0,
      "name": "Cloth_Block_Wool_Black"
    },
    {
      "x": -7,
      "y": 6,
      "z": 0,
      "name": "Cloth_Block_Wool_Black"
    },
    {
      "x": -7,
      "y": -2,
      "z": 1,
      "name": "Cloth_Block_Wool_Black"
    },
    {
      "x": -7,
      "y": -1,
      "z": 1,
      "name": "Cloth_Block_Wool_Black"
    },
    {
      "x": -7,
      "y": 0,
      "z": 1,
      "name": "Cloth_Block_Wool_Black"
    },
    {
      "x": -7,
      "y": 1,
      "z": 1,
      "name": "Cloth_Block_Wool_Black"
    },
    {
      "x": -7,
      "y": 2,
      "z": 1,
      "name": "Cloth_Block_Wool_Black"
    },
    {
      "x": -7,
      "y": 3,
      "z": 1,
      "name": "Cloth_Block_Wool_Black"
    },
    {
      "x": -7,
      "y": 4,
      "z": 1,
      "name": "Cloth_Block_Wool_Black"
    },
    {
      "x": -7,
      "y": 5,
      "z": 1,
      "name": "Cloth_Block_Wool_Black"
    },
    {
      "x": -7,
      "y": 6,
      "z": 1,
      "name": "Cloth_Block_Wool_Black"
    },
    {
      "x": -7,
      "y": 7,
      "z": 1,
      "name": "Cloth_Block_Wool_Black"
    },
    {
      "x": -7,
      "y": -2,
      "z": 2,
      "name": "Cloth_Block_Wool_Black"
    },
    {
      "x": -7,
      "y": -1,
      "z": 2,
      "name": "Cloth_Block_Wool_Black"
    },
    {
      "x": -7,
      "y": 0,
      "z": 2,
      "name": "Cloth_Block_Wool_Black"
    },
    {
      "x": -7,
      "y": 1,
      "z": 2,
      "name": "Wood_Blackwood_Beam",
      "rotation": 4
    },
    {
      "x": -7,
      "y": 2,
      "z": 2,
      "name": "Wood_Blackwood_Beam",
      "rotation": 4
    },
    {
      "x": -7,
      "y": 3,
      "z": 2,
      "name": "Wood_Blackwood_Beam",
      "rotation": 4
    },
    {
      "x": -7,
      "y": 4,
      "z": 2,
      "name": "Wood_Blackwood_Beam",
      "rotation": 4
    },
    {
      "x": -7,
      "y": 5,
      "z": 2,
      "name": "Cloth_Block_Wool_Black"
    },
    {
      "x": -7,
      "y": 6,
      "z": 2,
      "name": "Cloth_Block_Wool_Black"
    },
    {
      "x": -7,
      "y": 7,
      "z": 2,
      "name": "Cloth_Block_Wool_Black"
    },
    {
      "x": -7,
      "y": -2,
      "z": 3,
      "name": "Cloth_Block_Wool_Black"
    },
    {
      "x": -7,
      "y": -1,
      "z": 3,
      "name": "Cloth_Block_Wool_Black"
    },
    {
      "x": -7,
      "y": 0,
      "z": 3,
      "name": "Cloth_Block_Wool_Black"
    },
    {
      "x": -7,
      "y": 1,
      "z": 3,
      "name": "Wood_Blackwood_Beam",
      "rotation": 4
    },
    {
      "x": -7,
      "y": 2,
      "z": 3,
      "name": "Wood_Blackwood_Beam"
    },
    {
      "x": -7,
      "y": 3,
      "z": 3,
      "name": "Wood_Blackwood_Beam"
    },
    {
      "x": -7,
      "y": 4,
      "z": 3,
      "name": "Wood_Blackwood_Beam",
      "rotation": 4
    },
    {
      "x": -7,
      "y": 5,
      "z": 3,
      "name": "Cloth_Block_Wool_Black"
    },
    {
      "x": -7,
      "y": 6,
      "z": 3,
      "name": "Cloth_Block_Wool_Black"
    },
    {
      "x": -7,
      "y": 7,
      "z": 3,
      "name": "Cloth_Block_Wool_Black"
    },
    {
      "x": -7,
      "y": -2,
      "z": 4,
      "name": "Cloth_Block_Wool_Black"
    },
    {
      "x": -7,
      "y": -1,
      "z": 4,
      "name": "Cloth_Block_Wool_Black"
    },
    {
      "x": -7,
      "y": 0,
      "z": 4,
      "name": "Cloth_Block_Wool_Black"
    },
    {
      "x": -7,
      "y": 1,
      "z": 4,
      "name": "Wood_Blackwood_Beam",
      "rotation": 4
    },
    {
      "x": -7,
      "y": 2,
      "z": 4,
      "name": "Wood_Blackwood_Beam"
    },
    {
      "x": -7,
      "y": 3,
      "z": 4,
      "name": "Wood_Blackwood_Beam"
    },
    {
      "x": -7,
      "y": 4,
      "z": 4,
      "name": "Wood_Blackwood_Beam",
      "rotation": 4
    },
    {
      "x": -7,
      "y": 5,
      "z": 4,
      "name": "Cloth_Block_Wool_Black"
    },
    {
      "x": -7,
      "y": 6,
      "z": 4,
      "name": "Cloth_Block_Wool_Black"
    },
    {
      "x": -7,
      "y": 7,
      "z": 4,
      "name": "Cloth_Block_Wool_Black"
    },
    {
      "x": -7,
      "y": -2,
      "z": 5,
      "name": "Cloth_Block_Wool_Black"
    },
    {
      "x": -7,
      "y": -1,
      "z": 5,
      "name": "Cloth_Block_Wool_Black"
    },
    {
      "x": -7,
      "y": 0,
      "z": 5,
      "name": "Cloth_Block_Wool_Black"
    },
    {
      "x": -7,
      "y": 1,
      "z": 5,
      "name": "Wood_Blackwood_Beam",
      "rotation": 4
    },
    {
      "x": -7,
      "y": 2,
      "z": 5,
      "name": "Wood_Blackwood_Beam",
      "rotation": 4
    },
    {
      "x": -7,
      "y": 3,
      "z": 5,
      "name": "Wood_Blackwood_Beam",
      "rotation": 4
    },
    {
      "x": -7,
      "y": 4,
      "z": 5,
      "name": "Wood_Blackwood_Beam",
      "rotation": 4
    },
    {
      "x": -7,
      "y": 5,
      "z": 5,
      "name": "Cloth_Block_Wool_Black"
    },
    {
      "x": -7,
      "y": 6,
      "z": 5,
      "name": "Cloth_Block_Wool_Black"
    },
    {
      "x": -7,
      "y": 7,
      "z": 5,
      "name": "Cloth_Block_Wool_Black"
    },
    {
      "x": -7,
      "y": -1,
      "z": 6,
      "name": "Cloth_Block_Wool_Black"
    },
    {
      "x": -7,
      "y": 0,
      "z": 6,
      "name": "Cloth_Block_Wool_Black"
    },
    {
      "x": -7,
      "y": 1,
      "z": 6,
      "name": "Cloth_Block_Wool_Black"
    },
    {
      "x": -7,
      "y": 2,
      "z": 6,
      "name": "Cloth_Block_Wool_Black"
    },
    {
      "x": -7,
      "y": 3,
      "z": 6,
      "name": "Cloth_Block_Wool_Black"
    },
    {
      "x": -7,
      "y": 4,
      "z": 6,
      "name": "Cloth_Block_Wool_Black"
    },
    {
      "x": -7,
      "y": 5,
      "z": 6,
      "name": "Cloth_Block_Wool_Black"
    },
    {
      "x": -7,
      "y": 6,
      "z": 6,
      "name": "Cloth_Block_Wool_Black"
    },
    {
      "x": -7,
      "y": -1,
      "z": 7,
      "name": "Cloth_Block_Wool_Black"
    },
    {
      "x": -7,
      "y": 0,
      "z": 7,
      "name": "Cloth_Block_Wool_Black"
    },
    {
      "x": -7,
      "y": 1,
      "z": 7,
      "name": "Cloth_Block_Wool_Black"
    },
    {
      "x": -7,
      "y": 2,
      "z": 7,
      "name": "Cloth_Block_Wool_Black"
    },
    {
      "x": -7,
      "y": 3,
      "z": 7,
      "name": "Cloth_Block_Wool_Black"
    },
    {
      "x": -7,
      "y": 4,
      "z": 7,
      "name": "Cloth_Block_Wool_Black"
    },
    {
      "x": -7,
      "y": 5,
      "z": 7,
      "name": "Cloth_Block_Wool_Black"
    },
    {
      "x": -7,
      "y": 6,
      "z": 7,
      "name": "Cloth_Block_Wool_Black"
    },
    {
      "x": -6,
      "y": -1,
      "z": -7,
      "name": "Cloth_Block_Wool_Black"
    },
    {
      "x": -6,
      "y": 0,
      "z": -7,
      "name": "Cloth_Block_Wool_Black"
    },
    {
      "x": -6,
      "y": 1,
      "z": -7,
      "name": "Cloth_Block_Wool_Black"
    },
    {
      "x": -6,
      "y": 2,
      "z": -7,
      "name": "Cloth_Block_Wool_Black"
    },
    {
      "x": -6,
      "y": 3,
      "z": -7,
      "name": "Cloth_Block_Wool_Black"
    },
    {
      "x": -6,
      "y": 4,
      "z": -7,
      "name": "Cloth_Block_Wool_Black"
    },
    {
      "x": -6,
      "y": 5,
      "z": -7,
      "name": "Cloth_Block_Wool_Black"
    },
    {
      "x": -6,
      "y": 6,
      "z": -7,
      "name": "Cloth_Block_Wool_Black"
    },
    {
      "x": -6,
      "y": -2,
      "z": -6,
      "name": "Cloth_Block_Wool_Black"
    },
    {
      "x": -6,
      "y": -1,
      "z": -6,
      "name": "Cloth_Block_Wool_Black"
    },
    {
      "x": -6,
      "y": 0,
      "z": -6,
      "name": "Black_Cloth_Half"
    },
    {
      "x": -6,
      "y": 5,
      "z": -6,
      "name": "Black_Cloth_Half",
      "rotation": 8
    },
    {
      "x": -6,
      "y": 6,
      "z": -6,
      "name": "Cloth_Block_Wool_Black"
    },
    {
      "x": -6,
      "y": 7,
      "z": -6,
      "name": "Cloth_Block_Wool_Black"
    },
    {
      "x": -6,
      "y": -3,
      "z": -5,
      "name": "Cloth_Block_Wool_Black"
    },
    {
      "x": -6,
      "y": -2,
      "z": -5,
      "name": "Blue_Led_Beam",
      "rotation": 4
    },
    {
      "x": -6,
      "y": -1,
      "z": -5,
      "name": "Barrier"
    },
    {
      "x": -6,
      "y": 6,
      "z": -5,
      "name": "Barrier"
    },
    {
      "x": -6,
      "y": 7,
      "z": -5,
      "name": "Blue_Led_Beam",
      "rotation": 4
    },
    {
      "x": -6,
      "y": 8,
      "z": -5,
      "name": "Cloth_Block_Wool_Black"
    },
    {
      "x": -6,
      "y": -3,
      "z": -4,
      "name": "Cloth_Block_Wool_Black"
    },
    {
      "x": -6,
      "y": -2,
      "z": -4,
      "name": "Blue_Led_Beam",
      "rotation": 4
    },
    {
      "x": -6,
      "y": -1,
      "z": -4,
      "name": "Barrier"
    },
    {
      "x": -6,
      "y": 6,
      "z": -4,
      "name": "Barrier"
    },
    {
      "x": -6,
      "y": 7,
      "z": -4,
      "name": "Blue_Led_Beam",
      "rotation": 4
    },
    {
      "x": -6,
      "y": 8,
      "z": -4,
      "name": "Cloth_Block_Wool_Black"
    },
    {
      "x": -6,
      "y": -3,
      "z": -3,
      "name": "Cloth_Block_Wool_Black"
    },
    {
      "x": -6,
      "y": -2,
      "z": -3,
      "name": "Blue_Led_Beam",
      "rotation": 4
    },
    {
      "x": -6,
      "y": -1,
      "z": -3,
      "name": "Barrier"
    },
    {
      "x": -6,
      "y": 6,
      "z": -3,
      "name": "Barrier"
    },
    {
      "x": -6,
      "y": 7,
      "z": -3,
      "name": "Blue_Led_Beam",
      "rotation": 4
    },
    {
      "x": -6,
      "y": 8,
      "z": -3,
      "name": "Cloth_Block_Wool_Black"
    },
    {
      "x": -6,
      "y": -3,
      "z": -2,
      "name": "Cloth_Block_Wool_Black"
    },
    {
      "x": -6,
      "y": -2,
      "z": -2,
      "name": "Blue_Led_Beam",
      "rotation": 4
    },
    {
      "x": -6,
      "y": -1,
      "z": -2,
      "name": "Barrier"
    },
    {
      "x": -6,
      "y": 6,
      "z": -2,
      "name": "Barrier"
    },
    {
      "x": -6,
      "y": 7,
      "z": -2,
      "name": "Blue_Led_Beam",
      "rotation": 4
    },
    {
      "x": -6,
      "y": 8,
      "z": -2,
      "name": "Cloth_Block_Wool_Black"
    },
    {
      "x": -6,
      "y": -3,
      "z": -1,
      "name": "Cloth_Block_Wool_Black"
    },
    {
      "x": -6,
      "y": -2,
      "z": -1,
      "name": "Blue_Led_Beam",
      "rotation": 4
    },
    {
      "x": -6,
      "y": -1,
      "z": -1,
      "name": "Barrier"
    },
    {
      "x": -6,
      "y": 6,
      "z": -1,
      "name": "Barrier"
    },
    {
      "x": -6,
      "y": 7,
      "z": -1,
      "name": "Blue_Led_Beam",
      "rotation": 4
    },
    {
      "x": -6,
      "y": 8,
      "z": -1,
      "name": "Cloth_Block_Wool_Black"
    },
    {
      "x": -6,
      "y": -2,
      "z": 0,
      "name": "Cloth_Block_Wool_Black"
    },
    {
      "x": -6,
      "y": -1,
      "z": 0,
      "name": "Cloth_Block_Wool_Black"
    },
    {
      "x": -6,
      "y": 0,
      "z": 0,
      "name": "Black_Cloth_Half"
    },
    {
      "x": -6,
      "y": 5,
      "z": 0,
      "name": "Black_Cloth_Half",
      "rotation": 8
    },
    {
      "x": -6,
      "y": 6,
      "z": 0,
      "name": "Cloth_Block_Wool_Black"
    },
    {
      "x": -6,
      "y": 7,
      "z": 0,
      "name": "Cloth_Block_Wool_Black"
    },
    {
      "x": -6,
      "y": -3,
      "z": 1,
      "name": "Cloth_Block_Wool_Black"
    },
    {
      "x": -6,
      "y": -2,
      "z": 1,
      "name": "Blue_Led_Beam",
      "rotation": 4
    },
    {
      "x": -6,
      "y": -1,
      "z": 1,
      "name": "Barrier"
    },
    {
      "x": -6,
      "y": 6,
      "z": 1,
      "name": "Barrier"
    },
    {
      "x": -6,
      "y": 7,
      "z": 1,
      "name": "Blue_Led_Beam",
      "rotation": 4
    },
    {
      "x": -6,
      "y": 8,
      "z": 1,
      "name": "Cloth_Block_Wool_Black"
    },
    {
      "x": -6,
      "y": -3,
      "z": 2,
      "name": "Cloth_Block_Wool_Black"
    },
    {
      "x": -6,
      "y": -2,
      "z": 2,
      "name": "Blue_Led_Beam",
      "rotation": 4
    },
    {
      "x": -6,
      "y": -1,
      "z": 2,
      "name": "Barrier"
    },
    {
      "x": -6,
      "y": 6,
      "z": 2,
      "name": "Barrier"
    },
    {
      "x": -6,
      "y": 7,
      "z": 2,
      "name": "Blue_Led_Beam",
      "rotation": 4
    },
    {
      "x": -6,
      "y": 8,
      "z": 2,
      "name": "Cloth_Block_Wool_Black"
    },
    {
      "x": -6,
      "y": -3,
      "z": 3,
      "name": "Cloth_Block_Wool_Black"
    },
    {
      "x": -6,
      "y": -2,
      "z": 3,
      "name": "Blue_Led_Beam",
      "rotation": 4
    },
    {
      "x": -6,
      "y": -1,
      "z": 3,
      "name": "Barrier"
    },
    {
      "x": -6,
      "y": 6,
      "z": 3,
      "name": "Barrier"
    },
    {
      "x": -6,
      "y": 7,
      "z": 3,
      "name": "Blue_Led_Beam",
      "rotation": 4
    },
    {
      "x": -6,
      "y": 8,
      "z": 3,
      "name": "Cloth_Block_Wool_Black"
    },
    {
      "x": -6,
      "y": -3,
      "z": 4,
      "name": "Cloth_Block_Wool_Black"
    },
    {
      "x": -6,
      "y": -2,
      "z": 4,
      "name": "Blue_Led_Beam",
      "rotation": 4
    },
    {
      "x": -6,
      "y": -1,
      "z": 4,
      "name": "Barrier"
    },
    {
      "x": -6,
      "y": 6,
      "z": 4,
      "name": "Barrier"
    },
    {
      "x": -6,
      "y": 7,
      "z": 4,
      "name": "Blue_Led_Beam",
      "rotation": 4
    },
    {
      "x": -6,
      "y": 8,
      "z": 4,
      "name": "Cloth_Block_Wool_Black"
    },
    {
      "x": -6,
      "y": -3,
      "z": 5,
      "name": "Cloth_Block_Wool_Black"
    },
    {
      "x": -6,
      "y": -2,
      "z": 5,
      "name": "Blue_Led_Beam",
      "rotation": 4
    },
    {
      "x": -6,
      "y": -1,
      "z": 5,
      "name": "Barrier"
    },
    {
      "x": -6,
      "y": 6,
      "z": 5,
      "name": "Barrier"
    },
    {
      "x": -6,
      "y": 7,
      "z": 5,
      "name": "Blue_Led_Beam",
      "rotation": 4
    },
    {
      "x": -6,
      "y": 8,
      "z": 5,
      "name": "Cloth_Block_Wool_Black"
    },
    {
      "x": -6,
      "y": -2,
      "z": 6,
      "name": "Cloth_Block_Wool_Black"
    },
    {
      "x": -6,
      "y": -1,
      "z": 6,
      "name": "Cloth_Block_Wool_Black"
    },
    {
      "x": -6,
      "y": 0,
      "z": 6,
      "name": "Black_Cloth_Half"
    },
    {
      "x": -6,
      "y": 5,
      "z": 6,
      "name": "Black_Cloth_Half",
      "rotation": 8
    },
    {
      "x": -6,
      "y": 6,
      "z": 6,
      "name": "Cloth_Block_Wool_Black"
    },
    {
      "x": -6,
      "y": 7,
      "z": 6,
      "name": "Cloth_Block_Wool_Black"
    },
    {
      "x": -6,
      "y": -1,
      "z": 7,
      "name": "Cloth_Block_Wool_Black"
    },
    {
      "x": -6,
      "y": 0,
      "z": 7,
      "name": "Cloth_Block_Wool_Black"
    },
    {
      "x": -6,
      "y": 1,
      "z": 7,
      "name": "Cloth_Block_Wool_Black"
    },
    {
      "x": -6,
      "y": 2,
      "z": 7,
      "name": "Cloth_Block_Wool_Black"
    },
    {
      "x": -6,
      "y": 3,
      "z": 7,
      "name": "Cloth_Block_Wool_Black"
    },
    {
      "x": -6,
      "y": 4,
      "z": 7,
      "name": "Cloth_Block_Wool_Black"
    },
    {
      "x": -6,
      "y": 5,
      "z": 7,
      "name": "Cloth_Block_Wool_Black"
    },
    {
      "x": -6,
      "y": 6,
      "z": 7,
      "name": "Cloth_Block_Wool_Black"
    },
    {
      "x": -5,
      "y": -2,
      "z": -7,
      "name": "Cloth_Block_Wool_Black"
    },
    {
      "x": -5,
      "y": -1,
      "z": -7,
      "name": "Cloth_Block_Wool_Black"
    },
    {
      "x": -5,
      "y": 0,
      "z": -7,
      "name": "Cloth_Block_Wool_Black"
    },
    {
      "x": -5,
      "y": 1,
      "z": -7,
      "name": "Wood_Blackwood_Beam",
      "rotation": 5
    },
    {
      "x": -5,
      "y": 2,
      "z": -7,
      "name": "Wood_Blackwood_Beam",
      "rotation": 5
    },
    {
      "x": -5,
      "y": 3,
      "z": -7,
      "name": "Wood_Blackwood_Beam",
      "rotation": 5
    },
    {
      "x": -5,
      "y": 4,
      "z": -7,
      "name": "Wood_Blackwood_Beam",
      "rotation": 5
    },
    {
      "x": -5,
      "y": 5,
      "z": -7,
      "name": "Cloth_Block_Wool_Black"
    },
    {
      "x": -5,
      "y": 6,
      "z": -7,
      "name": "Cloth_Block_Wool_Black"
    },
    {
      "x": -5,
      "y": 7,
      "z": -7,
      "name": "Cloth_Block_Wool_Black"
    },
    {
      "x": -5,
      "y": -3,
      "z": -6,
      "name": "Cloth_Block_Wool_Black"
    },
    {
      "x": -5,
      "y": -2,
      "z": -6,
      "name": "Blue_Led_Beam",
      "rotation": 5
    },
    {
      "x": -5,
      "y": -1,
      "z": -6,
      "name": "Barrier"
    },
    {
      "x": -5,
      "y": 6,
      "z": -6,
      "name": "Barrier"
    },
    {
      "x": -5,
      "y": 7,
      "z": -6,
      "name": "Blue_Led_Beam",
      "rotation": 5
    },
    {
      "x": -5,
      "y": 8,
      "z": -6,
      "name": "Cloth_Block_Wool_Black"
    },
    {
      "x": -5,
      "y": -2,
      "z": -5,
      "name": "Cloth_Block_Wool_Black"
    },
    {
      "x": -5,
      "y": -1,
      "z": -5,
      "name": "Cloth_Block_Wool_Black"
    },
    {
      "x": -5,
      "y": 6,
      "z": -5,
      "name": "Cloth_Block_Wool_Black"
    },
    {
      "x": -5,
      "y": 7,
      "z": -5,
      "name": "Cloth_Block_Wool_Black"
    },
    {
      "x": -5,
      "y": -2,
      "z": -4,
      "name": "Cloth_Block_Wool_Black"
    },
    {
      "x": -5,
      "y": -1,
      "z": -4,
      "name": "Cloth_Block_Wool_Black"
    },
    {
      "x": -5,
      "y": 6,
      "z": -4,
      "name": "Cloth_Block_Wool_Black"
    },
    {
      "x": -5,
      "y": 7,
      "z": -4,
      "name": "Cloth_Block_Wool_Black"
    },
    {
      "x": -5,
      "y": -2,
      "z": -3,
      "name": "Cloth_Block_Wool_Black"
    },
    {
      "x": -5,
      "y": -1,
      "z": -3,
      "name": "Cloth_Block_Wool_Black"
    },
    {
      "x": -5,
      "y": 6,
      "z": -3,
      "name": "Cloth_Block_Wool_Black"
    },
    {
      "x": -5,
      "y": 7,
      "z": -3,
      "name": "Cloth_Block_Wool_Black"
    },
    {
      "x": -5,
      "y": -2,
      "z": -2,
      "name": "Cloth_Block_Wool_Black"
    },
    {
      "x": -5,
      "y": -1,
      "z": -2,
      "name": "Cloth_Block_Wool_Black"
    },
    {
      "x": -5,
      "y": 6,
      "z": -2,
      "name": "Cloth_Block_Wool_Black"
    },
    {
      "x": -5,
      "y": 7,
      "z": -2,
      "name": "Cloth_Block_Wool_Black"
    },
    {
      "x": -5,
      "y": -2,
      "z": -1,
      "name": "Cloth_Block_Wool_Black"
    },
    {
      "x": -5,
      "y": -1,
      "z": -1,
      "name": "Cloth_Block_Wool_Black"
    },
    {
      "x": -5,
      "y": 6,
      "z": -1,
      "name": "Cloth_Block_Wool_Black"
    },
    {
      "x": -5,
      "y": 7,
      "z": -1,
      "name": "Cloth_Block_Wool_Black"
    },
    {
      "x": -5,
      "y": -1,
      "z": 0,
      "name": "Cloth_Block_Wool_Black"
    },
    {
      "x": -5,
      "y": 6,
      "z": 0,
      "name": "Cloth_Block_Wool_Black"
    },
    {
      "x": -5,
      "y": -2,
      "z": 1,
      "name": "Cloth_Block_Wool_Black"
    },
    {
      "x": -5,
      "y": -1,
      "z": 1,
      "name": "Cloth_Block_Wool_Black"
    },
    {
      "x": -5,
      "y": 6,
      "z": 1,
      "name": "Cloth_Block_Wool_Black"
    },
    {
      "x": -5,
      "y": 7,
      "z": 1,
      "name": "Cloth_Block_Wool_Black"
    },
    {
      "x": -5,
      "y": -2,
      "z": 2,
      "name": "Cloth_Block_Wool_Black"
    },
    {
      "x": -5,
      "y": -1,
      "z": 2,
      "name": "Cloth_Block_Wool_Black"
    },
    {
      "x": -5,
      "y": 6,
      "z": 2,
      "name": "Cloth_Block_Wool_Black"
    },
    {
      "x": -5,
      "y": 7,
      "z": 2,
      "name": "Cloth_Block_Wool_Black"
    },
    {
      "x": -5,
      "y": -2,
      "z": 3,
      "name": "Cloth_Block_Wool_Black"
    },
    {
      "x": -5,
      "y": -1,
      "z": 3,
      "name": "Cloth_Block_Wool_Black"
    },
    {
      "x": -5,
      "y": 6,
      "z": 3,
      "name": "Cloth_Block_Wool_Black"
    },
    {
      "x": -5,
      "y": 7,
      "z": 3,
      "name": "Cloth_Block_Wool_Black"
    },
    {
      "x": -5,
      "y": -2,
      "z": 4,
      "name": "Cloth_Block_Wool_Black"
    },
    {
      "x": -5,
      "y": -1,
      "z": 4,
      "name": "Cloth_Block_Wool_Black"
    },
    {
      "x": -5,
      "y": 6,
      "z": 4,
      "name": "Cloth_Block_Wool_Black"
    },
    {
      "x": -5,
      "y": 7,
      "z": 4,
      "name": "Cloth_Block_Wool_Black"
    },
    {
      "x": -5,
      "y": -2,
      "z": 5,
      "name": "Cloth_Block_Wool_Black"
    },
    {
      "x": -5,
      "y": -1,
      "z": 5,
      "name": "Cloth_Block_Wool_Black"
    },
    {
      "x": -5,
      "y": 6,
      "z": 5,
      "name": "Cloth_Block_Wool_Black"
    },
    {
      "x": -5,
      "y": 7,
      "z": 5,
      "name": "Cloth_Block_Wool_Black"
    },
    {
      "x": -5,
      "y": -3,
      "z": 6,
      "name": "Cloth_Block_Wool_Black"
    },
    {
      "x": -5,
      "y": -2,
      "z": 6,
      "name": "Blue_Led_Beam",
      "rotation": 5
    },
    {
      "x": -5,
      "y": -1,
      "z": 6,
      "name": "Barrier"
    },
    {
      "x": -5,
      "y": 6,
      "z": 6,
      "name": "Barrier"
    },
    {
      "x": -5,
      "y": 7,
      "z": 6,
      "name": "Blue_Led_Beam",
      "rotation": 5
    },
    {
      "x": -5,
      "y": 8,
      "z": 6,
      "name": "Cloth_Block_Wool_Black"
    },
    {
      "x": -5,
      "y": -2,
      "z": 7,
      "name": "Cloth_Block_Wool_Black"
    },
    {
      "x": -5,
      "y": -1,
      "z": 7,
      "name": "Cloth_Block_Wool_Black"
    },
    {
      "x": -5,
      "y": 0,
      "z": 7,
      "name": "Cloth_Block_Wool_Black"
    },
    {
      "x": -5,
      "y": 1,
      "z": 7,
      "name": "Wood_Blackwood_Beam",
      "rotation": 5
    },
    {
      "x": -5,
      "y": 2,
      "z": 7,
      "name": "Wood_Blackwood_Beam",
      "rotation": 5
    },
    {
      "x": -5,
      "y": 3,
      "z": 7,
      "name": "Wood_Blackwood_Beam",
      "rotation": 5
    },
    {
      "x": -5,
      "y": 4,
      "z": 7,
      "name": "Wood_Blackwood_Beam",
      "rotation": 5
    },
    {
      "x": -5,
      "y": 5,
      "z": 7,
      "name": "Cloth_Block_Wool_Black"
    },
    {
      "x": -5,
      "y": 6,
      "z": 7,
      "name": "Cloth_Block_Wool_Black"
    },
    {
      "x": -5,
      "y": 7,
      "z": 7,
      "name": "Cloth_Block_Wool_Black"
    },
    {
      "x": -4,
      "y": 2,
      "z": -8,
      "name": "Barrier"
    },
    {
      "x": -4,
      "y": 3,
      "z": -8,
      "name": "Barrier"
    },
    {
      "x": -4,
      "y": -2,
      "z": -7,
      "name": "Cloth_Block_Wool_Black"
    },
    {
      "x": -4,
      "y": -1,
      "z": -7,
      "name": "Cloth_Block_Wool_Black"
    },
    {
      "x": -4,
      "y": 0,
      "z": -7,
      "name": "Cloth_Block_Wool_Black"
    },
    {
      "x": -4,
      "y": 1,
      "z": -7,
      "name": "Wood_Blackwood_Beam",
      "rotation": 5
    },
    {
      "x": -4,
      "y": 2,
      "z": -7,
      "name": "Wood_Blackwood_Beam"
    },
    {
      "x": -4,
      "y": 3,
      "z": -7,
      "name": "Wood_Blackwood_Beam"
    },
    {
      "x": -4,
      "y": 4,
      "z": -7,
      "name": "Wood_Blackwood_Beam",
      "rotation": 5
    },
    {
      "x": -4,
      "y": 5,
      "z": -7,
      "name": "Cloth_Block_Wool_Black"
    },
    {
      "x": -4,
      "y": 6,
      "z": -7,
      "name": "Cloth_Block_Wool_Black"
    },
    {
      "x": -4,
      "y": 7,
      "z": -7,
      "name": "Cloth_Block_Wool_Black"
    },
    {
      "x": -4,
      "y": -3,
      "z": -6,
      "name": "Cloth_Block_Wool_Black"
    },
    {
      "x": -4,
      "y": -2,
      "z": -6,
      "name": "Blue_Led_Beam",
      "rotation": 5
    },
    {
      "x": -4,
      "y": -1,
      "z": -6,
      "name": "Barrier"
    },
    {
      "x": -4,
      "y": 6,
      "z": -6,
      "name": "Barrier"
    },
    {
      "x": -4,
      "y": 7,
      "z": -6,
      "name": "Blue_Led_Beam",
      "rotation": 5
    },
    {
      "x": -4,
      "y": 8,
      "z": -6,
      "name": "Cloth_Block_Wool_Black"
    },
    {
      "x": -4,
      "y": -2,
      "z": -5,
      "name": "Cloth_Block_Wool_Black"
    },
    {
      "x": -4,
      "y": -1,
      "z": -5,
      "name": "Cloth_Block_Wool_Black"
    },
    {
      "x": -4,
      "y": 6,
      "z": -5,
      "name": "Cloth_Block_Wool_Black"
    },
    {
      "x": -4,
      "y": 7,
      "z": -5,
      "name": "Cloth_Block_Wool_Black"
    },
    {
      "x": -4,
      "y": -1,
      "z": -4,
      "name": "Cloth_Block_Wool_Black"
    },
    {
      "x": -4,
      "y": 6,
      "z": -4,
      "name": "Cloth_Block_Wool_Black"
    },
    {
      "x": -4,
      "y": -1,
      "z": -3,
      "name": "Cloth_Block_Wool_Black"
    },
    {
      "x": -4,
      "y": 6,
      "z": -3,
      "name": "Cloth_Block_Wool_Black"
    },
    {
      "x": -4,
      "y": -1,
      "z": -2,
      "name": "Cloth_Block_Wool_Black"
    },
    {
      "x": -4,
      "y": 6,
      "z": -2,
      "name": "Cloth_Block_Wool_Black"
    },
    {
      "x": -4,
      "y": -1,
      "z": -1,
      "name": "Cloth_Block_Wool_Black"
    },
    {
      "x": -4,
      "y": 6,
      "z": -1,
      "name": "Cloth_Block_Wool_Black"
    },
    {
      "x": -4,
      "y": -1,
      "z": 0,
      "name": "Cloth_Block_Wool_Black"
    },
    {
      "x": -4,
      "y": 6,
      "z": 0,
      "name": "Cloth_Block_Wool_Black"
    },
    {
      "x": -4,
      "y": -1,
      "z": 1,
      "name": "Cloth_Block_Wool_Black"
    },
    {
      "x": -4,
      "y": 6,
      "z": 1,
      "name": "Cloth_Block_Wool_Black"
    },
    {
      "x": -4,
      "y": -1,
      "z": 2,
      "name": "Cloth_Block_Wool_Black"
    },
    {
      "x": -4,
      "y": 6,
      "z": 2,
      "name": "Cloth_Block_Wool_Black"
    },
    {
      "x": -4,
      "y": -1,
      "z": 3,
      "name": "Cloth_Block_Wool_Black"
    },
    {
      "x": -4,
      "y": 6,
      "z": 3,
      "name": "Cloth_Block_Wool_Black"
    },
    {
      "x": -4,
      "y": -1,
      "z": 4,
      "name": "Cloth_Block_Wool_Black"
    },
    {
      "x": -4,
      "y": 6,
      "z": 4,
      "name": "Cloth_Block_Wool_Black"
    },
    {
      "x": -4,
      "y": -2,
      "z": 5,
      "name": "Cloth_Block_Wool_Black"
    },
    {
      "x": -4,
      "y": -1,
      "z": 5,
      "name": "Cloth_Block_Wool_Black"
    },
    {
      "x": -4,
      "y": 6,
      "z": 5,
      "name": "Cloth_Block_Wool_Black"
    },
    {
      "x": -4,
      "y": 7,
      "z": 5,
      "name": "Cloth_Block_Wool_Black"
    },
    {
      "x": -4,
      "y": -3,
      "z": 6,
      "name": "Cloth_Block_Wool_Black"
    },
    {
      "x": -4,
      "y": -2,
      "z": 6,
      "name": "Blue_Led_Beam",
      "rotation": 5
    },
    {
      "x": -4,
      "y": -1,
      "z": 6,
      "name": "Barrier"
    },
    {
      "x": -4,
      "y": 6,
      "z": 6,
      "name": "Barrier"
    },
    {
      "x": -4,
      "y": 7,
      "z": 6,
      "name": "Blue_Led_Beam",
      "rotation": 5
    },
    {
      "x": -4,
      "y": 8,
      "z": 6,
      "name": "Cloth_Block_Wool_Black"
    },
    {
      "x": -4,
      "y": -2,
      "z": 7,
      "name": "Cloth_Block_Wool_Black"
    },
    {
      "x": -4,
      "y": -1,
      "z": 7,
      "name": "Cloth_Block_Wool_Black"
    },
    {
      "x": -4,
      "y": 0,
      "z": 7,
      "name": "Cloth_Block_Wool_Black"
    },
    {
      "x": -4,
      "y": 1,
      "z": 7,
      "name": "Wood_Blackwood_Beam",
      "rotation": 5
    },
    {
      "x": -4,
      "y": 2,
      "z": 7,
      "name": "Wood_Blackwood_Beam"
    },
    {
      "x": -4,
      "y": 3,
      "z": 7,
      "name": "Wood_Blackwood_Beam"
    },
    {
      "x": -4,
      "y": 4,
      "z": 7,
      "name": "Wood_Blackwood_Beam",
      "rotation": 5
    },
    {
      "x": -4,
      "y": 5,
      "z": 7,
      "name": "Cloth_Block_Wool_Black"
    },
    {
      "x": -4,
      "y": 6,
      "z": 7,
      "name": "Cloth_Block_Wool_Black"
    },
    {
      "x": -4,
      "y": 7,
      "z": 7,
      "name": "Cloth_Block_Wool_Black"
    },
    {
      "x": -4,
      "y": 2,
      "z": 8,
      "name": "Barrier"
    },
    {
      "x": -4,
      "y": 3,
      "z": 8,
      "name": "Barrier"
    },
    {
      "x": -3,
      "y": 2,
      "z": -8,
      "name": "Barrier"
    },
    {
      "x": -3,
      "y": 3,
      "z": -8,
      "name": "Barrier"
    },
    {
      "x": -3,
      "y": -2,
      "z": -7,
      "name": "Cloth_Block_Wool_Black"
    },
    {
      "x": -3,
      "y": -1,
      "z": -7,
      "name": "Cloth_Block_Wool_Black"
    },
    {
      "x": -3,
      "y": 0,
      "z": -7,
      "name": "Cloth_Block_Wool_Black"
    },
    {
      "x": -3,
      "y": 1,
      "z": -7,
      "name": "Wood_Blackwood_Beam",
      "rotation": 5
    },
    {
      "x": -3,
      "y": 2,
      "z": -7,
      "name": "Wood_Blackwood_Beam"
    },
    {
      "x": -3,
      "y": 3,
      "z": -7,
      "name": "Wood_Blackwood_Beam"
    },
    {
      "x": -3,
      "y": 4,
      "z": -7,
      "name": "Wood_Blackwood_Beam",
      "rotation": 5
    },
    {
      "x": -3,
      "y": 5,
      "z": -7,
      "name": "Cloth_Block_Wool_Black"
    },
    {
      "x": -3,
      "y": 6,
      "z": -7,
      "name": "Cloth_Block_Wool_Black"
    },
    {
      "x": -3,
      "y": 7,
      "z": -7,
      "name": "Cloth_Block_Wool_Black"
    },
    {
      "x": -3,
      "y": -3,
      "z": -6,
      "name": "Cloth_Block_Wool_Black"
    },
    {
      "x": -3,
      "y": -2,
      "z": -6,
      "name": "Blue_Led_Beam",
      "rotation": 5
    },
    {
      "x": -3,
      "y": -1,
      "z": -6,
      "name": "Barrier"
    },
    {
      "x": -3,
      "y": 6,
      "z": -6,
      "name": "Barrier"
    },
    {
      "x": -3,
      "y": 7,
      "z": -6,
      "name": "Blue_Led_Beam",
      "rotation": 5
    },
    {
      "x": -3,
      "y": 8,
      "z": -6,
      "name": "Cloth_Block_Wool_Black"
    },
    {
      "x": -3,
      "y": -2,
      "z": -5,
      "name": "Cloth_Block_Wool_Black"
    },
    {
      "x": -3,
      "y": -1,
      "z": -5,
      "name": "Cloth_Block_Wool_Black"
    },
    {
      "x": -3,
      "y": 6,
      "z": -5,
      "name": "Cloth_Block_Wool_Black"
    },
    {
      "x": -3,
      "y": 7,
      "z": -5,
      "name": "Cloth_Block_Wool_Black"
    },
    {
      "x": -3,
      "y": -1,
      "z": -4,
      "name": "Cloth_Block_Wool_Black"
    },
    {
      "x": -3,
      "y": 6,
      "z": -4,
      "name": "Cloth_Block_Wool_Black"
    },
    {
      "x": -3,
      "y": -1,
      "z": -3,
      "name": "Cloth_Block_Wool_Black"
    },
    {
      "x": -3,
      "y": 6,
      "z": -3,
      "name": "Cloth_Block_Wool_Black"
    },
    {
      "x": -3,
      "y": -1,
      "z": -2,
      "name": "Cloth_Block_Wool_Black"
    },
    {
      "x": -3,
      "y": 6,
      "z": -2,
      "name": "Cloth_Block_Wool_Black"
    },
    {
      "x": -3,
      "y": -1,
      "z": -1,
      "name": "Cloth_Block_Wool_Black"
    },
    {
      "x": -3,
      "y": 6,
      "z": -1,
      "name": "Cloth_Block_Wool_Black"
    },
    {
      "x": -3,
      "y": -1,
      "z": 0,
      "name": "Cloth_Block_Wool_Black"
    },
    {
      "x": -3,
      "y": 6,
      "z": 0,
      "name": "Cloth_Block_Wool_Black"
    },
    {
      "x": -3,
      "y": -1,
      "z": 1,
      "name": "Cloth_Block_Wool_Black"
    },
    {
      "x": -3,
      "y": 6,
      "z": 1,
      "name": "Cloth_Block_Wool_Black"
    },
    {
      "x": -3,
      "y": -1,
      "z": 2,
      "name": "Cloth_Block_Wool_Black"
    },
    {
      "x": -3,
      "y": 6,
      "z": 2,
      "name": "Cloth_Block_Wool_Black"
    },
    {
      "x": -3,
      "y": -1,
      "z": 3,
      "name": "Cloth_Block_Wool_Black"
    },
    {
      "x": -3,
      "y": 6,
      "z": 3,
      "name": "Cloth_Block_Wool_Black"
    },
    {
      "x": -3,
      "y": -1,
      "z": 4,
      "name": "Cloth_Block_Wool_Black"
    },
    {
      "x": -3,
      "y": 6,
      "z": 4,
      "name": "Cloth_Block_Wool_Black"
    },
    {
      "x": -3,
      "y": -2,
      "z": 5,
      "name": "Cloth_Block_Wool_Black"
    },
    {
      "x": -3,
      "y": -1,
      "z": 5,
      "name": "Cloth_Block_Wool_Black"
    },
    {
      "x": -3,
      "y": 6,
      "z": 5,
      "name": "Cloth_Block_Wool_Black"
    },
    {
      "x": -3,
      "y": 7,
      "z": 5,
      "name": "Cloth_Block_Wool_Black"
    },
    {
      "x": -3,
      "y": -3,
      "z": 6,
      "name": "Cloth_Block_Wool_Black"
    },
    {
      "x": -3,
      "y": -2,
      "z": 6,
      "name": "Blue_Led_Beam",
      "rotation": 5
    },
    {
      "x": -3,
      "y": -1,
      "z": 6,
      "name": "Barrier"
    },
    {
      "x": -3,
      "y": 6,
      "z": 6,
      "name": "Barrier"
    },
    {
      "x": -3,
      "y": 7,
      "z": 6,
      "name": "Blue_Led_Beam",
      "rotation": 5
    },
    {
      "x": -3,
      "y": 8,
      "z": 6,
      "name": "Cloth_Block_Wool_Black"
    },
    {
      "x": -3,
      "y": -2,
      "z": 7,
      "name": "Cloth_Block_Wool_Black"
    },
    {
      "x": -3,
      "y": -1,
      "z": 7,
      "name": "Cloth_Block_Wool_Black"
    },
    {
      "x": -3,
      "y": 0,
      "z": 7,
      "name": "Cloth_Block_Wool_Black"
    },
    {
      "x": -3,
      "y": 1,
      "z": 7,
      "name": "Wood_Blackwood_Beam",
      "rotation": 5
    },
    {
      "x": -3,
      "y": 2,
      "z": 7,
      "name": "Wood_Blackwood_Beam"
    },
    {
      "x": -3,
      "y": 3,
      "z": 7,
      "name": "Wood_Blackwood_Beam"
    },
    {
      "x": -3,
      "y": 4,
      "z": 7,
      "name": "Wood_Blackwood_Beam",
      "rotation": 5
    },
    {
      "x": -3,
      "y": 5,
      "z": 7,
      "name": "Cloth_Block_Wool_Black"
    },
    {
      "x": -3,
      "y": 6,
      "z": 7,
      "name": "Cloth_Block_Wool_Black"
    },
    {
      "x": -3,
      "y": 7,
      "z": 7,
      "name": "Cloth_Block_Wool_Black"
    },
    {
      "x": -3,
      "y": 2,
      "z": 8,
      "name": "Barrier"
    },
    {
      "x": -3,
      "y": 3,
      "z": 8,
      "name": "Barrier"
    },
    {
      "x": -2,
      "y": -2,
      "z": -7,
      "name": "Cloth_Block_Wool_Black"
    },
    {
      "x": -2,
      "y": -1,
      "z": -7,
      "name": "Cloth_Block_Wool_Black"
    },
    {
      "x": -2,
      "y": 0,
      "z": -7,
      "name": "Cloth_Block_Wool_Black"
    },
    {
      "x": -2,
      "y": 1,
      "z": -7,
      "name": "Wood_Blackwood_Beam",
      "rotation": 5
    },
    {
      "x": -2,
      "y": 2,
      "z": -7,
      "name": "Wood_Blackwood_Beam",
      "rotation": 5
    },
    {
      "x": -2,
      "y": 3,
      "z": -7,
      "name": "Wood_Blackwood_Beam",
      "rotation": 5
    },
    {
      "x": -2,
      "y": 4,
      "z": -7,
      "name": "Wood_Blackwood_Beam",
      "rotation": 5
    },
    {
      "x": -2,
      "y": 5,
      "z": -7,
      "name": "Cloth_Block_Wool_Black"
    },
    {
      "x": -2,
      "y": 6,
      "z": -7,
      "name": "Cloth_Block_Wool_Black"
    },
    {
      "x": -2,
      "y": 7,
      "z": -7,
      "name": "Cloth_Block_Wool_Black"
    },
    {
      "x": -2,
      "y": -3,
      "z": -6,
      "name": "Cloth_Block_Wool_Black"
    },
    {
      "x": -2,
      "y": -2,
      "z": -6,
      "name": "Blue_Led_Beam",
      "rotation": 5
    },
    {
      "x": -2,
      "y": -1,
      "z": -6,
      "name": "Barrier"
    },
    {
      "x": -2,
      "y": 6,
      "z": -6,
      "name": "Barrier"
    },
    {
      "x": -2,
      "y": 7,
      "z": -6,
      "name": "Blue_Led_Beam",
      "rotation": 5
    },
    {
      "x": -2,
      "y": 8,
      "z": -6,
      "name": "Cloth_Block_Wool_Black"
    },
    {
      "x": -2,
      "y": -2,
      "z": -5,
      "name": "Cloth_Block_Wool_Black"
    },
    {
      "x": -2,
      "y": -1,
      "z": -5,
      "name": "Cloth_Block_Wool_Black"
    },
    {
      "x": -2,
      "y": 6,
      "z": -5,
      "name": "Cloth_Block_Wool_Black"
    },
    {
      "x": -2,
      "y": 7,
      "z": -5,
      "name": "Cloth_Block_Wool_Black"
    },
    {
      "x": -2,
      "y": -1,
      "z": -4,
      "name": "Cloth_Block_Wool_Black"
    },
    {
      "x": -2,
      "y": 6,
      "z": -4,
      "name": "Cloth_Block_Wool_Black"
    },
    {
      "x": -2,
      "y": -1,
      "z": -3,
      "name": "Cloth_Block_Wool_Black"
    },
    {
      "x": -2,
      "y": 6,
      "z": -3,
      "name": "Cloth_Block_Wool_Black"
    },
    {
      "x": -2,
      "y": -1,
      "z": -2,
      "name": "Cloth_Block_Wool_Black"
    },
    {
      "x": -2,
      "y": 6,
      "z": -2,
      "name": "Cloth_Block_Wool_Black"
    },
    {
      "x": -2,
      "y": -1,
      "z": -1,
      "name": "Cloth_Block_Wool_Black"
    },
    {
      "x": -2,
      "y": 6,
      "z": -1,
      "name": "Cloth_Block_Wool_Black"
    },
    {
      "x": -2,
      "y": -1,
      "z": 0,
      "name": "Cloth_Block_Wool_Black"
    },
    {
      "x": -2,
      "y": 6,
      "z": 0,
      "name": "Cloth_Block_Wool_Black"
    },
    {
      "x": -2,
      "y": -1,
      "z": 1,
      "name": "Cloth_Block_Wool_Black"
    },
    {
      "x": -2,
      "y": 6,
      "z": 1,
      "name": "Cloth_Block_Wool_Black"
    },
    {
      "x": -2,
      "y": -1,
      "z": 2,
      "name": "Cloth_Block_Wool_Black"
    },
    {
      "x": -2,
      "y": 6,
      "z": 2,
      "name": "Cloth_Block_Wool_Black"
    },
    {
      "x": -2,
      "y": -1,
      "z": 3,
      "name": "Cloth_Block_Wool_Black"
    },
    {
      "x": -2,
      "y": 6,
      "z": 3,
      "name": "Cloth_Block_Wool_Black"
    },
    {
      "x": -2,
      "y": -1,
      "z": 4,
      "name": "Cloth_Block_Wool_Black"
    },
    {
      "x": -2,
      "y": 6,
      "z": 4,
      "name": "Cloth_Block_Wool_Black"
    },
    {
      "x": -2,
      "y": -2,
      "z": 5,
      "name": "Cloth_Block_Wool_Black"
    },
    {
      "x": -2,
      "y": -1,
      "z": 5,
      "name": "Cloth_Block_Wool_Black"
    },
    {
      "x": -2,
      "y": 6,
      "z": 5,
      "name": "Cloth_Block_Wool_Black"
    },
    {
      "x": -2,
      "y": 7,
      "z": 5,
      "name": "Cloth_Block_Wool_Black"
    },
    {
      "x": -2,
      "y": -3,
      "z": 6,
      "name": "Cloth_Block_Wool_Black"
    },
    {
      "x": -2,
      "y": -2,
      "z": 6,
      "name": "Blue_Led_Beam",
      "rotation": 5
    },
    {
      "x": -2,
      "y": -1,
      "z": 6,
      "name": "Barrier"
    },
    {
      "x": -2,
      "y": 6,
      "z": 6,
      "name": "Barrier"
    },
    {
      "x": -2,
      "y": 7,
      "z": 6,
      "name": "Blue_Led_Beam",
      "rotation": 5
    },
    {
      "x": -2,
      "y": 8,
      "z": 6,
      "name": "Cloth_Block_Wool_Black"
    },
    {
      "x": -2,
      "y": -2,
      "z": 7,
      "name": "Cloth_Block_Wool_Black"
    },
    {
      "x": -2,
      "y": -1,
      "z": 7,
      "name": "Cloth_Block_Wool_Black"
    },
    {
      "x": -2,
      "y": 0,
      "z": 7,
      "name": "Cloth_Block_Wool_Black"
    },
    {
      "x": -2,
      "y": 1,
      "z": 7,
      "name": "Wood_Blackwood_Beam",
      "rotation": 5
    },
    {
      "x": -2,
      "y": 2,
      "z": 7,
      "name": "Wood_Blackwood_Beam",
      "rotation": 5
    },
    {
      "x": -2,
      "y": 3,
      "z": 7,
      "name": "Wood_Blackwood_Beam",
      "rotation": 5
    },
    {
      "x": -2,
      "y": 4,
      "z": 7,
      "name": "Wood_Blackwood_Beam",
      "rotation": 5
    },
    {
      "x": -2,
      "y": 5,
      "z": 7,
      "name": "Cloth_Block_Wool_Black"
    },
    {
      "x": -2,
      "y": 6,
      "z": 7,
      "name": "Cloth_Block_Wool_Black"
    },
    {
      "x": -2,
      "y": 7,
      "z": 7,
      "name": "Cloth_Block_Wool_Black"
    },
    {
      "x": -1,
      "y": -2,
      "z": -7,
      "name": "Cloth_Block_Wool_Black"
    },
    {
      "x": -1,
      "y": -1,
      "z": -7,
      "name": "Cloth_Block_Wool_Black"
    },
    {
      "x": -1,
      "y": 0,
      "z": -7,
      "name": "Cloth_Block_Wool_Black"
    },
    {
      "x": -1,
      "y": 1,
      "z": -7,
      "name": "Cloth_Block_Wool_Black"
    },
    {
      "x": -1,
      "y": 2,
      "z": -7,
      "name": "Cloth_Block_Wool_Black"
    },
    {
      "x": -1,
      "y": 3,
      "z": -7,
      "name": "Cloth_Block_Wool_Black"
    },
    {
      "x": -1,
      "y": 4,
      "z": -7,
      "name": "Cloth_Block_Wool_Black"
    },
    {
      "x": -1,
      "y": 5,
      "z": -7,
      "name": "Cloth_Block_Wool_Black"
    },
    {
      "x": -1,
      "y": 6,
      "z": -7,
      "name": "Cloth_Block_Wool_Black"
    },
    {
      "x": -1,
      "y": 7,
      "z": -7,
      "name": "Cloth_Block_Wool_Black"
    },
    {
      "x": -1,
      "y": -3,
      "z": -6,
      "name": "Cloth_Block_Wool_Black"
    },
    {
      "x": -1,
      "y": -2,
      "z": -6,
      "name": "Blue_Led_Beam",
      "rotation": 5
    },
    {
      "x": -1,
      "y": -1,
      "z": -6,
      "name": "Barrier"
    },
    {
      "x": -1,
      "y": 6,
      "z": -6,
      "name": "Barrier"
    },
    {
      "x": -1,
      "y": 7,
      "z": -6,
      "name": "Blue_Led_Beam",
      "rotation": 5
    },
    {
      "x": -1,
      "y": 8,
      "z": -6,
      "name": "Cloth_Block_Wool_Black"
    },
    {
      "x": -1,
      "y": -2,
      "z": -5,
      "name": "Cloth_Block_Wool_Black"
    },
    {
      "x": -1,
      "y": -1,
      "z": -5,
      "name": "Cloth_Block_Wool_Black"
    },
    {
      "x": -1,
      "y": 6,
      "z": -5,
      "name": "Cloth_Block_Wool_Black"
    },
    {
      "x": -1,
      "y": 7,
      "z": -5,
      "name": "Cloth_Block_Wool_Black"
    },
    {
      "x": -1,
      "y": -2,
      "z": -4,
      "name": "Cloth_Block_Wool_Black"
    },
    {
      "x": -1,
      "y": -1,
      "z": -4,
      "name": "Cloth_Block_Wool_Black"
    },
    {
      "x": -1,
      "y": 6,
      "z": -4,
      "name": "Cloth_Block_Wool_Black"
    },
    {
      "x": -1,
      "y": 7,
      "z": -4,
      "name": "Cloth_Block_Wool_Black"
    },
    {
      "x": -1,
      "y": -2,
      "z": -3,
      "name": "Cloth_Block_Wool_Black"
    },
    {
      "x": -1,
      "y": -1,
      "z": -3,
      "name": "Cloth_Block_Wool_Black"
    },
    {
      "x": -1,
      "y": 6,
      "z": -3,
      "name": "Cloth_Block_Wool_Black"
    },
    {
      "x": -1,
      "y": 7,
      "z": -3,
      "name": "Cloth_Block_Wool_Black"
    },
    {
      "x": -1,
      "y": -2,
      "z": -2,
      "name": "Cloth_Block_Wool_Black"
    },
    {
      "x": -1,
      "y": -1,
      "z": -2,
      "name": "Cloth_Block_Wool_Black"
    },
    {
      "x": -1,
      "y": 6,
      "z": -2,
      "name": "Cloth_Block_Wool_Black"
    },
    {
      "x": -1,
      "y": 7,
      "z": -2,
      "name": "Cloth_Block_Wool_Black"
    },
    {
      "x": -1,
      "y": -2,
      "z": -1,
      "name": "Cloth_Block_Wool_Black"
    },
    {
      "x": -1,
      "y": -1,
      "z": -1,
      "name": "Cloth_Block_Wool_Black"
    },
    {
      "x": -1,
      "y": 6,
      "z": -1,
      "name": "Cloth_Block_Wool_Black"
    },
    {
      "x": -1,
      "y": 7,
      "z": -1,
      "name": "Cloth_Block_Wool_Black"
    },
    {
      "x": -1,
      "y": -1,
      "z": 0,
      "name": "Cloth_Block_Wool_Black"
    },
    {
      "x": -1,
      "y": 6,
      "z": 0,
      "name": "Cloth_Block_Wool_Black"
    },
    {
      "x": -1,
      "y": -2,
      "z": 1,
      "name": "Cloth_Block_Wool_Black"
    },
    {
      "x": -1,
      "y": -1,
      "z": 1,
      "name": "Cloth_Block_Wool_Black"
    },
    {
      "x": -1,
      "y": 6,
      "z": 1,
      "name": "Cloth_Block_Wool_Black"
    },
    {
      "x": -1,
      "y": 7,
      "z": 1,
      "name": "Cloth_Block_Wool_Black"
    },
    {
      "x": -1,
      "y": -2,
      "z": 2,
      "name": "Cloth_Block_Wool_Black"
    },
    {
      "x": -1,
      "y": -1,
      "z": 2,
      "name": "Cloth_Block_Wool_Black"
    },
    {
      "x": -1,
      "y": 6,
      "z": 2,
      "name": "Cloth_Block_Wool_Black"
    },
    {
      "x": -1,
      "y": 7,
      "z": 2,
      "name": "Cloth_Block_Wool_Black"
    },
    {
      "x": -1,
      "y": -2,
      "z": 3,
      "name": "Cloth_Block_Wool_Black"
    },
    {
      "x": -1,
      "y": -1,
      "z": 3,
      "name": "Cloth_Block_Wool_Black"
    },
    {
      "x": -1,
      "y": 6,
      "z": 3,
      "name": "Cloth_Block_Wool_Black"
    },
    {
      "x": -1,
      "y": 7,
      "z": 3,
      "name": "Cloth_Block_Wool_Black"
    },
    {
      "x": -1,
      "y": -2,
      "z": 4,
      "name": "Cloth_Block_Wool_Black"
    },
    {
      "x": -1,
      "y": -1,
      "z": 4,
      "name": "Cloth_Block_Wool_Black"
    },
    {
      "x": -1,
      "y": 6,
      "z": 4,
      "name": "Cloth_Block_Wool_Black"
    },
    {
      "x": -1,
      "y": 7,
      "z": 4,
      "name": "Cloth_Block_Wool_Black"
    },
    {
      "x": -1,
      "y": -2,
      "z": 5,
      "name": "Cloth_Block_Wool_Black"
    },
    {
      "x": -1,
      "y": -1,
      "z": 5,
      "name": "Cloth_Block_Wool_Black"
    },
    {
      "x": -1,
      "y": 6,
      "z": 5,
      "name": "Cloth_Block_Wool_Black"
    },
    {
      "x": -1,
      "y": 7,
      "z": 5,
      "name": "Cloth_Block_Wool_Black"
    },
    {
      "x": -1,
      "y": -3,
      "z": 6,
      "name": "Cloth_Block_Wool_Black"
    },
    {
      "x": -1,
      "y": -2,
      "z": 6,
      "name": "Blue_Led_Beam",
      "rotation": 5
    },
    {
      "x": -1,
      "y": -1,
      "z": 6,
      "name": "Barrier"
    },
    {
      "x": -1,
      "y": 6,
      "z": 6,
      "name": "Barrier"
    },
    {
      "x": -1,
      "y": 7,
      "z": 6,
      "name": "Blue_Led_Beam",
      "rotation": 5
    },
    {
      "x": -1,
      "y": 8,
      "z": 6,
      "name": "Cloth_Block_Wool_Black"
    },
    {
      "x": -1,
      "y": -2,
      "z": 7,
      "name": "Cloth_Block_Wool_Black"
    },
    {
      "x": -1,
      "y": -1,
      "z": 7,
      "name": "Cloth_Block_Wool_Black"
    },
    {
      "x": -1,
      "y": 0,
      "z": 7,
      "name": "Cloth_Block_Wool_Black"
    },
    {
      "x": -1,
      "y": 1,
      "z": 7,
      "name": "Cloth_Block_Wool_Black"
    },
    {
      "x": -1,
      "y": 2,
      "z": 7,
      "name": "Cloth_Block_Wool_Black"
    },
    {
      "x": -1,
      "y": 3,
      "z": 7,
      "name": "Cloth_Block_Wool_Black"
    },
    {
      "x": -1,
      "y": 4,
      "z": 7,
      "name": "Cloth_Block_Wool_Black"
    },
    {
      "x": -1,
      "y": 5,
      "z": 7,
      "name": "Cloth_Block_Wool_Black"
    },
    {
      "x": -1,
      "y": 6,
      "z": 7,
      "name": "Cloth_Block_Wool_Black"
    },
    {
      "x": -1,
      "y": 7,
      "z": 7,
      "name": "Cloth_Block_Wool_Black"
    },
    {
      "x": 0,
      "y": 1,
      "z": -8,
      "name": "Cloth_Block_Wool_Black"
    },
    {
      "x": 0,
      "y": 2,
      "z": -8,
      "name": "Cloth_Block_Wool_Black"
    },
    {
      "x": 0,
      "y": 3,
      "z": -8,
      "name": "Cloth_Block_Wool_Black"
    },
    {
      "x": 0,
      "y": 4,
      "z": -8,
      "name": "Cloth_Block_Wool_Black"
    },
    {
      "x": 0,
      "y": -1,
      "z": -7,
      "name": "Cloth_Block_Wool_Black"
    },
    {
      "x": 0,
      "y": 0,
      "z": -7,
      "name": "Cloth_Block_Wool_Black"
    },
    {
      "x": 0,
      "y": 1,
      "z": -7,
      "name": "Purple_Led_Beam"
    },
    {
      "x": 0,
      "y": 2,
      "z": -7,
      "name": "Purple_Led_Beam"
    },
    {
      "x": 0,
      "y": 3,
      "z": -7,
      "name": "Purple_Led_Beam"
    },
    {
      "x": 0,
      "y": 4,
      "z": -7,
      "name": "Purple_Led_Beam"
    },
    {
      "x": 0,
      "y": 5,
      "z": -7,
      "name": "Cloth_Block_Wool_Black"
    },
    {
      "x": 0,
      "y": 6,
      "z": -7,
      "name": "Cloth_Block_Wool_Black"
    },
    {
      "x": 0,
      "y": -2,
      "z": -6,
      "name": "Cloth_Block_Wool_Black"
    },
    {
      "x": 0,
      "y": -1,
      "z": -6,
      "name": "Cloth_Block_Wool_Black"
    },
    {
      "x": 0,
      "y": 0,
      "z": -6,
      "name": "Black_Cloth_Half"
    },
    {
      "x": 0,
      "y": 5,
      "z": -6,
      "name": "Black_Cloth_Half",
      "rotation": 8
    },
    {
      "x": 0,
      "y": 6,
      "z": -6,
      "name": "Cloth_Block_Wool_Black"
    },
    {
      "x": 0,
      "y": 7,
      "z": -6,
      "name": "Cloth_Block_Wool_Black"
    },
    {
      "x": 0,
      "y": -3,
      "z": -5,
      "name": "Cloth_Block_Wool_Black"
    },
    {
      "x": 0,
      "y": -2,
      "z": -5,
      "name": "Purple_Led_Beam",
      "rotation": 4
    },
    {
      "x": 0,
      "y": -1,
      "z": -5,
      "name": "Barrier"
    },
    {
      "x": 0,
      "y": 6,
      "z": -5,
      "name": "Barrier"
    },
    {
      "x": 0,
      "y": 7,
      "z": -5,
      "name": "Purple_Led_Beam",
      "rotation": 4
    },
    {
      "x": 0,
      "y": 8,
      "z": -5,
      "name": "Cloth_Block_Wool_Black"
    },
    {
      "x": 0,
      "y": -3,
      "z": -4,
      "name": "Cloth_Block_Wool_Black"
    },
    {
      "x": 0,
      "y": -2,
      "z": -4,
      "name": "Purple_Led_Beam",
      "rotation": 4
    },
    {
      "x": 0,
      "y": -1,
      "z": -4,
      "name": "Barrier"
    },
    {
      "x": 0,
      "y": 6,
      "z": -4,
      "name": "Barrier"
    },
    {
      "x": 0,
      "y": 7,
      "z": -4,
      "name": "Purple_Led_Beam",
      "rotation": 4
    },
    {
      "x": 0,
      "y": 8,
      "z": -4,
      "name": "Cloth_Block_Wool_Black"
    },
    {
      "x": 0,
      "y": -3,
      "z": -3,
      "name": "Cloth_Block_Wool_Black"
    },
    {
      "x": 0,
      "y": -2,
      "z": -3,
      "name": "Purple_Led_Beam",
      "rotation": 4
    },
    {
      "x": 0,
      "y": -1,
      "z": -3,
      "name": "Barrier"
    },
    {
      "x": 0,
      "y": 6,
      "z": -3,
      "name": "Barrier"
    },
    {
      "x": 0,
      "y": 7,
      "z": -3,
      "name": "Purple_Led_Beam",
      "rotation": 4
    },
    {
      "x": 0,
      "y": 8,
      "z": -3,
      "name": "Cloth_Block_Wool_Black"
    },
    {
      "x": 0,
      "y": -3,
      "z": -2,
      "name": "Cloth_Block_Wool_Black"
    },
    {
      "x": 0,
      "y": -2,
      "z": -2,
      "name": "Purple_Led_Beam",
      "rotation": 4
    },
    {
      "x": 0,
      "y": -1,
      "z": -2,
      "name": "Barrier"
    },
    {
      "x": 0,
      "y": 6,
      "z": -2,
      "name": "Barrier"
    },
    {
      "x": 0,
      "y": 7,
      "z": -2,
      "name": "Purple_Led_Beam",
      "rotation": 4
    },
    {
      "x": 0,
      "y": 8,
      "z": -2,
      "name": "Cloth_Block_Wool_Black"
    },
    {
      "x": 0,
      "y": -3,
      "z": -1,
      "name": "Cloth_Block_Wool_Black"
    },
    {
      "x": 0,
      "y": -2,
      "z": -1,
      "name": "Purple_Led_Beam",
      "rotation": 4
    },
    {
      "x": 0,
      "y": -1,
      "z": -1,
      "name": "Barrier"
    },
    {
      "x": 0,
      "y": 6,
      "z": -1,
      "name": "Barrier"
    },
    {
      "x": 0,
      "y": 7,
      "z": -1,
      "name": "Purple_Led_Beam",
      "rotation": 4
    },
    {
      "x": 0,
      "y": 8,
      "z": -1,
      "name": "Cloth_Block_Wool_Black"
    },
    {
      "x": 0,
      "y": -2,
      "z": 0,
      "name": "Cloth_Block_Wool_Black"
    },
    {
      "x": 0,
      "y": -1,
      "z": 0,
      "name": "Cloth_Block_Wool_Black"
    },
    {
      "x": 0,
      "y": 5,
      "z": 0,
      "name": "Black_Cloth_Half",
      "rotation": 8
    },
    {
      "x": 0,
      "y": 6,
      "z": 0,
      "name": "Cloth_Block_Wool_Black"
    },
    {
      "x": 0,
      "y": 7,
      "z": 0,
      "name": "Cloth_Block_Wool_Black"
    },
    {
      "x": 0,
      "y": -3,
      "z": 1,
      "name": "Cloth_Block_Wool_Black"
    },
    {
      "x": 0,
      "y": -2,
      "z": 1,
      "name": "Purple_Led_Beam",
      "rotation": 4
    },
    {
      "x": 0,
      "y": -1,
      "z": 1,
      "name": "Barrier"
    },
    {
      "x": 0,
      "y": 6,
      "z": 1,
      "name": "Barrier"
    },
    {
      "x": 0,
      "y": 7,
      "z": 1,
      "name": "Purple_Led_Beam",
      "rotation": 4
    },
    {
      "x": 0,
      "y": 8,
      "z": 1,
      "name": "Cloth_Block_Wool_Black"
    },
    {
      "x": 0,
      "y": -3,
      "z": 2,
      "name": "Cloth_Block_Wool_Black"
    },
    {
      "x": 0,
      "y": -2,
      "z": 2,
      "name": "Purple_Led_Beam",
      "rotation": 4
    },
    {
      "x": 0,
      "y": -1,
      "z": 2,
      "name": "Barrier"
    },
    {
      "x": 0,
      "y": 6,
      "z": 2,
      "name": "Barrier"
    },
    {
      "x": 0,
      "y": 7,
      "z": 2,
      "name": "Purple_Led_Beam",
      "rotation": 4
    },
    {
      "x": 0,
      "y": 8,
      "z": 2,
      "name": "Cloth_Block_Wool_Black"
    },
    {
      "x": 0,
      "y": -3,
      "z": 3,
      "name": "Cloth_Block_Wool_Black"
    },
    {
      "x": 0,
      "y": -2,
      "z": 3,
      "name": "Purple_Led_Beam",
      "rotation": 4
    },
    {
      "x": 0,
      "y": -1,
      "z": 3,
      "name": "Barrier"
    },
    {
      "x": 0,
      "y": 6,
      "z": 3,
      "name": "Barrier"
    },
    {
      "x": 0,
      "y": 7,
      "z": 3,
      "name": "Purple_Led_Beam",
      "rotation": 4
    },
    {
      "x": 0,
      "y": 8,
      "z": 3,
      "name": "Cloth_Block_Wool_Black"
    },
    {
      "x": 0,
      "y": -3,
      "z": 4,
      "name": "Cloth_Block_Wool_Black"
    },
    {
      "x": 0,
      "y": -2,
      "z": 4,
      "name": "Purple_Led_Beam",
      "rotation": 4
    },
    {
      "x": 0,
      "y": -1,
      "z": 4,
      "name": "Barrier"
    },
    {
      "x": 0,
      "y": 6,
      "z": 4,
      "name": "Barrier"
    },
    {
      "x": 0,
      "y": 7,
      "z": 4,
      "name": "Purple_Led_Beam",
      "rotation": 4
    },
    {
      "x": 0,
      "y": 8,
      "z": 4,
      "name": "Cloth_Block_Wool_Black"
    },
    {
      "x": 0,
      "y": -3,
      "z": 5,
      "name": "Cloth_Block_Wool_Black"
    },
    {
      "x": 0,
      "y": -2,
      "z": 5,
      "name": "Purple_Led_Beam",
      "rotation": 4
    },
    {
      "x": 0,
      "y": -1,
      "z": 5,
      "name": "Barrier"
    },
    {
      "x": 0,
      "y": 6,
      "z": 5,
      "name": "Barrier"
    },
    {
      "x": 0,
      "y": 7,
      "z": 5,
      "name": "Purple_Led_Beam",
      "rotation": 4
    },
    {
      "x": 0,
      "y": 8,
      "z": 5,
      "name": "Cloth_Block_Wool_Black"
    },
    {
      "x": 0,
      "y": -2,
      "z": 6,
      "name": "Cloth_Block_Wool_Black"
    },
    {
      "x": 0,
      "y": -1,
      "z": 6,
      "name": "Cloth_Block_Wool_Black"
    },
    {
      "x": 0,
      "y": 0,
      "z": 6,
      "name": "Black_Cloth_Half"
    },
    {
      "x": 0,
      "y": 5,
      "z": 6,
      "name": "Black_Cloth_Half",
      "rotation": 8
    },
    {
      "x": 0,
      "y": 6,
      "z": 6,
      "name": "Cloth_Block_Wool_Black"
    },
    {
      "x": 0,
      "y": 7,
      "z": 6,
      "name": "Cloth_Block_Wool_Black"
    },
    {
      "x": 0,
      "y": -1,
      "z": 7,
      "name": "Cloth_Block_Wool_Black"
    },
    {
      "x": 0,
      "y": 0,
      "z": 7,
      "name": "Cloth_Block_Wool_Black"
    },
    {
      "x": 0,
      "y": 1,
      "z": 7,
      "name": "Purple_Led_Beam"
    },
    {
      "x": 0,
      "y": 2,
      "z": 7,
      "name": "Purple_Led_Beam"
    },
    {
      "x": 0,
      "y": 3,
      "z": 7,
      "name": "Purple_Led_Beam"
    },
    {
      "x": 0,
      "y": 4,
      "z": 7,
      "name": "Purple_Led_Beam"
    },
    {
      "x": 0,
      "y": 5,
      "z": 7,
      "name": "Cloth_Block_Wool_Black"
    },
    {
      "x": 0,
      "y": 6,
      "z": 7,
      "name": "Cloth_Block_Wool_Black"
    },
    {
      "x": 0,
      "y": 1,
      "z": 8,
      "name": "Cloth_Block_Wool_Black"
    },
    {
      "x": 0,
      "y": 2,
      "z": 8,
      "name": "Cloth_Block_Wool_Black"
    },
    {
      "x": 0,
      "y": 3,
      "z": 8,
      "name": "Cloth_Block_Wool_Black"
    },
    {
      "x": 0,
      "y": 4,
      "z": 8,
      "name": "Cloth_Block_Wool_Black"
    },
    {
      "x": 1,
      "y": -2,
      "z": -7,
      "name": "Cloth_Block_Wool_Black"
    },
    {
      "x": 1,
      "y": -1,
      "z": -7,
      "name": "Cloth_Block_Wool_Black"
    },
    {
      "x": 1,
      "y": 0,
      "z": -7,
      "name": "Cloth_Block_Wool_Black"
    },
    {
      "x": 1,
      "y": 1,
      "z": -7,
      "name": "Cloth_Block_Wool_Black"
    },
    {
      "x": 1,
      "y": 2,
      "z": -7,
      "name": "Cloth_Block_Wool_Black"
    },
    {
      "x": 1,
      "y": 3,
      "z": -7,
      "name": "Cloth_Block_Wool_Black"
    },
    {
      "x": 1,
      "y": 4,
      "z": -7,
      "name": "Cloth_Block_Wool_Black"
    },
    {
      "x": 1,
      "y": 5,
      "z": -7,
      "name": "Cloth_Block_Wool_Black"
    },
    {
      "x": 1,
      "y": 6,
      "z": -7,
      "name": "Cloth_Block_Wool_Black"
    },
    {
      "x": 1,
      "y": 7,
      "z": -7,
      "name": "Cloth_Block_Wool_Black"
    },
    {
      "x": 1,
      "y": -3,
      "z": -6,
      "name": "Cloth_Block_Wool_Black"
    },
    {
      "x": 1,
      "y": -2,
      "z": -6,
      "name": "Red_Led_Beam",
      "rotation": 5
    },
    {
      "x": 1,
      "y": -1,
      "z": -6,
      "name": "Barrier"
    },
    {
      "x": 1,
      "y": 6,
      "z": -6,
      "name": "Barrier"
    },
    {
      "x": 1,
      "y": 7,
      "z": -6,
      "name": "Red_Led_Beam",
      "rotation": 5
    },
    {
      "x": 1,
      "y": 8,
      "z": -6,
      "name": "Cloth_Block_Wool_Black"
    },
    {
      "x": 1,
      "y": -2,
      "z": -5,
      "name": "Cloth_Block_Wool_Black"
    },
    {
      "x": 1,
      "y": -1,
      "z": -5,
      "name": "Cloth_Block_Wool_Black"
    },
    {
      "x": 1,
      "y": 6,
      "z": -5,
      "name": "Cloth_Block_Wool_Black"
    },
    {
      "x": 1,
      "y": 7,
      "z": -5,
      "name": "Cloth_Block_Wool_Black"
    },
    {
      "x": 1,
      "y": -2,
      "z": -4,
      "name": "Cloth_Block_Wool_Black"
    },
    {
      "x": 1,
      "y": -1,
      "z": -4,
      "name": "Cloth_Block_Wool_Black"
    },
    {
      "x": 1,
      "y": 6,
      "z": -4,
      "name": "Cloth_Block_Wool_Black"
    },
    {
      "x": 1,
      "y": 7,
      "z": -4,
      "name": "Cloth_Block_Wool_Black"
    },
    {
      "x": 1,
      "y": -2,
      "z": -3,
      "name": "Cloth_Block_Wool_Black"
    },
    {
      "x": 1,
      "y": -1,
      "z": -3,
      "name": "Cloth_Block_Wool_Black"
    },
    {
      "x": 1,
      "y": 6,
      "z": -3,
      "name": "Cloth_Block_Wool_Black"
    },
    {
      "x": 1,
      "y": 7,
      "z": -3,
      "name": "Cloth_Block_Wool_Black"
    },
    {
      "x": 1,
      "y": -2,
      "z": -2,
      "name": "Cloth_Block_Wool_Black"
    },
    {
      "x": 1,
      "y": -1,
      "z": -2,
      "name": "Cloth_Block_Wool_Black"
    },
    {
      "x": 1,
      "y": 6,
      "z": -2,
      "name": "Cloth_Block_Wool_Black"
    },
    {
      "x": 1,
      "y": 7,
      "z": -2,
      "name": "Cloth_Block_Wool_Black"
    },
    {
      "x": 1,
      "y": -2,
      "z": -1,
      "name": "Cloth_Block_Wool_Black"
    },
    {
      "x": 1,
      "y": -1,
      "z": -1,
      "name": "Cloth_Block_Wool_Black"
    },
    {
      "x": 1,
      "y": 6,
      "z": -1,
      "name": "Cloth_Block_Wool_Black"
    },
    {
      "x": 1,
      "y": 7,
      "z": -1,
      "name": "Cloth_Block_Wool_Black"
    },
    {
      "x": 1,
      "y": -1,
      "z": 0,
      "name": "Cloth_Block_Wool_Black"
    },
    {
      "x": 1,
      "y": 6,
      "z": 0,
      "name": "Cloth_Block_Wool_Black"
    },
    {
      "x": 1,
      "y": -2,
      "z": 1,
      "name": "Cloth_Block_Wool_Black"
    },
    {
      "x": 1,
      "y": -1,
      "z": 1,
      "name": "Cloth_Block_Wool_Black"
    },
    {
      "x": 1,
      "y": 6,
      "z": 1,
      "name": "Cloth_Block_Wool_Black"
    },
    {
      "x": 1,
      "y": 7,
      "z": 1,
      "name": "Cloth_Block_Wool_Black"
    },
    {
      "x": 1,
      "y": -2,
      "z": 2,
      "name": "Cloth_Block_Wool_Black"
    },
    {
      "x": 1,
      "y": -1,
      "z": 2,
      "name": "Cloth_Block_Wool_Black"
    },
    {
      "x": 1,
      "y": 6,
      "z": 2,
      "name": "Cloth_Block_Wool_Black"
    },
    {
      "x": 1,
      "y": 7,
      "z": 2,
      "name": "Cloth_Block_Wool_Black"
    },
    {
      "x": 1,
      "y": -2,
      "z": 3,
      "name": "Cloth_Block_Wool_Black"
    },
    {
      "x": 1,
      "y": -1,
      "z": 3,
      "name": "Cloth_Block_Wool_Black"
    },
    {
      "x": 1,
      "y": 6,
      "z": 3,
      "name": "Cloth_Block_Wool_Black"
    },
    {
      "x": 1,
      "y": 7,
      "z": 3,
      "name": "Cloth_Block_Wool_Black"
    },
    {
      "x": 1,
      "y": -2,
      "z": 4,
      "name": "Cloth_Block_Wool_Black"
    },
    {
      "x": 1,
      "y": -1,
      "z": 4,
      "name": "Cloth_Block_Wool_Black"
    },
    {
      "x": 1,
      "y": 6,
      "z": 4,
      "name": "Cloth_Block_Wool_Black"
    },
    {
      "x": 1,
      "y": 7,
      "z": 4,
      "name": "Cloth_Block_Wool_Black"
    },
    {
      "x": 1,
      "y": -2,
      "z": 5,
      "name": "Cloth_Block_Wool_Black"
    },
    {
      "x": 1,
      "y": -1,
      "z": 5,
      "name": "Cloth_Block_Wool_Black"
    },
    {
      "x": 1,
      "y": 6,
      "z": 5,
      "name": "Cloth_Block_Wool_Black"
    },
    {
      "x": 1,
      "y": 7,
      "z": 5,
      "name": "Cloth_Block_Wool_Black"
    },
    {
      "x": 1,
      "y": -3,
      "z": 6,
      "name": "Cloth_Block_Wool_Black"
    },
    {
      "x": 1,
      "y": -2,
      "z": 6,
      "name": "Red_Led_Beam",
      "rotation": 5
    },
    {
      "x": 1,
      "y": -1,
      "z": 6,
      "name": "Barrier"
    },
    {
      "x": 1,
      "y": 6,
      "z": 6,
      "name": "Barrier"
    },
    {
      "x": 1,
      "y": 7,
      "z": 6,
      "name": "Red_Led_Beam",
      "rotation": 5
    },
    {
      "x": 1,
      "y": 8,
      "z": 6,
      "name": "Cloth_Block_Wool_Black"
    },
    {
      "x": 1,
      "y": -2,
      "z": 7,
      "name": "Cloth_Block_Wool_Black"
    },
    {
      "x": 1,
      "y": -1,
      "z": 7,
      "name": "Cloth_Block_Wool_Black"
    },
    {
      "x": 1,
      "y": 0,
      "z": 7,
      "name": "Cloth_Block_Wool_Black"
    },
    {
      "x": 1,
      "y": 1,
      "z": 7,
      "name": "Cloth_Block_Wool_Black"
    },
    {
      "x": 1,
      "y": 2,
      "z": 7,
      "name": "Cloth_Block_Wool_Black"
    },
    {
      "x": 1,
      "y": 3,
      "z": 7,
      "name": "Cloth_Block_Wool_Black"
    },
    {
      "x": 1,
      "y": 4,
      "z": 7,
      "name": "Cloth_Block_Wool_Black"
    },
    {
      "x": 1,
      "y": 5,
      "z": 7,
      "name": "Cloth_Block_Wool_Black"
    },
    {
      "x": 1,
      "y": 6,
      "z": 7,
      "name": "Cloth_Block_Wool_Black"
    },
    {
      "x": 1,
      "y": 7,
      "z": 7,
      "name": "Cloth_Block_Wool_Black"
    },
    {
      "x": 2,
      "y": -2,
      "z": -7,
      "name": "Cloth_Block_Wool_Black"
    },
    {
      "x": 2,
      "y": -1,
      "z": -7,
      "name": "Cloth_Block_Wool_Black"
    },
    {
      "x": 2,
      "y": 0,
      "z": -7,
      "name": "Cloth_Block_Wool_Black"
    },
    {
      "x": 2,
      "y": 1,
      "z": -7,
      "name": "Wood_Blackwood_Beam",
      "rotation": 5
    },
    {
      "x": 2,
      "y": 2,
      "z": -7,
      "name": "Wood_Blackwood_Beam",
      "rotation": 5
    },
    {
      "x": 2,
      "y": 3,
      "z": -7,
      "name": "Wood_Blackwood_Beam",
      "rotation": 5
    },
    {
      "x": 2,
      "y": 4,
      "z": -7,
      "name": "Wood_Blackwood_Beam",
      "rotation": 5
    },
    {
      "x": 2,
      "y": 5,
      "z": -7,
      "name": "Cloth_Block_Wool_Black"
    },
    {
      "x": 2,
      "y": 6,
      "z": -7,
      "name": "Cloth_Block_Wool_Black"
    },
    {
      "x": 2,
      "y": 7,
      "z": -7,
      "name": "Cloth_Block_Wool_Black"
    },
    {
      "x": 2,
      "y": -3,
      "z": -6,
      "name": "Cloth_Block_Wool_Black"
    },
    {
      "x": 2,
      "y": -2,
      "z": -6,
      "name": "Red_Led_Beam",
      "rotation": 5
    },
    {
      "x": 2,
      "y": -1,
      "z": -6,
      "name": "Barrier"
    },
    {
      "x": 2,
      "y": 6,
      "z": -6,
      "name": "Barrier"
    },
    {
      "x": 2,
      "y": 7,
      "z": -6,
      "name": "Red_Led_Beam",
      "rotation": 5
    },
    {
      "x": 2,
      "y": 8,
      "z": -6,
      "name": "Cloth_Block_Wool_Black"
    },
    {
      "x": 2,
      "y": -2,
      "z": -5,
      "name": "Cloth_Block_Wool_Black"
    },
    {
      "x": 2,
      "y": -1,
      "z": -5,
      "name": "Cloth_Block_Wool_Black"
    },
    {
      "x": 2,
      "y": 6,
      "z": -5,
      "name": "Cloth_Block_Wool_Black"
    },
    {
      "x": 2,
      "y": 7,
      "z": -5,
      "name": "Cloth_Block_Wool_Black"
    },
    {
      "x": 2,
      "y": -1,
      "z": -4,
      "name": "Cloth_Block_Wool_Black"
    },
    {
      "x": 2,
      "y": 6,
      "z": -4,
      "name": "Cloth_Block_Wool_Black"
    },
    {
      "x": 2,
      "y": -1,
      "z": -3,
      "name": "Cloth_Block_Wool_Black"
    },
    {
      "x": 2,
      "y": 6,
      "z": -3,
      "name": "Cloth_Block_Wool_Black"
    },
    {
      "x": 2,
      "y": -1,
      "z": -2,
      "name": "Cloth_Block_Wool_Black"
    },
    {
      "x": 2,
      "y": 6,
      "z": -2,
      "name": "Cloth_Block_Wool_Black"
    },
    {
      "x": 2,
      "y": -1,
      "z": -1,
      "name": "Cloth_Block_Wool_Black"
    },
    {
      "x": 2,
      "y": 6,
      "z": -1,
      "name": "Cloth_Block_Wool_Black"
    },
    {
      "x": 2,
      "y": -1,
      "z": 0,
      "name": "Cloth_Block_Wool_Black"
    },
    {
      "x": 2,
      "y": 6,
      "z": 0,
      "name": "Cloth_Block_Wool_Black"
    },
    {
      "x": 2,
      "y": -1,
      "z": 1,
      "name": "Cloth_Block_Wool_Black"
    },
    {
      "x": 2,
      "y": 6,
      "z": 1,
      "name": "Cloth_Block_Wool_Black"
    },
    {
      "x": 2,
      "y": -1,
      "z": 2,
      "name": "Cloth_Block_Wool_Black"
    },
    {
      "x": 2,
      "y": 6,
      "z": 2,
      "name": "Cloth_Block_Wool_Black"
    },
    {
      "x": 2,
      "y": -1,
      "z": 3,
      "name": "Cloth_Block_Wool_Black"
    },
    {
      "x": 2,
      "y": 6,
      "z": 3,
      "name": "Cloth_Block_Wool_Black"
    },
    {
      "x": 2,
      "y": -1,
      "z": 4,
      "name": "Cloth_Block_Wool_Black"
    },
    {
      "x": 2,
      "y": 6,
      "z": 4,
      "name": "Cloth_Block_Wool_Black"
    },
    {
      "x": 2,
      "y": -2,
      "z": 5,
      "name": "Cloth_Block_Wool_Black"
    },
    {
      "x": 2,
      "y": -1,
      "z": 5,
      "name": "Cloth_Block_Wool_Black"
    },
    {
      "x": 2,
      "y": 6,
      "z": 5,
      "name": "Cloth_Block_Wool_Black"
    },
    {
      "x": 2,
      "y": 7,
      "z": 5,
      "name": "Cloth_Block_Wool_Black"
    },
    {
      "x": 2,
      "y": -3,
      "z": 6,
      "name": "Cloth_Block_Wool_Black"
    },
    {
      "x": 2,
      "y": -2,
      "z": 6,
      "name": "Red_Led_Beam",
      "rotation": 5
    },
    {
      "x": 2,
      "y": -1,
      "z": 6,
      "name": "Barrier"
    },
    {
      "x": 2,
      "y": 6,
      "z": 6,
      "name": "Barrier"
    },
    {
      "x": 2,
      "y": 7,
      "z": 6,
      "name": "Red_Led_Beam",
      "rotation": 5
    },
    {
      "x": 2,
      "y": 8,
      "z": 6,
      "name": "Cloth_Block_Wool_Black"
    },
    {
      "x": 2,
      "y": -2,
      "z": 7,
      "name": "Cloth_Block_Wool_Black"
    },
    {
      "x": 2,
      "y": -1,
      "z": 7,
      "name": "Cloth_Block_Wool_Black"
    },
    {
      "x": 2,
      "y": 0,
      "z": 7,
      "name": "Cloth_Block_Wool_Black"
    },
    {
      "x": 2,
      "y": 1,
      "z": 7,
      "name": "Wood_Blackwood_Beam",
      "rotation": 5
    },
    {
      "x": 2,
      "y": 2,
      "z": 7,
      "name": "Wood_Blackwood_Beam",
      "rotation": 5
    },
    {
      "x": 2,
      "y": 3,
      "z": 7,
      "name": "Wood_Blackwood_Beam",
      "rotation": 5
    },
    {
      "x": 2,
      "y": 4,
      "z": 7,
      "name": "Wood_Blackwood_Beam",
      "rotation": 5
    },
    {
      "x": 2,
      "y": 5,
      "z": 7,
      "name": "Cloth_Block_Wool_Black"
    },
    {
      "x": 2,
      "y": 6,
      "z": 7,
      "name": "Cloth_Block_Wool_Black"
    },
    {
      "x": 2,
      "y": 7,
      "z": 7,
      "name": "Cloth_Block_Wool_Black"
    },
    {
      "x": 3,
      "y": 2,
      "z": -8,
      "name": "Barrier"
    },
    {
      "x": 3,
      "y": 3,
      "z": -8,
      "name": "Barrier"
    },
    {
      "x": 3,
      "y": -2,
      "z": -7,
      "name": "Cloth_Block_Wool_Black"
    },
    {
      "x": 3,
      "y": -1,
      "z": -7,
      "name": "Cloth_Block_Wool_Black"
    },
    {
      "x": 3,
      "y": 0,
      "z": -7,
      "name": "Cloth_Block_Wool_Black"
    },
    {
      "x": 3,
      "y": 1,
      "z": -7,
      "name": "Wood_Blackwood_Beam",
      "rotation": 5
    },
    {
      "x": 3,
      "y": 2,
      "z": -7,
      "name": "Wood_Blackwood_Beam"
    },
    {
      "x": 3,
      "y": 3,
      "z": -7,
      "name": "Wood_Blackwood_Beam"
    },
    {
      "x": 3,
      "y": 4,
      "z": -7,
      "name": "Wood_Blackwood_Beam",
      "rotation": 5
    },
    {
      "x": 3,
      "y": 5,
      "z": -7,
      "name": "Cloth_Block_Wool_Black"
    },
    {
      "x": 3,
      "y": 6,
      "z": -7,
      "name": "Cloth_Block_Wool_Black"
    },
    {
      "x": 3,
      "y": 7,
      "z": -7,
      "name": "Cloth_Block_Wool_Black"
    },
    {
      "x": 3,
      "y": -3,
      "z": -6,
      "name": "Cloth_Block_Wool_Black"
    },
    {
      "x": 3,
      "y": -2,
      "z": -6,
      "name": "Red_Led_Beam",
      "rotation": 5
    },
    {
      "x": 3,
      "y": -1,
      "z": -6,
      "name": "Barrier"
    },
    {
      "x": 3,
      "y": 6,
      "z": -6,
      "name": "Barrier"
    },
    {
      "x": 3,
      "y": 7,
      "z": -6,
      "name": "Red_Led_Beam",
      "rotation": 5
    },
    {
      "x": 3,
      "y": 8,
      "z": -6,
      "name": "Cloth_Block_Wool_Black"
    },
    {
      "x": 3,
      "y": -2,
      "z": -5,
      "name": "Cloth_Block_Wool_Black"
    },
    {
      "x": 3,
      "y": -1,
      "z": -5,
      "name": "Cloth_Block_Wool_Black"
    },
    {
      "x": 3,
      "y": 6,
      "z": -5,
      "name": "Cloth_Block_Wool_Black"
    },
    {
      "x": 3,
      "y": 7,
      "z": -5,
      "name": "Cloth_Block_Wool_Black"
    },
    {
      "x": 3,
      "y": -1,
      "z": -4,
      "name": "Cloth_Block_Wool_Black"
    },
    {
      "x": 3,
      "y": 6,
      "z": -4,
      "name": "Cloth_Block_Wool_Black"
    },
    {
      "x": 3,
      "y": -1,
      "z": -3,
      "name": "Cloth_Block_Wool_Black"
    },
    {
      "x": 3,
      "y": 6,
      "z": -3,
      "name": "Cloth_Block_Wool_Black"
    },
    {
      "x": 3,
      "y": -1,
      "z": -2,
      "name": "Cloth_Block_Wool_Black"
    },
    {
      "x": 3,
      "y": 6,
      "z": -2,
      "name": "Cloth_Block_Wool_Black"
    },
    {
      "x": 3,
      "y": -1,
      "z": -1,
      "name": "Cloth_Block_Wool_Black"
    },
    {
      "x": 3,
      "y": 6,
      "z": -1,
      "name": "Cloth_Block_Wool_Black"
    },
    {
      "x": 3,
      "y": -1,
      "z": 0,
      "name": "Cloth_Block_Wool_Black"
    },
    {
      "x": 3,
      "y": 6,
      "z": 0,
      "name": "Cloth_Block_Wool_Black"
    },
    {
      "x": 3,
      "y": -1,
      "z": 1,
      "name": "Cloth_Block_Wool_Black"
    },
    {
      "x": 3,
      "y": 6,
      "z": 1,
      "name": "Cloth_Block_Wool_Black"
    },
    {
      "x": 3,
      "y": -1,
      "z": 2,
      "name": "Cloth_Block_Wool_Black"
    },
    {
      "x": 3,
      "y": 6,
      "z": 2,
      "name": "Cloth_Block_Wool_Black"
    },
    {
      "x": 3,
      "y": -1,
      "z": 3,
      "name": "Cloth_Block_Wool_Black"
    },
    {
      "x": 3,
      "y": 6,
      "z": 3,
      "name": "Cloth_Block_Wool_Black"
    },
    {
      "x": 3,
      "y": -1,
      "z": 4,
      "name": "Cloth_Block_Wool_Black"
    },
    {
      "x": 3,
      "y": 6,
      "z": 4,
      "name": "Cloth_Block_Wool_Black"
    },
    {
      "x": 3,
      "y": -2,
      "z": 5,
      "name": "Cloth_Block_Wool_Black"
    },
    {
      "x": 3,
      "y": -1,
      "z": 5,
      "name": "Cloth_Block_Wool_Black"
    },
    {
      "x": 3,
      "y": 6,
      "z": 5,
      "name": "Cloth_Block_Wool_Black"
    },
    {
      "x": 3,
      "y": 7,
      "z": 5,
      "name": "Cloth_Block_Wool_Black"
    },
    {
      "x": 3,
      "y": -3,
      "z": 6,
      "name": "Cloth_Block_Wool_Black"
    },
    {
      "x": 3,
      "y": -2,
      "z": 6,
      "name": "Red_Led_Beam",
      "rotation": 5
    },
    {
      "x": 3,
      "y": -1,
      "z": 6,
      "name": "Barrier"
    },
    {
      "x": 3,
      "y": 6,
      "z": 6,
      "name": "Barrier"
    },
    {
      "x": 3,
      "y": 7,
      "z": 6,
      "name": "Red_Led_Beam",
      "rotation": 5
    },
    {
      "x": 3,
      "y": 8,
      "z": 6,
      "name": "Cloth_Block_Wool_Black"
    },
    {
      "x": 3,
      "y": -2,
      "z": 7,
      "name": "Cloth_Block_Wool_Black"
    },
    {
      "x": 3,
      "y": -1,
      "z": 7,
      "name": "Cloth_Block_Wool_Black"
    },
    {
      "x": 3,
      "y": 0,
      "z": 7,
      "name": "Cloth_Block_Wool_Black"
    },
    {
      "x": 3,
      "y": 1,
      "z": 7,
      "name": "Wood_Blackwood_Beam",
      "rotation": 5
    },
    {
      "x": 3,
      "y": 2,
      "z": 7,
      "name": "Wood_Blackwood_Beam"
    },
    {
      "x": 3,
      "y": 3,
      "z": 7,
      "name": "Wood_Blackwood_Beam"
    },
    {
      "x": 3,
      "y": 4,
      "z": 7,
      "name": "Wood_Blackwood_Beam",
      "rotation": 5
    },
    {
      "x": 3,
      "y": 5,
      "z": 7,
      "name": "Cloth_Block_Wool_Black"
    },
    {
      "x": 3,
      "y": 6,
      "z": 7,
      "name": "Cloth_Block_Wool_Black"
    },
    {
      "x": 3,
      "y": 7,
      "z": 7,
      "name": "Cloth_Block_Wool_Black"
    },
    {
      "x": 3,
      "y": 2,
      "z": 8,
      "name": "Barrier"
    },
    {
      "x": 3,
      "y": 3,
      "z": 8,
      "name": "Barrier"
    },
    {
      "x": 4,
      "y": 2,
      "z": -8,
      "name": "Barrier"
    },
    {
      "x": 4,
      "y": 3,
      "z": -8,
      "name": "Barrier"
    },
    {
      "x": 4,
      "y": -2,
      "z": -7,
      "name": "Cloth_Block_Wool_Black"
    },
    {
      "x": 4,
      "y": -1,
      "z": -7,
      "name": "Cloth_Block_Wool_Black"
    },
    {
      "x": 4,
      "y": 0,
      "z": -7,
      "name": "Cloth_Block_Wool_Black"
    },
    {
      "x": 4,
      "y": 1,
      "z": -7,
      "name": "Wood_Blackwood_Beam",
      "rotation": 5
    },
    {
      "x": 4,
      "y": 2,
      "z": -7,
      "name": "Wood_Blackwood_Beam"
    },
    {
      "x": 4,
      "y": 3,
      "z": -7,
      "name": "Wood_Blackwood_Beam"
    },
    {
      "x": 4,
      "y": 4,
      "z": -7,
      "name": "Wood_Blackwood_Beam",
      "rotation": 5
    },
    {
      "x": 4,
      "y": 5,
      "z": -7,
      "name": "Cloth_Block_Wool_Black"
    },
    {
      "x": 4,
      "y": 6,
      "z": -7,
      "name": "Cloth_Block_Wool_Black"
    },
    {
      "x": 4,
      "y": 7,
      "z": -7,
      "name": "Cloth_Block_Wool_Black"
    },
    {
      "x": 4,
      "y": -3,
      "z": -6,
      "name": "Cloth_Block_Wool_Black"
    },
    {
      "x": 4,
      "y": -2,
      "z": -6,
      "name": "Red_Led_Beam",
      "rotation": 5
    },
    {
      "x": 4,
      "y": -1,
      "z": -6,
      "name": "Barrier"
    },
    {
      "x": 4,
      "y": 6,
      "z": -6,
      "name": "Barrier"
    },
    {
      "x": 4,
      "y": 7,
      "z": -6,
      "name": "Red_Led_Beam",
      "rotation": 5
    },
    {
      "x": 4,
      "y": 8,
      "z": -6,
      "name": "Cloth_Block_Wool_Black"
    },
    {
      "x": 4,
      "y": -2,
      "z": -5,
      "name": "Cloth_Block_Wool_Black"
    },
    {
      "x": 4,
      "y": -1,
      "z": -5,
      "name": "Cloth_Block_Wool_Black"
    },
    {
      "x": 4,
      "y": 6,
      "z": -5,
      "name": "Cloth_Block_Wool_Black"
    },
    {
      "x": 4,
      "y": 7,
      "z": -5,
      "name": "Cloth_Block_Wool_Black"
    },
    {
      "x": 4,
      "y": -1,
      "z": -4,
      "name": "Cloth_Block_Wool_Black"
    },
    {
      "x": 4,
      "y": 6,
      "z": -4,
      "name": "Cloth_Block_Wool_Black"
    },
    {
      "x": 4,
      "y": -1,
      "z": -3,
      "name": "Cloth_Block_Wool_Black"
    },
    {
      "x": 4,
      "y": 6,
      "z": -3,
      "name": "Cloth_Block_Wool_Black"
    },
    {
      "x": 4,
      "y": -1,
      "z": -2,
      "name": "Cloth_Block_Wool_Black"
    },
    {
      "x": 4,
      "y": 6,
      "z": -2,
      "name": "Cloth_Block_Wool_Black"
    },
    {
      "x": 4,
      "y": -1,
      "z": -1,
      "name": "Cloth_Block_Wool_Black"
    },
    {
      "x": 4,
      "y": 6,
      "z": -1,
      "name": "Cloth_Block_Wool_Black"
    },
    {
      "x": 4,
      "y": -1,
      "z": 0,
      "name": "Cloth_Block_Wool_Black"
    },
    {
      "x": 4,
      "y": 6,
      "z": 0,
      "name": "Cloth_Block_Wool_Black"
    },
    {
      "x": 4,
      "y": -1,
      "z": 1,
      "name": "Cloth_Block_Wool_Black"
    },
    {
      "x": 4,
      "y": 6,
      "z": 1,
      "name": "Cloth_Block_Wool_Black"
    },
    {
      "x": 4,
      "y": -1,
      "z": 2,
      "name": "Cloth_Block_Wool_Black"
    },
    {
      "x": 4,
      "y": 6,
      "z": 2,
      "name": "Cloth_Block_Wool_Black"
    },
    {
      "x": 4,
      "y": -1,
      "z": 3,
      "name": "Cloth_Block_Wool_Black"
    },
    {
      "x": 4,
      "y": 6,
      "z": 3,
      "name": "Cloth_Block_Wool_Black"
    },
    {
      "x": 4,
      "y": -1,
      "z": 4,
      "name": "Cloth_Block_Wool_Black"
    },
    {
      "x": 4,
      "y": 6,
      "z": 4,
      "name": "Cloth_Block_Wool_Black"
    },
    {
      "x": 4,
      "y": -2,
      "z": 5,
      "name": "Cloth_Block_Wool_Black"
    },
    {
      "x": 4,
      "y": -1,
      "z": 5,
      "name": "Cloth_Block_Wool_Black"
    },
    {
      "x": 4,
      "y": 6,
      "z": 5,
      "name": "Cloth_Block_Wool_Black"
    },
    {
      "x": 4,
      "y": 7,
      "z": 5,
      "name": "Cloth_Block_Wool_Black"
    },
    {
      "x": 4,
      "y": -3,
      "z": 6,
      "name": "Cloth_Block_Wool_Black"
    },
    {
      "x": 4,
      "y": -2,
      "z": 6,
      "name": "Red_Led_Beam",
      "rotation": 5
    },
    {
      "x": 4,
      "y": -1,
      "z": 6,
      "name": "Barrier"
    },
    {
      "x": 4,
      "y": 6,
      "z": 6,
      "name": "Barrier"
    },
    {
      "x": 4,
      "y": 7,
      "z": 6,
      "name": "Red_Led_Beam",
      "rotation": 5
    },
    {
      "x": 4,
      "y": 8,
      "z": 6,
      "name": "Cloth_Block_Wool_Black"
    },
    {
      "x": 4,
      "y": -2,
      "z": 7,
      "name": "Cloth_Block_Wool_Black"
    },
    {
      "x": 4,
      "y": -1,
      "z": 7,
      "name": "Cloth_Block_Wool_Black"
    },
    {
      "x": 4,
      "y": 0,
      "z": 7,
      "name": "Cloth_Block_Wool_Black"
    },
    {
      "x": 4,
      "y": 1,
      "z": 7,
      "name": "Wood_Blackwood_Beam",
      "rotation": 5
    },
    {
      "x": 4,
      "y": 2,
      "z": 7,
      "name": "Wood_Blackwood_Beam"
    },
    {
      "x": 4,
      "y": 3,
      "z": 7,
      "name": "Wood_Blackwood_Beam"
    },
    {
      "x": 4,
      "y": 4,
      "z": 7,
      "name": "Wood_Blackwood_Beam",
      "rotation": 5
    },
    {
      "x": 4,
      "y": 5,
      "z": 7,
      "name": "Cloth_Block_Wool_Black"
    },
    {
      "x": 4,
      "y": 6,
      "z": 7,
      "name": "Cloth_Block_Wool_Black"
    },
    {
      "x": 4,
      "y": 7,
      "z": 7,
      "name": "Cloth_Block_Wool_Black"
    },
    {
      "x": 4,
      "y": 2,
      "z": 8,
      "name": "Barrier"
    },
    {
      "x": 4,
      "y": 3,
      "z": 8,
      "name": "Barrier"
    },
    {
      "x": 5,
      "y": -2,
      "z": -7,
      "name": "Cloth_Block_Wool_Black"
    },
    {
      "x": 5,
      "y": -1,
      "z": -7,
      "name": "Cloth_Block_Wool_Black"
    },
    {
      "x": 5,
      "y": 0,
      "z": -7,
      "name": "Cloth_Block_Wool_Black"
    },
    {
      "x": 5,
      "y": 1,
      "z": -7,
      "name": "Wood_Blackwood_Beam",
      "rotation": 5
    },
    {
      "x": 5,
      "y": 2,
      "z": -7,
      "name": "Wood_Blackwood_Beam",
      "rotation": 5
    },
    {
      "x": 5,
      "y": 3,
      "z": -7,
      "name": "Wood_Blackwood_Beam",
      "rotation": 5
    },
    {
      "x": 5,
      "y": 4,
      "z": -7,
      "name": "Wood_Blackwood_Beam",
      "rotation": 5
    },
    {
      "x": 5,
      "y": 5,
      "z": -7,
      "name": "Cloth_Block_Wool_Black"
    },
    {
      "x": 5,
      "y": 6,
      "z": -7,
      "name": "Cloth_Block_Wool_Black"
    },
    {
      "x": 5,
      "y": 7,
      "z": -7,
      "name": "Cloth_Block_Wool_Black"
    },
    {
      "x": 5,
      "y": -3,
      "z": -6,
      "name": "Cloth_Block_Wool_Black"
    },
    {
      "x": 5,
      "y": -2,
      "z": -6,
      "name": "Red_Led_Beam",
      "rotation": 5
    },
    {
      "x": 5,
      "y": -1,
      "z": -6,
      "name": "Barrier"
    },
    {
      "x": 5,
      "y": 6,
      "z": -6,
      "name": "Barrier"
    },
    {
      "x": 5,
      "y": 7,
      "z": -6,
      "name": "Red_Led_Beam",
      "rotation": 5
    },
    {
      "x": 5,
      "y": 8,
      "z": -6,
      "name": "Cloth_Block_Wool_Black"
    },
    {
      "x": 5,
      "y": -2,
      "z": -5,
      "name": "Cloth_Block_Wool_Black"
    },
    {
      "x": 5,
      "y": -1,
      "z": -5,
      "name": "Cloth_Block_Wool_Black"
    },
    {
      "x": 5,
      "y": 6,
      "z": -5,
      "name": "Cloth_Block_Wool_Black"
    },
    {
      "x": 5,
      "y": 7,
      "z": -5,
      "name": "Cloth_Block_Wool_Black"
    },
    {
      "x": 5,
      "y": -2,
      "z": -4,
      "name": "Cloth_Block_Wool_Black"
    },
    {
      "x": 5,
      "y": -1,
      "z": -4,
      "name": "Cloth_Block_Wool_Black"
    },
    {
      "x": 5,
      "y": 6,
      "z": -4,
      "name": "Cloth_Block_Wool_Black"
    },
    {
      "x": 5,
      "y": 7,
      "z": -4,
      "name": "Cloth_Block_Wool_Black"
    },
    {
      "x": 5,
      "y": -2,
      "z": -3,
      "name": "Cloth_Block_Wool_Black"
    },
    {
      "x": 5,
      "y": -1,
      "z": -3,
      "name": "Cloth_Block_Wool_Black"
    },
    {
      "x": 5,
      "y": 6,
      "z": -3,
      "name": "Cloth_Block_Wool_Black"
    },
    {
      "x": 5,
      "y": 7,
      "z": -3,
      "name": "Cloth_Block_Wool_Black"
    },
    {
      "x": 5,
      "y": -2,
      "z": -2,
      "name": "Cloth_Block_Wool_Black"
    },
    {
      "x": 5,
      "y": -1,
      "z": -2,
      "name": "Cloth_Block_Wool_Black"
    },
    {
      "x": 5,
      "y": 6,
      "z": -2,
      "name": "Cloth_Block_Wool_Black"
    },
    {
      "x": 5,
      "y": 7,
      "z": -2,
      "name": "Cloth_Block_Wool_Black"
    },
    {
      "x": 5,
      "y": -2,
      "z": -1,
      "name": "Cloth_Block_Wool_Black"
    },
    {
      "x": 5,
      "y": -1,
      "z": -1,
      "name": "Cloth_Block_Wool_Black"
    },
    {
      "x": 5,
      "y": 6,
      "z": -1,
      "name": "Cloth_Block_Wool_Black"
    },
    {
      "x": 5,
      "y": 7,
      "z": -1,
      "name": "Cloth_Block_Wool_Black"
    },
    {
      "x": 5,
      "y": -1,
      "z": 0,
      "name": "Cloth_Block_Wool_Black"
    },
    {
      "x": 5,
      "y": 6,
      "z": 0,
      "name": "Cloth_Block_Wool_Black"
    },
    {
      "x": 5,
      "y": -2,
      "z": 1,
      "name": "Cloth_Block_Wool_Black"
    },
    {
      "x": 5,
      "y": -1,
      "z": 1,
      "name": "Cloth_Block_Wool_Black"
    },
    {
      "x": 5,
      "y": 6,
      "z": 1,
      "name": "Cloth_Block_Wool_Black"
    },
    {
      "x": 5,
      "y": 7,
      "z": 1,
      "name": "Cloth_Block_Wool_Black"
    },
    {
      "x": 5,
      "y": -2,
      "z": 2,
      "name": "Cloth_Block_Wool_Black"
    },
    {
      "x": 5,
      "y": -1,
      "z": 2,
      "name": "Cloth_Block_Wool_Black"
    },
    {
      "x": 5,
      "y": 6,
      "z": 2,
      "name": "Cloth_Block_Wool_Black"
    },
    {
      "x": 5,
      "y": 7,
      "z": 2,
      "name": "Cloth_Block_Wool_Black"
    },
    {
      "x": 5,
      "y": -2,
      "z": 3,
      "name": "Cloth_Block_Wool_Black"
    },
    {
      "x": 5,
      "y": -1,
      "z": 3,
      "name": "Cloth_Block_Wool_Black"
    },
    {
      "x": 5,
      "y": 6,
      "z": 3,
      "name": "Cloth_Block_Wool_Black"
    },
    {
      "x": 5,
      "y": 7,
      "z": 3,
      "name": "Cloth_Block_Wool_Black"
    },
    {
      "x": 5,
      "y": -2,
      "z": 4,
      "name": "Cloth_Block_Wool_Black"
    },
    {
      "x": 5,
      "y": -1,
      "z": 4,
      "name": "Cloth_Block_Wool_Black"
    },
    {
      "x": 5,
      "y": 6,
      "z": 4,
      "name": "Cloth_Block_Wool_Black"
    },
    {
      "x": 5,
      "y": 7,
      "z": 4,
      "name": "Cloth_Block_Wool_Black"
    },
    {
      "x": 5,
      "y": -2,
      "z": 5,
      "name": "Cloth_Block_Wool_Black"
    },
    {
      "x": 5,
      "y": -1,
      "z": 5,
      "name": "Cloth_Block_Wool_Black"
    },
    {
      "x": 5,
      "y": 6,
      "z": 5,
      "name": "Cloth_Block_Wool_Black"
    },
    {
      "x": 5,
      "y": 7,
      "z": 5,
      "name": "Cloth_Block_Wool_Black"
    },
    {
      "x": 5,
      "y": -3,
      "z": 6,
      "name": "Cloth_Block_Wool_Black"
    },
    {
      "x": 5,
      "y": -2,
      "z": 6,
      "name": "Red_Led_Beam",
      "rotation": 5
    },
    {
      "x": 5,
      "y": -1,
      "z": 6,
      "name": "Barrier"
    },
    {
      "x": 5,
      "y": 6,
      "z": 6,
      "name": "Barrier"
    },
    {
      "x": 5,
      "y": 7,
      "z": 6,
      "name": "Red_Led_Beam",
      "rotation": 5
    },
    {
      "x": 5,
      "y": 8,
      "z": 6,
      "name": "Cloth_Block_Wool_Black"
    },
    {
      "x": 5,
      "y": -2,
      "z": 7,
      "name": "Cloth_Block_Wool_Black"
    },
    {
      "x": 5,
      "y": -1,
      "z": 7,
      "name": "Cloth_Block_Wool_Black"
    },
    {
      "x": 5,
      "y": 0,
      "z": 7,
      "name": "Cloth_Block_Wool_Black"
    },
    {
      "x": 5,
      "y": 1,
      "z": 7,
      "name": "Wood_Blackwood_Beam",
      "rotation": 5
    },
    {
      "x": 5,
      "y": 2,
      "z": 7,
      "name": "Wood_Blackwood_Beam",
      "rotation": 5
    },
    {
      "x": 5,
      "y": 3,
      "z": 7,
      "name": "Wood_Blackwood_Beam",
      "rotation": 5
    },
    {
      "x": 5,
      "y": 4,
      "z": 7,
      "name": "Wood_Blackwood_Beam",
      "rotation": 5
    },
    {
      "x": 5,
      "y": 5,
      "z": 7,
      "name": "Cloth_Block_Wool_Black"
    },
    {
      "x": 5,
      "y": 6,
      "z": 7,
      "name": "Cloth_Block_Wool_Black"
    },
    {
      "x": 5,
      "y": 7,
      "z": 7,
      "name": "Cloth_Block_Wool_Black"
    },
    {
      "x": 6,
      "y": -1,
      "z": -7,
      "name": "Cloth_Block_Wool_Black"
    },
    {
      "x": 6,
      "y": 0,
      "z": -7,
      "name": "Cloth_Block_Wool_Black"
    },
    {
      "x": 6,
      "y": 1,
      "z": -7,
      "name": "Cloth_Block_Wool_Black"
    },
    {
      "x": 6,
      "y": 2,
      "z": -7,
      "name": "Cloth_Block_Wool_Black"
    },
    {
      "x": 6,
      "y": 3,
      "z": -7,
      "name": "Cloth_Block_Wool_Black"
    },
    {
      "x": 6,
      "y": 4,
      "z": -7,
      "name": "Cloth_Block_Wool_Black"
    },
    {
      "x": 6,
      "y": 5,
      "z": -7,
      "name": "Cloth_Block_Wool_Black"
    },
    {
      "x": 6,
      "y": 6,
      "z": -7,
      "name": "Cloth_Block_Wool_Black"
    },
    {
      "x": 6,
      "y": -2,
      "z": -6,
      "name": "Cloth_Block_Wool_Black"
    },
    {
      "x": 6,
      "y": -1,
      "z": -6,
      "name": "Cloth_Block_Wool_Black"
    },
    {
      "x": 6,
      "y": 0,
      "z": -6,
      "name": "Black_Cloth_Half"
    },
    {
      "x": 6,
      "y": 5,
      "z": -6,
      "name": "Black_Cloth_Half",
      "rotation": 8
    },
    {
      "x": 6,
      "y": 6,
      "z": -6,
      "name": "Cloth_Block_Wool_Black"
    },
    {
      "x": 6,
      "y": 7,
      "z": -6,
      "name": "Cloth_Block_Wool_Black"
    },
    {
      "x": 6,
      "y": -3,
      "z": -5,
      "name": "Cloth_Block_Wool_Black"
    },
    {
      "x": 6,
      "y": -2,
      "z": -5,
      "name": "Red_Led_Beam",
      "rotation": 4
    },
    {
      "x": 6,
      "y": -1,
      "z": -5,
      "name": "Barrier"
    },
    {
      "x": 6,
      "y": 6,
      "z": -5,
      "name": "Barrier"
    },
    {
      "x": 6,
      "y": 7,
      "z": -5,
      "name": "Red_Led_Beam",
      "rotation": 4
    },
    {
      "x": 6,
      "y": 8,
      "z": -5,
      "name": "Cloth_Block_Wool_Black"
    },
    {
      "x": 6,
      "y": -3,
      "z": -4,
      "name": "Cloth_Block_Wool_Black"
    },
    {
      "x": 6,
      "y": -2,
      "z": -4,
      "name": "Red_Led_Beam",
      "rotation": 4
    },
    {
      "x": 6,
      "y": -1,
      "z": -4,
      "name": "Barrier"
    },
    {
      "x": 6,
      "y": 6,
      "z": -4,
      "name": "Barrier"
    },
    {
      "x": 6,
      "y": 7,
      "z": -4,
      "name": "Red_Led_Beam",
      "rotation": 4
    },
    {
      "x": 6,
      "y": 8,
      "z": -4,
      "name": "Cloth_Block_Wool_Black"
    },
    {
      "x": 6,
      "y": -3,
      "z": -3,
      "name": "Cloth_Block_Wool_Black"
    },
    {
      "x": 6,
      "y": -2,
      "z": -3,
      "name": "Red_Led_Beam",
      "rotation": 4
    },
    {
      "x": 6,
      "y": -1,
      "z": -3,
      "name": "Barrier"
    },
    {
      "x": 6,
      "y": 6,
      "z": -3,
      "name": "Barrier"
    },
    {
      "x": 6,
      "y": 7,
      "z": -3,
      "name": "Red_Led_Beam",
      "rotation": 4
    },
    {
      "x": 6,
      "y": 8,
      "z": -3,
      "name": "Cloth_Block_Wool_Black"
    },
    {
      "x": 6,
      "y": -3,
      "z": -2,
      "name": "Cloth_Block_Wool_Black"
    },
    {
      "x": 6,
      "y": -2,
      "z": -2,
