{
  "version": 8,
  "blockIdVersion": 11,
  "anchorX": 0,
  "anchorY": 3,
  "anchorZ": 0,
  "blocks": [
    {
      "x": -29,
      "y": 3,
      "z": -25,
      "name": "Cloth_Block_Wool_Black"
    },
    {
      "x": -29,
      "y": 4,
      "z": -25,
      "name": "Cloth_Block_Wool_Black"
    },
    {
      "x": -29,
      "y": 5,
      "z": -25,
      "name": "Cloth_Block_Wool_Black"
    },
    {
      "x": -29,
      "y": 6,
      "z": -25,
      "name": "Cloth_Block_Wool_Black"
    },
    {
      "x": -29,
      "y": 7,
      "z": -25,
      "name": "Cloth_Block_Wool_Black"
    },
    {
      "x": -29,
      "y": 8,
      "z": -25,
      "name": "Cloth_Block_Wool_Black"
    },
    {
      "x": -29,
      "y": 9,
      "z": -25,
      "name": "Cloth_Block_Wool_Black"
    },
    {
      "x": -29,
      "y": 3,
      "z": -24,
      "name": "Cloth_Block_Wool_Black"
    },
    {
      "x": -29,
      "y": 4,
      "z": -24,
      "name": "Cloth_Block_Wool_Black"
    },
    {
      "x": -29,
      "y": 5,
      "z": -24,
      "name": "Cloth_Block_Wool_Black"
    },
    {
      "x": -29,
      "y": 6,
      "z": -24,
      "name": "Cloth_Block_Wool_Black"
    },
    {
      "x": -29,
      "y": 7,
      "z": -24,
      "name": "Cloth_Block_Wool_Black"
    },
    {
      "x": -29,
      "y": 8,
      "z": -24,
      "name": "Cloth_Block_Wool_Black"
    },
    {
      "x": -29,
      "y": 9,
      "z": -24,
      "name": "Cloth_Block_Wool_Black"
    },
    {
      "x": -29,
      "y": 3,
      "z": -23,
      "name": "Cloth_Block_Wool_Black"
    },
    {
      "x": -29,
      "y": 4,
      "z": -23,
      "name": "Cloth_Block_Wool_Black"
    },
    {
      "x": -29,
      "y": 5,
      "z": -23,
      "name": "Cloth_Block_Wool_Black"
    },
    {
      "x": -29,
      "y": 6,
      "z": -23,
      "name": "Cloth_Block_Wool_Black"
    },
    {
      "x": -29,
      "y": 7,
      "z": -23,
      "name": "Cloth_Block_Wool_Black"
    },
    {
      "x": -29,
      "y": 8,
      "z": -23,
      "name": "Cloth_Block_Wool_Black"
    },
    {
      "x": -29,
      "y": 9,
      "z": -23,
      "name": "Cloth_Block_Wool_Black"
    },
    {
      "x": -29,
      "y": 3,
      "z": -22,
      "name": "Cloth_Block_Wool_Black"
    },
    {
      "x": -29,
      "y": 4,
      "z": -22,
      "name": "Cloth_Block_Wool_Black"
    },
    {
      "x": -29,
      "y": 5,
      "z": -22,
      "name": "Cloth_Block_Wool_Black"
    },
    {
      "x": -29,
      "y": 6,
      "z": -22,
      "name": "Cloth_Block_Wool_Black"
    },
    {
      "x": -29,
      "y": 7,
      "z": -22,
      "name": "Cloth_Block_Wool_Black"
    },
    {
      "x": -29,
      "y": 8,
      "z": -22,
      "name": "Cloth_Block_Wool_Black"
    },
    {
      "x": -29,
      "y": 9,
      "z": -22,
      "name": "Cloth_Block_Wool_Black"
    },
    {
      "x": -29,
      "y": 3,
      "z": -21,
      "name": "Cloth_Block_Wool_Black"
    },
    {
      "x": -29,
      "y": 4,
      "z": -21,
      "name": "Cloth_Block_Wool_Black"
    },
    {
      "x": -29,
      "y": 5,
      "z": -21,
      "name": "Cloth_Block_Wool_Black"
    },
    {
      "x": -29,
      "y": 6,
      "z": -21,
      "name": "Cloth_Block_Wool_Black"
    },
    {
      "x": -29,
      "y": 7,
      "z": -21,
      "name": "Cloth_Block_Wool_Black"
    },
    {
      "x": -29,
      "y": 8,
      "z": -21,
      "name": "Cloth_Block_Wool_Black"
    },
    {
      "x": -29,
      "y": 9,
      "z": -21,
      "name": "Cloth_Block_Wool_Black"
    },
    {
      "x": -29,
      "y": 3,
      "z": -20,
      "name": "Cloth_Block_Wool_Black"
    },
    {
      "x": -29,
      "y": 4,
      "z": -20,
      "name": "Cloth_Block_Wool_Black"
    },
    {
      "x": -29,
      "y": 5,
      "z": -20,
      "name": "Cloth_Block_Wool_Black"
    },
    {
      "x": -29,
      "y": 6,
      "z": -20,
      "name": "Cloth_Block_Wool_Black"
    },
    {
      "x": -29,
      "y": 7,
      "z": -20,
      "name": "Cloth_Block_Wool_Black"
    },
    {
      "x": -29,
      "y": 8,
      "z": -20,
      "name": "Cloth_Block_Wool_Black"
    },
    {
      "x": -29,
      "y": 9,
      "z": -20,
      "name": "Cloth_Block_Wool_Black"
    },
    {
      "x": -29,
      "y": 3,
      "z": -19,
      "name": "Cloth_Block_Wool_Black"
    },
    {
      "x": -29,
      "y": 4,
      "z": -19,
      "name": "Cloth_Block_Wool_Black"
    },
    {
      "x": -29,
      "y": 5,
      "z": -19,
      "name": "Cloth_Block_Wool_Black"
    },
    {
      "x": -29,
      "y": 6,
      "z": -19,
      "name": "Cloth_Block_Wool_Black"
    },
    {
      "x": -29,
      "y": 7,
      "z": -19,
      "name": "Cloth_Block_Wool_Black"
    },
    {
      "x": -29,
      "y": 8,
      "z": -19,
      "name": "Cloth_Block_Wool_Black"
    },
    {
      "x": -29,
      "y": 9,
      "z": -19,
      "name": "Cloth_Block_Wool_Black"
    },
    {
      "x": -29,
      "y": 3,
      "z": -18,
      "name": "Cloth_Block_Wool_Black"
    },
    {
      "x": -29,
      "y": 4,
      "z": -18,
      "name": "Cloth_Block_Wool_Black"
    },
    {
      "x": -29,
      "y": 5,
      "z": -18,
      "name": "Cloth_Block_Wool_Black"
    },
    {
      "x": -29,
      "y": 6,
      "z": -18,
      "name": "Cloth_Block_Wool_Black"
    },
    {
      "x": -29,
      "y": 7,
      "z": -18,
      "name": "Cloth_Block_Wool_Black"
    },
    {
      "x": -29,
      "y": 8,
      "z": -18,
      "name": "Cloth_Block_Wool_Black"
    },
    {
      "x": -29,
      "y": 9,
      "z": -18,
      "name": "Cloth_Block_Wool_Black"
    },
    {
      "x": -29,
      "y": 3,
      "z": -17,
      "name": "Cloth_Block_Wool_Black"
    },
    {
      "x": -29,
      "y": 4,
      "z": -17,
      "name": "Cloth_Block_Wool_Black"
    },
    {
      "x": -29,
      "y": 5,
      "z": -17,
      "name": "Cloth_Block_Wool_Black"
    },
    {
      "x": -29,
      "y": 6,
      "z": -17,
      "name": "Cloth_Block_Wool_Black"
    },
    {
      "x": -29,
      "y": 7,
      "z": -17,
      "name": "Cloth_Block_Wool_Black"
    },
    {
      "x": -29,
      "y": 8,
      "z": -17,
      "name": "Cloth_Block_Wool_Black"
    },
    {
      "x": -29,
      "y": 9,
      "z": -17,
      "name": "Cloth_Block_Wool_Black"
    },
    {
      "x": -29,
      "y": 3,
      "z": -16,
      "name": "Cloth_Block_Wool_Black"
    },
    {
      "x": -29,
      "y": 4,
      "z": -16,
      "name": "Cloth_Block_Wool_Black"
    },
    {
      "x": -29,
      "y": 5,
      "z": -16,
      "name": "Cloth_Block_Wool_Black"
    },
    {
      "x": -29,
      "y": 6,
      "z": -16,
      "name": "Cloth_Block_Wool_Black"
    },
    {
      "x": -29,
      "y": 7,
      "z": -16,
      "name": "Cloth_Block_Wool_Black"
    },
    {
      "x": -29,
      "y": 8,
      "z": -16,
      "name": "Cloth_Block_Wool_Black"
    },
    {
      "x": -29,
      "y": 9,
      "z": -16,
      "name": "Cloth_Block_Wool_Black"
    },
    {
      "x": -29,
      "y": 3,
      "z": -15,
      "name": "Cloth_Block_Wool_Black"
    },
    {
      "x": -29,
      "y": 4,
      "z": -15,
      "name": "Cloth_Block_Wool_Black"
    },
    {
      "x": -29,
      "y": 5,
      "z": -15,
      "name": "Cloth_Block_Wool_Black"
    },
    {
      "x": -29,
      "y": 6,
      "z": -15,
      "name": "Cloth_Block_Wool_Black"
    },
    {
      "x": -29,
      "y": 7,
      "z": -15,
      "name": "Cloth_Block_Wool_Black"
    },
    {
      "x": -29,
      "y": 8,
      "z": -15,
      "name": "Cloth_Block_Wool_Black"
    },
    {
      "x": -29,
      "y": 9,
      "z": -15,
      "name": "Cloth_Block_Wool_Black"
    },
    {
      "x": -29,
      "y": 3,
      "z": -14,
      "name": "Cloth_Block_Wool_Black"
    },
    {
      "x": -29,
      "y": 4,
      "z": -14,
      "name": "Cloth_Block_Wool_Black"
    },
    {
      "x": -29,
      "y": 5,
      "z": -14,
      "name": "Cloth_Block_Wool_Black"
    },
    {
      "x": -29,
      "y": 6,
      "z": -14,
      "name": "Cloth_Block_Wool_Black"
    },
    {
      "x": -29,
      "y": 7,
      "z": -14,
      "name": "Cloth_Block_Wool_Black"
    },
    {
      "x": -29,
      "y": 8,
      "z": -14,
      "name": "Cloth_Block_Wool_Black"
    },
    {
      "x": -29,
      "y": 9,
      "z": -14,
      "name": "Cloth_Block_Wool_Black"
    },
    {
      "x": -29,
      "y": 3,
      "z": -13,
      "name": "Cloth_Block_Wool_Black"
    },
    {
      "x": -29,
      "y": 4,
      "z": -13,
      "name": "Cloth_Block_Wool_Black"
    },
    {
      "x": -29,
      "y": 5,
      "z": -13,
      "name": "Cloth_Block_Wool_Black"
    },
    {
      "x": -29,
      "y": 6,
      "z": -13,
      "name": "Cloth_Block_Wool_Black"
    },
    {
      "x": -29,
      "y": 7,
      "z": -13,
      "name": "Cloth_Block_Wool_Black"
    },
    {
      "x": -29,
      "y": 8,
      "z": -13,
      "name": "Cloth_Block_Wool_Black"
    },
    {
      "x": -29,
      "y": 9,
      "z": -13,
      "name": "Cloth_Block_Wool_Black"
    },
    {
      "x": -29,
      "y": 3,
      "z": -12,
      "name": "Cloth_Block_Wool_Black"
    },
    {
      "x": -29,
      "y": 4,
      "z": -12,
      "name": "Cloth_Block_Wool_Black"
    },
    {
      "x": -29,
      "y": 5,
      "z": -12,
      "name": "Cloth_Block_Wool_Black"
    },
    {
      "x": -29,
      "y": 6,
      "z": -12,
      "name": "Cloth_Block_Wool_Black"
    },
    {
      "x": -29,
      "y": 7,
      "z": -12,
      "name": "Cloth_Block_Wool_Black"
    },
    {
      "x": -29,
      "y": 8,
      "z": -12,
      "name": "Cloth_Block_Wool_Black"
    },
    {
      "x": -29,
      "y": 9,
      "z": -12,
      "name": "Cloth_Block_Wool_Black"
    },
    {
      "x": -29,
      "y": 3,
      "z": -11,
      "name": "Cloth_Block_Wool_Black"
    },
    {
      "x": -29,
      "y": 4,
      "z": -11,
      "name": "Cloth_Block_Wool_Black"
    },
    {
      "x": -29,
      "y": 5,
      "z": -11,
      "name": "Cloth_Block_Wool_Black"
    },
    {
      "x": -29,
      "y": 6,
      "z": -11,
      "name": "Cloth_Block_Wool_Black"
    },
    {
      "x": -29,
      "y": 7,
      "z": -11,
      "name": "Cloth_Block_Wool_Black"
    },
    {
      "x": -29,
      "y": 8,
      "z": -11,
      "name": "Cloth_Block_Wool_Black"
    },
    {
      "x": -29,
      "y": 9,
      "z": -11,
      "name": "Cloth_Block_Wool_Black"
    },
    {
      "x": -29,
      "y": 3,
      "z": -10,
      "name": "Cloth_Block_Wool_Black"
    },
    {
      "x": -29,
      "y": 4,
      "z": -10,
      "name": "Cloth_Block_Wool_Black"
    },
    {
      "x": -29,
      "y": 5,
      "z": -10,
      "name": "Cloth_Block_Wool_Black"
    },
    {
      "x": -29,
      "y": 6,
      "z": -10,
      "name": "Cloth_Block_Wool_Black"
    },
    {
      "x": -29,
      "y": 7,
      "z": -10,
      "name": "Cloth_Block_Wool_Black"
    },
    {
      "x": -29,
      "y": 8,
      "z": -10,
      "name": "Cloth_Block_Wool_Black"
    },
    {
      "x": -29,
      "y": 9,
      "z": -10,
      "name": "Cloth_Block_Wool_Black"
    },
    {
      "x": -29,
      "y": 3,
      "z": -9,
      "name": "Cloth_Block_Wool_Black"
    },
    {
      "x": -29,
      "y": 4,
      "z": -9,
      "name": "Cloth_Block_Wool_Black"
    },
    {
      "x": -29,
      "y": 5,
      "z": -9,
      "name": "Cloth_Block_Wool_Black"
    },
    {
      "x": -29,
      "y": 6,
      "z": -9,
      "name": "Cloth_Block_Wool_Black"
    },
    {
      "x": -29,
      "y": 7,
      "z": -9,
      "name": "Cloth_Block_Wool_Black"
    },
    {
      "x": -29,
      "y": 8,
      "z": -9,
      "name": "Cloth_Block_Wool_Black"
    },
    {
      "x": -29,
      "y": 9,
      "z": -9,
      "name": "Cloth_Block_Wool_Black"
    },
    {
      "x": -29,
      "y": 3,
      "z": -8,
      "name": "Cloth_Block_Wool_Black"
    },
    {
      "x": -29,
      "y": 4,
      "z": -8,
      "name": "Cloth_Block_Wool_Black"
    },
    {
      "x": -29,
      "y": 5,
      "z": -8,
      "name": "Cloth_Block_Wool_Black"
    },
    {
      "x": -29,
      "y": 6,
      "z": -8,
      "name": "Cloth_Block_Wool_Black"
    },
    {
      "x": -29,
      "y": 7,
      "z": -8,
      "name": "Cloth_Block_Wool_Black"
    },
    {
      "x": -29,
      "y": 8,
      "z": -8,
      "name": "Cloth_Block_Wool_Black"
    },
    {
      "x": -29,
      "y": 9,
      "z": -8,
      "name": "Cloth_Block_Wool_Black"
    },
    {
      "x": -29,
      "y": 3,
      "z": -7,
      "name": "Cloth_Block_Wool_Black"
    },
    {
      "x": -29,
      "y": 4,
      "z": -7,
      "name": "Cloth_Block_Wool_Black"
    },
    {
      "x": -29,
      "y": 5,
      "z": -7,
      "name": "Cloth_Block_Wool_Black"
    },
    {
      "x": -29,
      "y": 6,
      "z": -7,
      "name": "Cloth_Block_Wool_Black"
    },
    {
      "x": -29,
      "y": 7,
      "z": -7,
      "name": "Cloth_Block_Wool_Black"
    },
    {
      "x": -29,
      "y": 8,
      "z": -7,
      "name": "Cloth_Block_Wool_Black"
    },
    {
      "x": -29,
      "y": 9,
      "z": -7,
      "name": "Cloth_Block_Wool_Black"
    },
    {
      "x": -29,
      "y": 3,
      "z": -6,
      "name": "Cloth_Block_Wool_Black"
    },
    {
      "x": -29,
      "y": 4,
      "z": -6,
      "name": "Cloth_Block_Wool_Black"
    },
    {
      "x": -29,
      "y": 5,
      "z": -6,
      "name": "Cloth_Block_Wool_Black"
    },
    {
      "x": -29,
      "y": 6,
      "z": -6,
      "name": "Cloth_Block_Wool_Black"
    },
    {
      "x": -29,
      "y": 7,
      "z": -6,
      "name": "Cloth_Block_Wool_Black"
    },
    {
      "x": -29,
      "y": 8,
      "z": -6,
      "name": "Cloth_Block_Wool_Black"
    },
    {
      "x": -29,
      "y": 9,
      "z": -6,
      "name": "Cloth_Block_Wool_Black"
    },
    {
      "x": -29,
      "y": 3,
      "z": -5,
      "name": "Cloth_Block_Wool_Black"
    },
    {
      "x": -29,
      "y": 4,
      "z": -5,
      "name": "Cloth_Block_Wool_Black"
    },
    {
      "x": -29,
      "y": 5,
      "z": -5,
      "name": "Cloth_Block_Wool_Black"
    },
    {
      "x": -29,
      "y": 6,
      "z": -5,
      "name": "Cloth_Block_Wool_Black"
    },
    {
      "x": -29,
      "y": 7,
      "z": -5,
      "name": "Cloth_Block_Wool_Black"
    },
    {
      "x": -29,
      "y": 8,
      "z": -5,
      "name": "Cloth_Block_Wool_Black"
    },
    {
      "x": -29,
      "y": 9,
      "z": -5,
      "name": "Cloth_Block_Wool_Black"
    },
    {
      "x": -29,
      "y": 3,
      "z": -4,
      "name": "Cloth_Block_Wool_Black"
    },
    {
      "x": -29,
      "y": 4,
      "z": -4,
      "name": "Cloth_Block_Wool_Black"
    },
    {
      "x": -29,
      "y": 5,
      "z": -4,
      "name": "Cloth_Block_Wool_Black"
    },
    {
      "x": -29,
      "y": 6,
      "z": -4,
      "name": "Cloth_Block_Wool_Black"
    },
    {
      "x": -29,
      "y": 7,
      "z": -4,
      "name": "Cloth_Block_Wool_Black"
    },
    {
      "x": -29,
      "y": 8,
      "z": -4,
      "name": "Cloth_Block_Wool_Black"
    },
    {
      "x": -29,
      "y": 9,
      "z": -4,
      "name": "Cloth_Block_Wool_Black"
    },
    {
      "x": -29,
      "y": 3,
      "z": -3,
      "name": "Cloth_Block_Wool_Black"
    },
    {
      "x": -29,
      "y": 4,
      "z": -3,
      "name": "Cloth_Block_Wool_Black"
    },
    {
      "x": -29,
      "y": 5,
      "z": -3,
      "name": "Cloth_Block_Wool_Black"
    },
    {
      "x": -29,
      "y": 6,
      "z": -3,
      "name": "Cloth_Block_Wool_Black"
    },
    {
      "x": -29,
      "y": 7,
      "z": -3,
      "name": "Cloth_Block_Wool_Black"
    },
    {
      "x": -29,
      "y": 8,
      "z": -3,
      "name": "Cloth_Block_Wool_Black"
    },
    {
      "x": -29,
      "y": 9,
      "z": -3,
      "name": "Cloth_Block_Wool_Black"
    },
    {
      "x": -29,
      "y": 3,
      "z": -2,
      "name": "Cloth_Block_Wool_Black"
    },
    {
      "x": -29,
      "y": 4,
      "z": -2,
      "name": "Cloth_Block_Wool_Black"
    },
    {
      "x": -29,
      "y": 5,
      "z": -2,
      "name": "Cloth_Block_Wool_Black"
    },
    {
      "x": -29,
      "y": 6,
      "z": -2,
      "name": "Cloth_Block_Wool_Black"
    },
    {
      "x": -29,
      "y": 7,
      "z": -2,
      "name": "Cloth_Block_Wool_Black"
    },
    {
      "x": -29,
      "y": 8,
      "z": -2,
      "name": "Cloth_Block_Wool_Black"
    },
    {
      "x": -29,
      "y": 9,
      "z": -2,
      "name": "Cloth_Block_Wool_Black"
    },
    {
      "x": -29,
      "y": 3,
      "z": -1,
      "name": "Cloth_Block_Wool_Black"
    },
    {
      "x": -29,
      "y": 4,
      "z": -1,
      "name": "Cloth_Block_Wool_Black"
    },
    {
      "x": -29,
      "y": 5,
      "z": -1,
      "name": "Cloth_Block_Wool_Black"
    },
    {
      "x": -29,
      "y": 6,
      "z": -1,
      "name": "Cloth_Block_Wool_Black"
    },
    {
      "x": -29,
      "y": 7,
      "z": -1,
      "name": "Cloth_Block_Wool_Black"
    },
    {
      "x": -29,
      "y": 8,
      "z": -1,
      "name": "Cloth_Block_Wool_Black"
    },
    {
      "x": -29,
      "y": 9,
      "z": -1,
      "name": "Cloth_Block_Wool_Black"
    },
    {
      "x": -29,
      "y": 3,
      "z": 0,
      "name": "Cloth_Block_Wool_Black"
    },
    {
      "x": -29,
      "y": 4,
      "z": 0,
      "name": "Cloth_Block_Wool_Black"
    },
    {
      "x": -29,
      "y": 5,
      "z": 0,
      "name": "Cloth_Block_Wool_Black"
    },
    {
      "x": -29,
      "y": 6,
      "z": 0,
      "name": "Cloth_Block_Wool_Black"
    },
    {
      "x": -29,
      "y": 7,
      "z": 0,
      "name": "Cloth_Block_Wool_Black"
    },
    {
      "x": -29,
      "y": 8,
      "z": 0,
      "name": "Cloth_Block_Wool_Black"
    },
    {
      "x": -29,
      "y": 9,
      "z": 0,
      "name": "Cloth_Block_Wool_Black"
    },
    {
      "x": -29,
      "y": 3,
      "z": 1,
      "name": "Cloth_Block_Wool_Black"
    },
    {
      "x": -29,
      "y": 4,
      "z": 1,
      "name": "Cloth_Block_Wool_Black"
    },
    {
      "x": -29,
      "y": 5,
      "z": 1,
      "name": "Cloth_Block_Wool_Black"
    },
    {
      "x": -29,
      "y": 6,
      "z": 1,
      "name": "Cloth_Block_Wool_Black"
    },
    {
      "x": -29,
      "y": 7,
      "z": 1,
      "name": "Cloth_Block_Wool_Black"
    },
    {
      "x": -29,
      "y": 8,
      "z": 1,
      "name": "Cloth_Block_Wool_Black"
    },
    {
      "x": -29,
      "y": 9,
      "z": 1,
      "name": "Cloth_Block_Wool_Black"
    },
    {
      "x": -29,
      "y": 3,
      "z": 2,
      "name": "Cloth_Block_Wool_Black"
    },
    {
      "x": -29,
      "y": 4,
      "z": 2,
      "name": "Cloth_Block_Wool_Black"
    },
    {
      "x": -29,
      "y": 5,
      "z": 2,
      "name": "Cloth_Block_Wool_Black"
    },
    {
      "x": -29,
      "y": 6,
      "z": 2,
      "name": "Cloth_Block_Wool_Black"
    },
    {
      "x": -29,
      "y": 7,
      "z": 2,
      "name": "Cloth_Block_Wool_Black"
    },
    {
      "x": -29,
      "y": 8,
      "z": 2,
      "name": "Cloth_Block_Wool_Black"
    },
    {
      "x": -29,
      "y": 9,
      "z": 2,
      "name": "Cloth_Block_Wool_Black"
    },
    {
      "x": -29,
      "y": 3,
      "z": 3,
      "name": "Cloth_Block_Wool_Black"
    },
    {
      "x": -29,
      "y": 4,
      "z": 3,
      "name": "Cloth_Block_Wool_Black"
    },
    {
      "x": -29,
      "y": 5,
      "z": 3,
      "name": "Cloth_Block_Wool_Black"
    },
    {
      "x": -29,
      "y": 6,
      "z": 3,
      "name": "Cloth_Block_Wool_Black"
    },
    {
      "x": -29,
      "y": 7,
      "z": 3,
      "name": "Cloth_Block_Wool_Black"
    },
    {
      "x": -29,
      "y": 8,
      "z": 3,
      "name": "Cloth_Block_Wool_Black"
    },
    {
      "x": -29,
      "y": 9,
      "z": 3,
      "name": "Cloth_Block_Wool_Black"
    },
    {
      "x": -29,
      "y": 3,
      "z": 4,
      "name": "Cloth_Block_Wool_Black"
    },
    {
      "x": -29,
      "y": 4,
      "z": 4,
      "name": "Cloth_Block_Wool_Black"
    },
    {
      "x": -29,
      "y": 5,
      "z": 4,
      "name": "Cloth_Block_Wool_Black"
    },
    {
      "x": -29,
      "y": 6,
      "z": 4,
      "name": "Cloth_Block_Wool_Black"
    },
    {
      "x": -29,
      "y": 7,
      "z": 4,
      "name": "Cloth_Block_Wool_Black"
    },
    {
      "x": -29,
      "y": 8,
      "z": 4,
      "name": "Cloth_Block_Wool_Black"
    },
    {
      "x": -29,
      "y": 9,
      "z": 4,
      "name": "Cloth_Block_Wool_Black"
    },
    {
      "x": -29,
      "y": 3,
      "z": 5,
      "name": "Cloth_Block_Wool_Black"
    },
    {
      "x": -29,
      "y": 4,
      "z": 5,
      "name": "Cloth_Block_Wool_Black"
    },
    {
      "x": -29,
      "y": 5,
      "z": 5,
      "name": "Cloth_Block_Wool_Black"
    },
    {
      "x": -29,
      "y": 6,
      "z": 5,
      "name": "Cloth_Block_Wool_Black"
    },
    {
      "x": -29,
      "y": 7,
      "z": 5,
      "name": "Cloth_Block_Wool_Black"
    },
    {
      "x": -29,
      "y": 8,
      "z": 5,
      "name": "Cloth_Block_Wool_Black"
    },
    {
      "x": -29,
      "y": 9,
      "z": 5,
      "name": "Cloth_Block_Wool_Black"
    },
    {
      "x": -29,
      "y": 3,
      "z": 6,
      "name": "Cloth_Block_Wool_Black"
    },
    {
      "x": -29,
      "y": 4,
      "z": 6,
      "name": "Cloth_Block_Wool_Black"
    },
    {
      "x": -29,
      "y": 5,
      "z": 6,
      "name": "Cloth_Block_Wool_Black"
    },
    {
      "x": -29,
      "y": 6,
      "z": 6,
      "name": "Cloth_Block_Wool_Black"
    },
    {
      "x": -29,
      "y": 7,
      "z": 6,
      "name": "Cloth_Block_Wool_Black"
    },
    {
      "x": -29,
      "y": 8,
      "z": 6,
      "name": "Cloth_Block_Wool_Black"
    },
    {
      "x": -29,
      "y": 9,
      "z": 6,
      "name": "Cloth_Block_Wool_Black"
    },
    {
      "x": -29,
      "y": 3,
      "z": 7,
      "name": "Cloth_Block_Wool_Black"
    },
    {
      "x": -29,
      "y": 4,
      "z": 7,
      "name": "Cloth_Block_Wool_Black"
    },
    {
      "x": -29,
      "y": 5,
      "z": 7,
      "name": "Cloth_Block_Wool_Black"
    },
    {
      "x": -29,
      "y": 6,
      "z": 7,
      "name": "Cloth_Block_Wool_Black"
    },
    {
      "x": -29,
      "y": 7,
      "z": 7,
      "name": "Cloth_Block_Wool_Black"
    },
    {
      "x": -29,
      "y": 8,
      "z": 7,
      "name": "Cloth_Block_Wool_Black"
    },
    {
      "x": -29,
      "y": 9,
      "z": 7,
      "name": "Cloth_Block_Wool_Black"
    },
    {
      "x": -29,
      "y": 3,
      "z": 8,
      "name": "Cloth_Block_Wool_Black"
    },
    {
      "x": -29,
      "y": 4,
      "z": 8,
      "name": "Cloth_Block_Wool_Black"
    },
    {
      "x": -29,
      "y": 5,
      "z": 8,
      "name": "Cloth_Block_Wool_Black"
    },
    {
      "x": -29,
      "y": 6,
      "z": 8,
      "name": "Cloth_Block_Wool_Black"
    },
    {
      "x": -29,
      "y": 7,
      "z": 8,
      "name": "Cloth_Block_Wool_Black"
    },
    {
      "x": -29,
      "y": 8,
      "z": 8,
      "name": "Cloth_Block_Wool_Black"
    },
    {
      "x": -29,
      "y": 9,
      "z": 8,
      "name": "Cloth_Block_Wool_Black"
    },
    {
      "x": -29,
      "y": 3,
      "z": 9,
      "name": "Cloth_Block_Wool_Black"
    },
    {
      "x": -29,
      "y": 4,
      "z": 9,
      "name": "Cloth_Block_Wool_Black"
    },
    {
      "x": -29,
      "y": 5,
      "z": 9,
      "name": "Cloth_Block_Wool_Black"
    },
    {
      "x": -29,
      "y": 6,
      "z": 9,
      "name": "Cloth_Block_Wool_Black"
    },
    {
      "x": -29,
      "y": 7,
      "z": 9,
      "name": "Cloth_Block_Wool_Black"
    },
    {
      "x": -29,
      "y": 8,
      "z": 9,
      "name": "Cloth_Block_Wool_Black"
    },
    {
      "x": -29,
      "y": 9,
      "z": 9,
      "name": "Cloth_Block_Wool_Black"
    },
    {
      "x": -29,
      "y": 3,
      "z": 10,
      "name": "Cloth_Block_Wool_Black"
    },
    {
      "x": -29,
      "y": 4,
      "z": 10,
      "name": "Cloth_Block_Wool_Black"
    },
    {
      "x": -29,
      "y": 5,
      "z": 10,
      "name": "Cloth_Block_Wool_Black"
    },
    {
      "x": -29,
      "y": 6,
      "z": 10,
      "name": "Cloth_Block_Wool_Black"
    },
    {
      "x": -29,
      "y": 7,
      "z": 10,
      "name": "Cloth_Block_Wool_Black"
    },
    {
      "x": -29,
      "y": 8,
      "z": 10,
      "name": "Cloth_Block_Wool_Black"
    },
    {
      "x": -29,
      "y": 9,
      "z": 10,
      "name": "Cloth_Block_Wool_Black"
    },
    {
      "x": -29,
      "y": 3,
      "z": 11,
      "name": "Cloth_Block_Wool_Black"
    },
    {
      "x": -29,
      "y": 4,
      "z": 11,
      "name": "Cloth_Block_Wool_Black"
    },
    {
      "x": -29,
      "y": 5,
      "z": 11,
      "name": "Cloth_Block_Wool_Black"
    },
    {
      "x": -29,
      "y": 6,
      "z": 11,
      "name": "Cloth_Block_Wool_Black"
    },
    {
      "x": -29,
      "y": 7,
      "z": 11,
      "name": "Cloth_Block_Wool_Black"
    },
    {
      "x": -29,
      "y": 8,
      "z": 11,
      "name": "Cloth_Block_Wool_Black"
    },
    {
      "x": -29,
      "y": 9,
      "z": 11,
      "name": "Cloth_Block_Wool_Black"
    },
    {
      "x": -29,
      "y": 3,
      "z": 12,
      "name": "Cloth_Block_Wool_Black"
    },
    {
      "x": -29,
      "y": 4,
      "z": 12,
      "name": "Cloth_Block_Wool_Black"
    },
    {
      "x": -29,
      "y": 5,
      "z": 12,
      "name": "Cloth_Block_Wool_Black"
    },
    {
      "x": -29,
      "y": 6,
      "z": 12,
      "name": "Cloth_Block_Wool_Black"
    },
    {
      "x": -29,
      "y": 7,
      "z": 12,
      "name": "Cloth_Block_Wool_Black"
    },
    {
      "x": -29,
      "y": 8,
      "z": 12,
      "name": "Cloth_Block_Wool_Black"
    },
    {
      "x": -29,
      "y": 9,
      "z": 12,
      "name": "Cloth_Block_Wool_Black"
    },
    {
      "x": -29,
      "y": 3,
      "z": 13,
      "name": "Cloth_Block_Wool_Black"
    },
    {
      "x": -29,
      "y": 4,
      "z": 13,
      "name": "Cloth_Block_Wool_Black"
    },
    {
      "x": -29,
      "y": 5,
      "z": 13,
      "name": "Cloth_Block_Wool_Black"
    },
    {
      "x": -29,
      "y": 6,
      "z": 13,
      "name": "Cloth_Block_Wool_Black"
    },
    {
      "x": -29,
      "y": 7,
      "z": 13,
      "name": "Cloth_Block_Wool_Black"
    },
    {
      "x": -29,
      "y": 8,
      "z": 13,
      "name": "Cloth_Block_Wool_Black"
    },
    {
      "x": -29,
      "y": 9,
      "z": 13,
      "name": "Cloth_Block_Wool_Black"
    },
    {
      "x": -29,
      "y": 3,
      "z": 14,
      "name": "Cloth_Block_Wool_Black"
    },
    {
      "x": -29,
      "y": 4,
      "z": 14,
      "name": "Cloth_Block_Wool_Black"
    },
    {
      "x": -29,
      "y": 5,
      "z": 14,
      "name": "Cloth_Block_Wool_Black"
    },
    {
      "x": -29,
      "y": 6,
      "z": 14,
      "name": "Cloth_Block_Wool_Black"
    },
    {
      "x": -29,
      "y": 7,
      "z": 14,
      "name": "Cloth_Block_Wool_Black"
    },
    {
      "x": -29,
      "y": 8,
      "z": 14,
      "name": "Cloth_Block_Wool_Black"
    },
    {
      "x": -29,
      "y": 9,
      "z": 14,
      "name": "Cloth_Block_Wool_Black"
    },
    {
      "x": -29,
      "y": 3,
      "z": 15,
      "name": "Cloth_Block_Wool_Black"
    },
    {
      "x": -29,
      "y": 4,
      "z": 15,
      "name": "Cloth_Block_Wool_Black"
    },
    {
      "x": -29,
      "y": 5,
      "z": 15,
      "name": "Cloth_Block_Wool_Black"
    },
    {
      "x": -29,
      "y": 6,
      "z": 15,
      "name": "Cloth_Block_Wool_Black"
    },
    {
      "x": -29,
      "y": 7,
      "z": 15,
      "name": "Cloth_Block_Wool_Black"
    },
    {
      "x": -29,
      "y": 8,
      "z": 15,
      "name": "Cloth_Block_Wool_Black"
    },
    {
      "x": -29,
      "y": 9,
      "z": 15,
      "name": "Cloth_Block_Wool_Black"
    },
    {
      "x": -29,
      "y": 3,
      "z": 16,
      "name": "Cloth_Block_Wool_Black"
    },
    {
      "x": -29,
      "y": 4,
      "z": 16,
      "name": "Cloth_Block_Wool_Black"
    },
    {
      "x": -29,
      "y": 5,
      "z": 16,
      "name": "Cloth_Block_Wool_Black"
    },
    {
      "x": -29,
      "y": 6,
      "z": 16,
      "name": "Cloth_Block_Wool_Black"
    },
    {
      "x": -29,
      "y": 7,
      "z": 16,
      "name": "Cloth_Block_Wool_Black"
    },
    {
      "x": -29,
      "y": 8,
      "z": 16,
      "name": "Cloth_Block_Wool_Black"
    },
    {
      "x": -29,
      "y": 9,
      "z": 16,
      "name": "Cloth_Block_Wool_Black"
    },
    {
      "x": -29,
      "y": 3,
      "z": 17,
      "name": "Cloth_Block_Wool_Black"
    },
    {
      "x": -29,
      "y": 4,
      "z": 17,
      "name": "Cloth_Block_Wool_Black"
    },
    {
      "x": -29,
      "y": 5,
      "z": 17,
      "name": "Cloth_Block_Wool_Black"
    },
    {
      "x": -29,
      "y": 6,
      "z": 17,
      "name": "Cloth_Block_Wool_Black"
    },
    {
      "x": -29,
      "y": 7,
      "z": 17,
      "name": "Cloth_Block_Wool_Black"
    },
    {
      "x": -29,
      "y": 8,
      "z": 17,
      "name": "Cloth_Block_Wool_Black"
    },
    {
      "x": -29,
      "y": 9,
      "z": 17,
      "name": "Cloth_Block_Wool_Black"
    },
    {
      "x": -29,
      "y": 3,
      "z": 18,
      "name": "Cloth_Block_Wool_Black"
    },
    {
      "x": -29,
      "y": 4,
      "z": 18,
      "name": "Cloth_Block_Wool_Black"
    },
    {
      "x": -29,
      "y": 5,
      "z": 18,
      "name": "Cloth_Block_Wool_Black"
    },
    {
      "x": -29,
      "y": 6,
      "z": 18,
      "name": "Cloth_Block_Wool_Black"
    },
    {
      "x": -29,
      "y": 7,
      "z": 18,
      "name": "Cloth_Block_Wool_Black"
    },
    {
      "x": -29,
      "y": 8,
      "z": 18,
      "name": "Cloth_Block_Wool_Black"
    },
    {
      "x": -29,
      "y": 9,
      "z": 18,
      "name": "Cloth_Block_Wool_Black"
    },
    {
      "x": -29,
      "y": 3,
      "z": 19,
      "name": "Cloth_Block_Wool_Black"
    },
    {
      "x": -29,
      "y": 4,
      "z": 19,
      "name": "Cloth_Block_Wool_Black"
    },
    {
      "x": -29,
      "y": 5,
      "z": 19,
      "name": "Cloth_Block_Wool_Black"
    },
    {
      "x": -29,
      "y": 6,
      "z": 19,
      "name": "Cloth_Block_Wool_Black"
    },
    {
      "x": -29,
      "y": 7,
      "z": 19,
      "name": "Cloth_Block_Wool_Black"
    },
    {
      "x": -29,
      "y": 8,
      "z": 19,
      "name": "Cloth_Block_Wool_Black"
    },
    {
      "x": -29,
      "y": 9,
      "z": 19,
      "name": "Cloth_Block_Wool_Black"
    },
    {
      "x": -29,
      "y": 3,
      "z": 20,
      "name": "Cloth_Block_Wool_Black"
    },
    {
      "x": -29,
      "y": 4,
      "z": 20,
      "name": "Cloth_Block_Wool_Black"
    },
    {
      "x": -29,
      "y": 5,
      "z": 20,
      "name": "Cloth_Block_Wool_Black"
    },
    {
      "x": -29,
      "y": 6,
      "z": 20,
      "name": "Cloth_Block_Wool_Black"
    },
    {
      "x": -29,
      "y": 7,
      "z": 20,
      "name": "Cloth_Block_Wool_Black"
    },
    {
      "x": -29,
      "y": 8,
      "z": 20,
      "name": "Cloth_Block_Wool_Black"
    },
    {
      "x": -29,
      "y": 9,
      "z": 20,
      "name": "Cloth_Block_Wool_Black"
    },
    {
      "x": -29,
      "y": 3,
      "z": 21,
      "name": "Cloth_Block_Wool_Black"
    },
    {
      "x": -29,
      "y": 4,
      "z": 21,
      "name": "Cloth_Block_Wool_Black"
    },
    {
      "x": -29,
      "y": 5,
      "z": 21,
      "name": "Cloth_Block_Wool_Black"
    },
    {
      "x": -29,
      "y": 6,
      "z": 21,
      "name": "Cloth_Block_Wool_Black"
    },
    {
      "x": -29,
      "y": 7,
      "z": 21,
      "name": "Cloth_Block_Wool_Black"
    },
    {
      "x": -29,
      "y": 8,
      "z": 21,
      "name": "Cloth_Block_Wool_Black"
    },
    {
      "x": -29,
      "y": 9,
      "z": 21,
      "name": "Cloth_Block_Wool_Black"
    },
    {
      "x": -29,
      "y": 3,
      "z": 22,
      "name": "Cloth_Block_Wool_Black"
    },
    {
      "x": -29,
      "y": 4,
      "z": 22,
      "name": "Cloth_Block_Wool_Black"
    },
    {
      "x": -29,
      "y": 5,
      "z": 22,
      "name": "Cloth_Block_Wool_Black"
    },
    {
      "x": -29,
      "y": 6,
      "z": 22,
      "name": "Cloth_Block_Wool_Black"
    },
    {
      "x": -29,
      "y": 7,
      "z": 22,
      "name": "Cloth_Block_Wool_Black"
    },
    {
      "x": -29,
      "y": 8,
      "z": 22,
      "name": "Cloth_Block_Wool_Black"
    },
    {
      "x": -29,
      "y": 9,
      "z": 22,
      "name": "Cloth_Block_Wool_Black"
    },
    {
      "x": -29,
      "y": 3,
      "z": 23,
      "name": "Cloth_Block_Wool_Black"
    },
    {
      "x": -29,
      "y": 4,
      "z": 23,
      "name": "Cloth_Block_Wool_Black"
    },
    {
      "x": -29,
      "y": 5,
      "z": 23,
      "name": "Cloth_Block_Wool_Black"
    },
    {
      "x": -29,
      "y": 6,
      "z": 23,
      "name": "Cloth_Block_Wool_Black"
    },
    {
      "x": -29,
      "y": 7,
      "z": 23,
      "name": "Cloth_Block_Wool_Black"
    },
    {
      "x": -29,
      "y": 8,
      "z": 23,
      "name": "Cloth_Block_Wool_Black"
    },
    {
      "x": -29,
      "y": 9,
      "z": 23,
      "name": "Cloth_Block_Wool_Black"
    },
    {
      "x": -29,
      "y": 3,
      "z": 24,
      "name": "Cloth_Block_Wool_Black"
    },
    {
      "x": -29,
      "y": 4,
      "z": 24,
      "name": "Cloth_Block_Wool_Black"
    },
    {
      "x": -29,
      "y": 5,
      "z": 24,
      "name": "Cloth_Block_Wool_Black"
    },
    {
      "x": -29,
      "y": 6,
      "z": 24,
      "name": "Cloth_Block_Wool_Black"
    },
    {
      "x": -29,
      "y": 7,
      "z": 24,
      "name": "Cloth_Block_Wool_Black"
    },
    {
      "x": -29,
      "y": 8,
      "z": 24,
      "name": "Cloth_Block_Wool_Black"
    },
    {
      "x": -29,
      "y": 9,
      "z": 24,
      "name": "Cloth_Block_Wool_Black"
    },
    {
      "x": -29,
      "y": 3,
      "z": 25,
      "name": "Cloth_Block_Wool_Black"
    },
    {
      "x": -29,
      "y": 4,
      "z": 25,
      "name": "Cloth_Block_Wool_Black"
    },
    {
      "x": -29,
      "y": 5,
      "z": 25,
      "name": "Cloth_Block_Wool_Black"
    },
    {
      "x": -29,
      "y": 6,
      "z": 25,
      "name": "Cloth_Block_Wool_Black"
    },
    {
      "x": -29,
      "y": 7,
      "z": 25,
      "name": "Cloth_Block_Wool_Black"
    },
    {
      "x": -29,
      "y": 8,
      "z": 25,
      "name": "Cloth_Block_Wool_Black"
    },
    {
      "x": -29,
      "y": 9,
      "z": 25,
      "name": "Cloth_Block_Wool_Black"
    },
    {
      "x": -28,
      "y": 3,
      "z": -25,
      "name": "Cloth_Block_Wool_Black"
    },
    {
      "x": -28,
      "y": 4,
      "z": -25,
      "name": "Cloth_Block_Wool_Black"
    },
    {
      "x": -28,
      "y": 5,
      "z": -25,
      "name": "Cloth_Block_Wool_Black"
    },
    {
      "x": -28,
      "y": 6,
      "z": -25,
      "name": "Cloth_Block_Wool_Black"
    },
    {
      "x": -28,
      "y": 7,
      "z": -25,
      "name": "Cloth_Block_Wool_Black"
    },
    {
      "x": -28,
      "y": 8,
      "z": -25,
      "name": "Cloth_Block_Wool_Black"
    },
    {
      "x": -28,
      "y": 9,
      "z": -25,
      "name": "Cloth_Block_Wool_Black"
    },
    {
      "x": -28,
      "y": 3,
      "z": -24,
      "name": "Cloth_Block_Wool_Black"
    },
    {
      "x": -28,
      "y": 9,
      "z": -24,
      "name": "Cloth_Block_Wool_Black"
    },
    {
      "x": -28,
      "y": 3,
      "z": -23,
      "name": "Cloth_Block_Wool_Black"
    },
    {
      "x": -28,
      "y": 9,
      "z": -23,
      "name": "Cloth_Block_Wool_Black"
    },
    {
      "x": -28,
      "y": 3,
      "z": -22,
      "name": "Cloth_Block_Wool_Black"
    },
    {
      "x": -28,
      "y": 9,
      "z": -22,
      "name": "Cloth_Block_Wool_Black"
    },
    {
      "x": -28,
      "y": 3,
      "z": -21,
      "name": "Cloth_Block_Wool_Black"
    },
    {
      "x": -28,
      "y": 9,
      "z": -21,
      "name": "Cloth_Block_Wool_Black"
    },
    {
      "x": -28,
      "y": 3,
      "z": -20,
      "name": "Cloth_Block_Wool_Black"
    },
    {
      "x": -28,
      "y": 9,
      "z": -20,
      "name": "Cloth_Block_Wool_Black"
    },
    {
      "x": -28,
      "y": 3,
      "z": -19,
      "name": "Cloth_Block_Wool_Black"
    },
    {
      "x": -28,
      "y": 9,
      "z": -19,
      "name": "Cloth_Block_Wool_Black"
    },
    {
      "x": -28,
      "y": 3,
      "z": -18,
      "name": "Cloth_Block_Wool_Black"
    },
    {
      "x": -28,
      "y": 9,
      "z": -18,
      "name": "Cloth_Block_Wool_Black"
    },
    {
      "x": -28,
      "y": 3,
      "z": -17,
      "name": "Cloth_Block_Wool_Black"
    },
    {
      "x": -28,
      "y": 9,
      "z": -17,
      "name": "Cloth_Block_Wool_Black"
    },
    {
      "x": -28,
      "y": 3,
      "z": -16,
      "name": "Cloth_Block_Wool_Black"
    },
    {
      "x": -28,
      "y": 9,
      "z": -16,
      "name": "Cloth_Block_Wool_Black"
    },
    {
      "x": -28,
      "y": 3,
      "z": -15,
      "name": "Cloth_Block_Wool_Black"
    },
    {
      "x": -28,
      "y": 9,
      "z": -15,
      "name": "Cloth_Block_Wool_Black"
    },
    {
      "x": -28,
      "y": 3,
      "z": -14,
      "name": "Cloth_Block_Wool_Black"
    },
    {
      "x": -28,
      "y": 9,
      "z": -14,
      "name": "Cloth_Block_Wool_Black"
    },
    {
      "x": -28,
      "y": 3,
      "z": -13,
      "name": "Cloth_Block_Wool_Black"
    },
    {
      "x": -28,
      "y": 9,
      "z": -13,
      "name": "Cloth_Block_Wool_Black"
    },
    {
      "x": -28,
      "y": 3,
      "z": -12,
      "name": "Cloth_Block_Wool_Black"
    },
    {
      "x": -28,
      "y": 9,
      "z": -12,
      "name": "Cloth_Block_Wool_Black"
    },
    {
      "x": -28,
      "y": 3,
      "z": -11,
      "name": "Cloth_Block_Wool_Black"
    },
    {
      "x": -28,
      "y": 9,
      "z": -11,
      "name": "Cloth_Block_Wool_Black"
    },
    {
      "x": -28,
      "y": 3,
      "z": -10,
      "name": "Cloth_Block_Wool_Black"
    },
    {
      "x": -28,
      "y": 9,
      "z": -10,
      "name": "Cloth_Block_Wool_Black"
    },
    {
      "x": -28,
      "y": 3,
      "z": -9,
      "name": "Cloth_Block_Wool_Black"
    },
    {
      "x": -28,
      "y": 9,
      "z": -9,
      "name": "Cloth_Block_Wool_Black"
    },
    {
      "x": -28,
      "y": 3,
      "z": -8,
      "name": "Cloth_Block_Wool_Black"
    },
    {
      "x": -28,
      "y": 9,
      "z": -8,
      "name": "Cloth_Block_Wool_Black"
    },
    {
      "x": -28,
      "y": 3,
      "z": -7,
      "name": "Cloth_Block_Wool_Black"
    },
    {
      "x": -28,
      "y": 9,
      "z": -7,
      "name": "Cloth_Block_Wool_Black"
    },
    {
      "x": -28,
      "y": 3,
      "z": -6,
      "name": "Cloth_Block_Wool_Black"
    },
    {
      "x": -28,
      "y": 9,
      "z": -6,
      "name": "Cloth_Block_Wool_Black"
    },
    {
      "x": -28,
      "y": 3,
      "z": -5,
      "name": "Cloth_Block_Wool_Black"
    },
    {
      "x": -28,
      "y": 9,
      "z": -5,
      "name": "Cloth_Block_Wool_Black"
    },
    {
      "x": -28,
      "y": 3,
      "z": -4,
      "name": "Cloth_Block_Wool_Black"
    },
    {
      "x": -28,
      "y": 9,
      "z": -4,
      "name": "Cloth_Block_Wool_Black"
    },
    {
      "x": -28,
      "y": 3,
      "z": -3,
      "name": "Cloth_Block_Wool_Black"
    },
    {
      "x": -28,
      "y": 9,
      "z": -3,
      "name": "Cloth_Block_Wool_Black"
    },
    {
      "x": -28,
      "y": 3,
      "z": -2,
      "name": "Cloth_Block_Wool_Black"
    },
    {
      "x": -28,
      "y": 9,
      "z": -2,
      "name": "Cloth_Block_Wool_Black"
    },
    {
      "x": -28,
      "y": 3,
      "z": -1,
      "name": "Cloth_Block_Wool_Black"
    },
    {
      "x": -28,
      "y": 9,
      "z": -1,
      "name": "Cloth_Block_Wool_Black"
    },
    {
      "x": -28,
      "y": 3,
      "z": 0,
      "name": "Cloth_Block_Wool_Black"
    },
    {
      "x": -28,
      "y": 9,
      "z": 0,
      "name": "Cloth_Block_Wool_Black"
    },
    {
      "x": -28,
      "y": 3,
      "z": 1,
      "name": "Cloth_Block_Wool_Black"
    },
    {
      "x": -28,
      "y": 9,
      "z": 1,
      "name": "Cloth_Block_Wool_Black"
    },
    {
      "x": -28,
      "y": 3,
      "z": 2,
      "name": "Cloth_Block_Wool_Black"
    },
    {
      "x": -28,
      "y": 9,
      "z": 2,
      "name": "Cloth_Block_Wool_Black"
    },
    {
      "x": -28,
      "y": 3,
      "z": 3,
      "name": "Cloth_Block_Wool_Black"
    },
    {
      "x": -28,
      "y": 9,
      "z": 3,
      "name": "Cloth_Block_Wool_Black"
    },
    {
      "x": -28,
      "y": 3,
      "z": 4,
      "name": "Cloth_Block_Wool_Black"
    },
    {
      "x": -28,
      "y": 9,
      "z": 4,
      "name": "Cloth_Block_Wool_Black"
    },
    {
      "x": -28,
      "y": 3,
      "z": 5,
      "name": "Cloth_Block_Wool_Black"
    },
    {
      "x": -28,
      "y": 9,
      "z": 5,
      "name": "Cloth_Block_Wool_Black"
    },
    {
      "x": -28,
      "y": 3,
      "z": 6,
      "name": "Cloth_Block_Wool_Black"
    },
    {
      "x": -28,
      "y": 9,
      "z": 6,
      "name": "Cloth_Block_Wool_Black"
    },
    {
      "x": -28,
      "y": 3,
      "z": 7,
      "name": "Cloth_Block_Wool_Black"
    },
    {
      "x": -28,
      "y": 9,
      "z": 7,
      "name": "Cloth_Block_Wool_Black"
    },
    {
      "x": -28,
      "y": 3,
      "z": 8,
      "name": "Cloth_Block_Wool_Black"
    },
    {
      "x": -28,
      "y": 9,
      "z": 8,
      "name": "Cloth_Block_Wool_Black"
    },
    {
      "x": -28,
      "y": 3,
      "z": 9,
      "name": "Cloth_Block_Wool_Black"
    },
    {
      "x": -28,
      "y": 9,
      "z": 9,
      "name": "Cloth_Block_Wool_Black"
    },
    {
      "x": -28,
      "y": 3,
      "z": 10,
      "name": "Cloth_Block_Wool_Black"
    },
    {
      "x": -28,
      "y": 9,
      "z": 10,
      "name": "Cloth_Block_Wool_Black"
    },
    {
      "x": -28,
      "y": 3,
      "z": 11,
      "name": "Cloth_Block_Wool_Black"
    },
    {
      "x": -28,
      "y": 9,
      "z": 11,
      "name": "Cloth_Block_Wool_Black"
    },
    {
      "x": -28,
      "y": 3,
      "z": 12,
      "name": "Cloth_Block_Wool_Black"
    },
    {
      "x": -28,
      "y": 9,
      "z": 12,
      "name": "Cloth_Block_Wool_Black"
    },
    {
      "x": -28,
      "y": 3,
      "z": 13,
      "name": "Cloth_Block_Wool_Black"
    },
    {
      "x": -28,
      "y": 9,
      "z": 13,
      "name": "Cloth_Block_Wool_Black"
    },
    {
      "x": -28,
      "y": 3,
      "z": 14,
      "name": "Cloth_Block_Wool_Black"
    },
    {
      "x": -28,
      "y": 9,
      "z": 14,
      "name": "Cloth_Block_Wool_Black"
    },
    {
      "x": -28,
      "y": 3,
      "z": 15,
      "name": "Cloth_Block_Wool_Black"
    },
    {
      "x": -28,
      "y": 9,
      "z": 15,
      "name": "Cloth_Block_Wool_Black"
    },
    {
      "x": -28,
      "y": 3,
      "z": 16,
      "name": "Cloth_Block_Wool_Black"
    },
    {
      "x": -28,
      "y": 9,
      "z": 16,
      "name": "Cloth_Block_Wool_Black"
    },
    {
      "x": -28,
      "y": 3,
      "z": 17,
      "name": "Cloth_Block_Wool_Black"
    },
    {
      "x": -28,
      "y": 9,
      "z": 17,
      "name": "Cloth_Block_Wool_Black"
    },
    {
      "x": -28,
      "y": 3,
      "z": 18,
      "name": "Cloth_Block_Wool_Black"
    },
    {
      "x": -28,
      "y": 9,
      "z": 18,
      "name": "Cloth_Block_Wool_Black"
    },
    {
      "x": -28,
      "y": 3,
      "z": 19,
      "name": "Cloth_Block_Wool_Black"
    },
    {
      "x": -28,
      "y": 9,
      "z": 19,
      "name": "Cloth_Block_Wool_Black"
    },
    {
      "x": -28,
      "y": 3,
      "z": 20,
      "name": "Cloth_Block_Wool_Black"
    },
    {
      "x": -28,
      "y": 9,
      "z": 20,
      "name": "Cloth_Block_Wool_Black"
    },
    {
      "x": -28,
      "y": 3,
      "z": 21,
      "name": "Cloth_Block_Wool_Black"
    },
    {
      "x": -28,
      "y": 9,
      "z": 21,
      "name": "Cloth_Block_Wool_Black"
    },
    {
      "x": -28,
      "y": 3,
      "z": 22,
      "name": "Cloth_Block_Wool_Black"
    },
    {
      "x": -28,
      "y": 9,
      "z": 22,
      "name": "Cloth_Block_Wool_Black"
    },
    {
      "x": -28,
      "y": 3,
      "z": 23,
      "name": "Cloth_Block_Wool_Black"
    },
    {
      "x": -28,
      "y": 9,
      "z": 23,
      "name": "Cloth_Block_Wool_Black"
    },
    {
      "x": -28,
      "y": 3,
      "z": 24,
      "name": "Cloth_Block_Wool_Black"
    },
    {
      "x": -28,
      "y": 9,
      "z": 24,
      "name": "Cloth_Block_Wool_Black"
    },
    {
      "x": -28,
      "y": 3,
      "z": 25,
      "name": "Cloth_Block_Wool_Black"
    },
    {
      "x": -28,
      "y": 4,
      "z": 25,
      "name": "Cloth_Block_Wool_Black"
    },
    {
      "x": -28,
      "y": 5,
      "z": 25,
      "name": "Cloth_Block_Wool_Black"
    },
    {
      "x": -28,
      "y": 6,
      "z": 25,
      "name": "Cloth_Block_Wool_Black"
    },
    {
      "x": -28,
      "y": 7,
      "z": 25,
      "name": "Cloth_Block_Wool_Black"
    },
    {
      "x": -28,
      "y": 8,
      "z": 25,
      "name": "Cloth_Block_Wool_Black"
    },
    {
      "x": -28,
      "y": 9,
      "z": 25,
      "name": "Cloth_Block_Wool_Black"
    },
    {
      "x": -27,
      "y": 3,
      "z": -25,
      "name": "Cloth_Block_Wool_Black"
    },
    {
      "x": -27,
      "y": 4,
      "z": -25,
      "name": "Cloth_Block_Wool_Black"
    },
    {
      "x": -27,
      "y": 5,
      "z": -25,
      "name": "Cloth_Block_Wool_Black"
    },
    {
      "x": -27,
      "y": 6,
      "z": -25,
      "name": "Cloth_Block_Wool_Black"
    },
    {
      "x": -27,
      "y": 7,
      "z": -25,
      "name": "Cloth_Block_Wool_Black"
    },
    {
      "x": -27,
      "y": 8,
      "z": -25,
      "name": "Cloth_Block_Wool_Black"
    },
    {
      "x": -27,
      "y": 9,
      "z": -25,
      "name": "Cloth_Block_Wool_Black"
    },
    {
      "x": -27,
      "y": 3,
      "z": -24,
      "name": "Cloth_Block_Wool_Black"
    },
    {
      "x": -27,
      "y": 9,
      "z": -24,
      "name": "Cloth_Block_Wool_Black"
    },
    {
      "x": -27,
      "y": 3,
      "z": -23,
      "name": "Cloth_Block_Wool_Blue"
    },
    {
      "x": -27,
      "y": 9,
      "z": -23,
      "name": "Cloth_Block_Wool_Black"
    },
    {
      "x": -27,
      "y": 3,
      "z": -22,
      "name": "Cloth_Block_Wool_Blue"
    },
    {
      "x": -27,
      "y": 9,
      "z": -22,
      "name": "Cloth_Block_Wool_Black"
    },
    {
      "x": -27,
      "y": 3,
      "z": -21,
      "name": "Cloth_Block_Wool_Blue"
    },
    {
      "x": -27,
      "y": 9,
      "z": -21,
      "name": "Cloth_Block_Wool_Black"
    },
    {
      "x": -27,
      "y": 3,
      "z": -20,
      "name": "Cloth_Block_Wool_Blue"
    },
    {
      "x": -27,
      "y": 9,
      "z": -20,
      "name": "Cloth_Block_Wool_Black"
    },
    {
      "x": -27,
      "y": 3,
      "z": -19,
      "name": "Cloth_Block_Wool_Blue"
    },
    {
      "x": -27,
      "y": 9,
      "z": -19,
      "name": "Cloth_Block_Wool_Black"
    },
    {
      "x": -27,
      "y": 3,
      "z": -18,
      "name": "Cloth_Block_Wool_Blue"
    },
    {
      "x": -27,
      "y": 9,
      "z": -18,
      "name": "Cloth_Block_Wool_Black"
    },
    {
      "x": -27,
      "y": 3,
      "z": -17,
      "name": "Cloth_Block_Wool_Blue"
    },
    {
      "x": -27,
      "y": 9,
      "z": -17,
      "name": "Cloth_Block_Wool_Black"
    },
    {
      "x": -27,
      "y": 3,
      "z": -16,
      "name": "Cloth_Block_Wool_Blue"
    },
    {
      "x": -27,
      "y": 9,
      "z": -16,
      "name": "Cloth_Block_Wool_Black"
    },
    {
      "x": -27,
      "y": 3,
      "z": -15,
      "name": "Cloth_Block_Wool_Blue"
    },
    {
      "x": -27,
      "y": 9,
      "z": -15,
      "name": "Cloth_Block_Wool_Black"
    },
    {
      "x": -27,
      "y": 3,
      "z": -14,
      "name": "Cloth_Block_Wool_Blue"
    },
    {
      "x": -27,
      "y": 9,
      "z": -14,
      "name": "Cloth_Block_Wool_Black"
    },
    {
      "x": -27,
      "y": 3,
      "z": -13,
      "name": "Cloth_Block_Wool_Blue"
    },
    {
      "x": -27,
      "y": 9,
      "z": -13,
      "name": "Cloth_Block_Wool_Black"
    },
    {
      "x": -27,
      "y": 3,
      "z": -12,
      "name": "Cloth_Block_Wool_Blue"
    },
    {
      "x": -27,
      "y": 9,
      "z": -12,
      "name": "Cloth_Block_Wool_Black"
    },
    {
      "x": -27,
      "y": 3,
      "z": -11,
      "name": "Cloth_Block_Wool_Blue"
    },
    {
      "x": -27,
      "y": 9,
      "z": -11,
      "name": "Cloth_Block_Wool_Black"
    },
    {
      "x": -27,
      "y": 3,
      "z": -10,
      "name": "Cloth_Block_Wool_Blue"
    },
    {
      "x": -27,
      "y": 9,
      "z": -10,
      "name": "Cloth_Block_Wool_Black"
    },
    {
      "x": -27,
      "y": 3,
      "z": -9,
      "name": "Cloth_Block_Wool_Blue"
    },
    {
      "x": -27,
      "y": 9,
      "z": -9,
      "name": "Cloth_Block_Wool_Black"
    },
    {
      "x": -27,
      "y": 3,
      "z": -8,
      "name": "Cloth_Block_Wool_Blue"
    },
    {
      "x": -27,
      "y": 9,
      "z": -8,
      "name": "Cloth_Block_Wool_Black"
    },
    {
      "x": -27,
      "y": 3,
      "z": -7,
      "name": "Cloth_Block_Wool_Blue"
    },
    {
      "x": -27,
      "y": 9,
      "z": -7,
      "name": "Cloth_Block_Wool_Black"
    },
    {
      "x": -27,
      "y": 3,
      "z": -6,
      "name": "Cloth_Block_Wool_Blue"
    },
    {
      "x": -27,
      "y": 9,
      "z": -6,
      "name": "Cloth_Block_Wool_Black"
    },
    {
      "x": -27,
      "y": 3,
      "z": -5,
      "name": "Cloth_Block_Wool_Blue"
    },
    {
      "x": -27,
      "y": 9,
      "z": -5,
      "name": "Cloth_Block_Wool_Black"
    },
    {
      "x": -27,
      "y": 3,
      "z": -4,
      "name": "Cloth_Block_Wool_Blue"
    },
    {
      "x": -27,
      "y": 9,
      "z": -4,
      "name": "Cloth_Block_Wool_Black"
    },
    {
      "x": -27,
      "y": 3,
      "z": -3,
      "name": "Cloth_Block_Wool_Blue"
    },
    {
      "x": -27,
      "y": 9,
      "z": -3,
      "name": "Cloth_Block_Wool_Black"
    },
    {
      "x": -27,
      "y": 3,
      "z": -2,
      "name": "Cloth_Block_Wool_Blue"
    },
    {
      "x": -27,
      "y": 9,
      "z": -2,
      "name": "Cloth_Block_Wool_Black"
    },
    {
      "x": -27,
      "y": 3,
      "z": -1,
      "name": "Cloth_Block_Wool_Blue"
    },
    {
      "x": -27,
      "y": 9,
      "z": -1,
      "name": "Cloth_Block_Wool_Black"
    },
    {
      "x": -27,
      "y": 3,
      "z": 0,
      "name": "Cloth_Block_Wool_Blue"
    },
    {
      "x": -27,
      "y": 9,
      "z": 0,
      "name": "Cloth_Block_Wool_Black"
    },
    {
      "x": -27,
      "y": 3,
      "z": 1,
      "name": "Cloth_Block_Wool_Blue"
    },
    {
      "x": -27,
      "y": 9,
      "z": 1,
      "name": "Cloth_Block_Wool_Black"
    },
    {
      "x": -27,
      "y": 3,
      "z": 2,
      "name": "Cloth_Block_Wool_Blue"
    },
    {
      "x": -27,
      "y": 9,
      "z": 2,
      "name": "Cloth_Block_Wool_Black"
    },
    {
      "x": -27,
      "y": 3,
      "z": 3,
      "name": "Cloth_Block_Wool_Blue"
    },
    {
      "x": -27,
      "y": 9,
      "z": 3,
      "name": "Cloth_Block_Wool_Black"
    },
    {
      "x": -27,
      "y": 3,
      "z": 4,
      "name": "Cloth_Block_Wool_Blue"
    },
    {
      "x": -27,
      "y": 9,
      "z": 4,
      "name": "Cloth_Block_Wool_Black"
    },
    {
      "x": -27,
      "y": 3,
      "z": 5,
      "name": "Cloth_Block_Wool_Blue"
    },
    {
      "x": -27,
      "y": 9,
      "z": 5,
      "name": "Cloth_Block_Wool_Black"
    },
    {
      "x": -27,
      "y": 3,
      "z": 6,
      "name": "Cloth_Block_Wool_Blue"
    },
    {
      "x": -27,
      "y": 9,
      "z": 6,
      "name": "Cloth_Block_Wool_Black"
    },
    {
      "x": -27,
      "y": 3,
      "z": 7,
      "name": "Cloth_Block_Wool_Blue"
    },
    {
      "x": -27,
      "y": 9,
      "z": 7,
      "name": "Cloth_Block_Wool_Black"
    },
    {
      "x": -27,
      "y": 3,
      "z": 8,
      "name": "Cloth_Block_Wool_Blue"
    },
    {
      "x": -27,
      "y": 9,
      "z": 8,
      "name": "Cloth_Block_Wool_Black"
    },
    {
      "x": -27,
      "y": 3,
      "z": 9,
      "name": "Cloth_Block_Wool_Blue"
    },
    {
      "x": -27,
      "y": 9,
      "z": 9,
      "name": "Cloth_Block_Wool_Black"
    },
    {
      "x": -27,
      "y": 3,
      "z": 10,
      "name": "Cloth_Block_Wool_Blue"
    },
    {
      "x": -27,
      "y": 9,
      "z": 10,
      "name": "Cloth_Block_Wool_Black"
    },
    {
      "x": -27,
      "y": 3,
      "z": 11,
      "name": "Cloth_Block_Wool_Blue"
    },
    {
      "x": -27,
      "y": 9,
      "z": 11,
      "name": "Cloth_Block_Wool_Black"
    },
    {
      "x": -27,
      "y": 3,
      "z": 12,
      "name": "Cloth_Block_Wool_Blue"
    },
    {
      "x": -27,
      "y": 9,
      "z": 12,
      "name": "Cloth_Block_Wool_Black"
    },
    {
      "x": -27,
      "y": 3,
      "z": 13,
      "name": "Cloth_Block_Wool_Blue"
    },
    {
      "x": -27,
      "y": 9,
      "z": 13,
      "name": "Cloth_Block_Wool_Black"
    },
    {
      "x": -27,
      "y": 3,
      "z": 14,
      "name": "Cloth_Block_Wool_Blue"
    },
    {
      "x": -27,
      "y": 9,
      "z": 14,
      "name": "Cloth_Block_Wool_Black"
    },
    {
      "x": -27,
      "y": 3,
      "z": 15,
      "name": "Cloth_Block_Wool_Blue"
    },
    {
      "x": -27,
      "y": 9,
      "z": 15,
      "name": "Cloth_Block_Wool_Black"
    },
    {
      "x": -27,
      "y": 3,
      "z": 16,
      "name": "Cloth_Block_Wool_Blue"
    },
    {
      "x": -27,
      "y": 9,
      "z": 16,
      "name": "Cloth_Block_Wool_Black"
    },
    {
      "x": -27,
      "y": 3,
      "z": 17,
      "name": "Cloth_Block_Wool_Blue"
    },
    {
      "x": -27,
      "y": 9,
      "z": 17,
      "name": "Cloth_Block_Wool_Black"
    },
    {
      "x": -27,
      "y": 3,
      "z": 18,
      "name": "Cloth_Block_Wool_Blue"
    },
    {
      "x": -27,
      "y": 9,
      "z": 18,
      "name": "Cloth_Block_Wool_Black"
    },
    {
      "x": -27,
      "y": 3,
      "z": 19,
      "name": "Cloth_Block_Wool_Blue"
    },
    {
      "x": -27,
      "y": 9,
      "z": 19,
      "name": "Cloth_Block_Wool_Black"
    },
    {
      "x": -27,
      "y": 3,
      "z": 20,
      "name": "Cloth_Block_Wool_Blue"
    },
    {
      "x": -27,
      "y": 9,
      "z": 20,
      "name": "Cloth_Block_Wool_Black"
    },
    {
      "x": -27,
      "y": 3,
      "z": 21,
      "name": "Cloth_Block_Wool_Blue"
    },
    {
      "x": -27,
      "y": 9,
      "z": 21,
      "name": "Cloth_Block_Wool_Black"
    },
    {
      "x": -27,
      "y": 3,
      "z": 22,
      "name": "Cloth_Block_Wool_Blue"
    },
    {
      "x": -27,
      "y": 9,
      "z": 22,
      "name": "Cloth_Block_Wool_Black"
    },
    {
      "x": -27,
      "y": 3,
      "z": 23,
      "name": "Cloth_Block_Wool_Blue"
    },
    {
      "x": -27,
      "y": 9,
      "z": 23,
      "name": "Cloth_Block_Wool_Black"
    },
    {
      "x": -27,
      "y": 3,
      "z": 24,
      "name": "Cloth_Block_Wool_Black"
    },
    {
      "x": -27,
      "y": 9,
      "z": 24,
      "name": "Cloth_Block_Wool_Black"
    },
    {
      "x": -27,
      "y": 3,
      "z": 25,
      "name": "Cloth_Block_Wool_Black"
    },
    {
      "x": -27,
      "y": 4,
      "z": 25,
      "name": "Cloth_Block_Wool_Black"
    },
    {
      "x": -27,
      "y": 5,
      "z": 25,
      "name": "Cloth_Block_Wool_Black"
    },
    {
      "x": -27,
      "y": 6,
      "z": 25,
      "name": "Cloth_Block_Wool_Black"
    },
    {
      "x": -27,
      "y": 7,
      "z": 25,
      "name": "Cloth_Block_Wool_Black"
    },
    {
      "x": -27,
      "y": 8,
      "z": 25,
      "name": "Cloth_Block_Wool_Black"
    },
    {
      "x": -27,
      "y": 9,
      "z": 25,
      "name": "Cloth_Block_Wool_Black"
    },
    {
      "x": -26,
      "y": 3,
      "z": -25,
      "name": "Cloth_Block_Wool_Black"
    },
    {
      "x": -26,
      "y": 4,
      "z": -25,
      "name": "Cloth_Block_Wool_Black"
    },
    {
      "x": -26,
      "y": 5,
      "z": -25,
      "name": "Cloth_Block_Wool_Black"
    },
    {
      "x": -26,
      "y": 6,
      "z": -25,
      "name": "Cloth_Block_Wool_Black"
    },
    {
      "x": -26,
      "y": 7,
      "z": -25,
      "name": "Cloth_Block_Wool_Black"
    },
    {
      "x": -26,
      "y": 8,
      "z": -25,
      "name": "Cloth_Block_Wool_Black"
    },
    {
      "x": -26,
      "y": 9,
      "z": -25,
      "name": "Cloth_Block_Wool_Black"
    },
    {
      "x": -26,
      "y": 3,
      "z": -24,
      "name": "Cloth_Block_Wool_Black"
    },
    {
      "x": -26,
      "y": 9,
      "z": -24,
      "name": "Cloth_Block_Wool_Black"
    },
    {
      "x": -26,
      "y": 3,
      "z": -23,
      "name": "Cloth_Block_Wool_Blue"
    },
    {
      "x": -26,
      "y": 9,
      "z": -23,
      "name": "Cloth_Block_Wool_Black"
    },
    {
      "x": -26,
      "y": 3,
      "z": -22,
      "name": "Cloth_Block_Wool_Blue"
    },
    {
      "x": -26,
      "y": 9,
      "z": -22,
      "name": "Cloth_Block_Wool_Black"
    },
    {
      "x": -26,
      "y": 3,
      "z": -21,
      "name": "Cloth_Block_Wool_Blue"
    },
    {
      "x": -26,
      "y": 9,
      "z": -21,
      "name": "Cloth_Block_Wool_Black"
    },
    {
      "x": -26,
      "y": 3,
      "z": -20,
      "name": "Cloth_Block_Wool_Blue"
    },
    {
      "x": -26,
      "y": 9,
      "z": -20,
      "name": "Cloth_Block_Wool_Black"
    },
    {
      "x": -26,
      "y": 3,
      "z": -19,
      "name": "Cloth_Block_Wool_Blue"
    },
    {
      "x": -26,
      "y": 9,
      "z": -19,
      "name": "Cloth_Block_Wool_Black"
    },
    {
      "x": -26,
      "y": 3,
      "z": -18,
      "name": "Cloth_Block_Wool_Blue"
    },
    {
      "x": -26,
      "y": 9,
      "z": -18,
      "name": "Cloth_Block_Wool_Black"
    },
    {
      "x": -26,
      "y": 3,
      "z": -17,
      "name": "Cloth_Block_Wool_Blue"
    },
    {
      "x": -26,
      "y": 9,
      "z": -17,
      "name": "Cloth_Block_Wool_Black"
    },
    {
      "x": -26,
      "y": 3,
      "z": -16,
      "name": "Cloth_Block_Wool_Blue"
    },
    {
      "x": -26,
      "y": 9,
      "z": -16,
      "name": "Cloth_Block_Wool_Black"
    },
    {
      "x": -26,
      "y": 2,
      "z": -15,
      "name": "Laser_Tag_Marker_Team_Spawn1",
      "components": {
        "Components": {
          "LaserTagMarkerTeamSpawnerComponent": {
            "TeamId": 1,
            "Position": {
              "X": 0,
              "Y": 0,
              "Z": 0
            }
          },
          "PlacedByInteraction": {
            "WhoPlacedUuid": {
              "$binary": "AuYy7aUASF6e9/O1FVNSzw==",
              "$type": "04"
            }
          },
          "RespawnBlock": {}
        }
      }
    },
    {
      "x": -26,
      "y": 3,
      "z": -15,
      "name": "Cloth_Block_Wool_Blue"
    },
    {
      "x": -26,
      "y": 9,
      "z": -15,
      "name": "Cloth_Block_Wool_Black"
    },
    {
      "x": -26,
      "y": 3,
      "z": -14,
      "name": "Cloth_Block_Wool_Blue"
    },
    {
      "x": -26,
      "y": 9,
      "z": -14,
      "name": "Cloth_Block_Wool_Black"
    },
    {
      "x": -26,
      "y": 2,
      "z": -13,
      "name": "Laser_Tag_Marker_Team_Spawn1",
      "components": {
        "Components": {
          "LaserTagMarkerTeamSpawnerComponent": {
            "TeamId": 1,
            "Position": {
              "X": 0,
              "Y": 0,
              "Z": 0
            }
          },
          "PlacedByInteraction": {
            "WhoPlacedUuid": {
              "$binary": "AuYy7aUASF6e9/O1FVNSzw==",
              "$type": "04"
            }
          },
          "RespawnBlock": {}
        }
      }
    },
    {
      "x": -26,
      "y": 3,
      "z": -13,
      "name": "Cloth_Block_Wool_Blue"
    },
    {
      "x": -26,
      "y": 9,
      "z": -13,
      "name": "Cloth_Block_Wool_Black"
    },
    {
      "x": -26,
      "y": 3,
      "z": -12,
      "name": "Cloth_Block_Wool_Blue"
    },
    {
      "x": -26,
      "y": 9,
      "z": -12,
      "name": "Cloth_Block_Wool_Black"
    },
    {
      "x": -26,
      "y": 2,
      "z": -11,
      "name": "Laser_Tag_Marker_Team_Spawn1",
      "components": {
        "Components": {
          "LaserTagMarkerTeamSpawnerComponent": {
            "TeamId": 1,
            "Position": {
              "X": 0,
              "Y": 0,
              "Z": 0
            }
          },
          "PlacedByInteraction": {
            "WhoPlacedUuid": {
              "$binary": "AuYy7aUASF6e9/O1FVNSzw==",
              "$type": "04"
            }
          },
          "RespawnBlock": {}
        }
      }
    },
    {
      "x": -26,
      "y": 3,
      "z": -11,
      "name": "Cloth_Block_Wool_Blue"
    },
    {
      "x": -26,
      "y": 9,
      "z": -11,
      "name": "Cloth_Block_Wool_Black"
    },
    {
      "x": -26,
      "y": 3,
      "z": -10,
      "name": "Cloth_Block_Wool_Blue"
    },
    {
      "x": -26,
      "y": 9,
      "z": -10,
      "name": "Cloth_Block_Wool_Black"
    },
    {
      "x": -26,
      "y": 3,
      "z": -9,
      "name": "Cloth_Block_Wool_Blue"
    },
    {
      "x": -26,
      "y": 9,
      "z": -9,
      "name": "Cloth_Block_Wool_Black"
    },
    {
      "x": -26,
      "y": 3,
      "z": -8,
      "name": "Cloth_Block_Wool_Blue"
    },
    {
      "x": -26,
      "y": 9,
      "z": -8,
      "name": "Cloth_Block_Wool_Black"
    },
    {
      "x": -26,
      "y": 3,
      "z": -7,
      "name": "Cloth_Block_Wool_Blue"
    },
    {
      "x": -26,
      "y": 9,
      "z": -7,
      "name": "Cloth_Block_Wool_Black"
    },
    {
      "x": -26,
      "y": 3,
      "z": -6,
      "name": "Cloth_Block_Wool_Blue"
    },
    {
      "x": -26,
      "y": 9,
      "z": -6,
      "name": "Cloth_Block_Wool_Black"
    },
    {
      "x": -26,
      "y": 3,
      "z": -5,
      "name": "Cloth_Block_Wool_Blue"
    },
    {
      "x": -26,
      "y": 9,
      "z": -5,
      "name": "Cloth_Block_Wool_Black"
    },
    {
      "x": -26,
      "y": 3,
      "z": -4,
      "name": "Cloth_Block_Wool_Blue"
    },
    {
      "x": -26,
      "y": 9,
      "z": -4,
      "name": "Cloth_Block_Wool_Black"
    },
    {
      "x": -26,
      "y": 3,
      "z": -3,
      "name": "Cloth_Block_Wool_Blue"
    },
    {
      "x": -26,
      "y": 9,
      "z": -3,
      "name": "Cloth_Block_Wool_Black"
    },
    {
      "x": -26,
      "y": 3,
      "z": -2,
      "name": "Cloth_Block_Wool_Blue"
    },
    {
      "x": -26,
      "y": 9,
      "z": -2,
      "name": "Cloth_Block_Wool_Black"
    },
    {
      "x": -26,
      "y": 3,
      "z": -1,
      "name": "Cloth_Block_Wool_Blue"
    },
    {
      "x": -26,
      "y": 9,
      "z": -1,
      "name": "Cloth_Block_Wool_Black"
    },
    {
      "x": -26,
      "y": 2,
      "z": 0,
      "name": "Laser_Tag_Marker_Team_Spawn1",
      "components": {
        "Components": {
          "LaserTagMarkerTeamSpawnerComponent": {
            "TeamId": 1,
            "Position": {
              "X": 0,
              "Y": 0,
              "Z": 0
            }
          },
          "PlacedByInteraction": {
            "WhoPlacedUuid": {
              "$binary": "AuYy7aUASF6e9/O1FVNSzw==",
              "$type": "04"
            }
          },
          "RespawnBlock": {}
        }
      }
    },
    {
      "x": -26,
      "y": 3,
      "z": 0,
      "name": "Cloth_Block_Wool_Blue"
    },
    {
      "x": -26,
      "y": 9,
      "z": 0,
      "name": "Cloth_Block_Wool_Black"
    },
    {
      "x": -26,
      "y": 3,
      "z": 1,
      "name": "Cloth_Block_Wool_Blue"
    },
    {
      "x": -26,
      "y": 9,
      "z": 1,
      "name": "Cloth_Block_Wool_Black"
    },
    {
      "x": -26,
      "y": 3,
      "z": 2,
      "name": "Cloth_Block_Wool_Blue"
    },
    {
      "x": -26,
      "y": 9,
      "z": 2,
      "name": "Cloth_Block_Wool_Black"
    },
    {
      "x": -26,
      "y": 3,
      "z": 3,
      "name": "Cloth_Block_Wool_Blue"
    },
    {
      "x": -26,
      "y": 9,
      "z": 3,
      "name": "Cloth_Block_Wool_Black"
    },
    {
      "x": -26,
      "y": 3,
      "z": 4,
      "name": "Cloth_Block_Wool_Blue"
    },
    {
      "x": -26,
      "y": 9,
      "z": 4,
      "name": "Cloth_Block_Wool_Black"
    },
    {
      "x": -26,
      "y": 3,
      "z": 5,
      "name": "Cloth_Block_Wool_Blue"
    },
    {
      "x": -26,
      "y": 9,
      "z": 5,
      "name": "Cloth_Block_Wool_Black"
    },
    {
      "x": -26,
      "y": 3,
      "z": 6,
      "name": "Cloth_Block_Wool_Blue"
    },
    {
      "x": -26,
      "y": 9,
      "z": 6,
      "name": "Cloth_Block_Wool_Black"
    },
    {
      "x": -26,
      "y": 3,
      "z": 7,
      "name": "Cloth_Block_Wool_Blue"
    },
    {
      "x": -26,
      "y": 9,
      "z": 7,
      "name": "Cloth_Block_Wool_Black"
    },
    {
      "x": -26,
      "y": 3,
      "z": 8,
      "name": "Cloth_Block_Wool_Blue"
    },
    {
      "x": -26,
      "y": 9,
      "z": 8,
      "name": "Cloth_Block_Wool_Black"
    },
    {
      "x": -26,
      "y": 3,
      "z": 9,
      "name": "Cloth_Block_Wool_Blue"
    },
    {
      "x": -26,
      "y": 9,
      "z": 9,
      "name": "Cloth_Block_Wool_Black"
    },
    {
      "x": -26,
      "y": 3,
      "z": 10,
      "name": "Cloth_Block_Wool_Blue"
    },
    {
      "x": -26,
      "y": 9,
      "z": 10,
      "name": "Cloth_Block_Wool_Black"
    },
    {
      "x": -26,
      "y": 2,
      "z": 11,
      "name": "Laser_Tag_Marker_Team_Spawn1",
      "components": {
        "Components": {
          "LaserTagMarkerTeamSpawnerComponent": {
            "TeamId": 1,
            "Position": {
              "X": 0,
              "Y": 0,
              "Z": 0
            }
          },
          "PlacedByInteraction": {
            "WhoPlacedUuid": {
              "$binary": "AuYy7aUASF6e9/O1FVNSzw==",
              "$type": "04"
            }
          },
          "RespawnBlock": {}
        }
      }
    },
    {
      "x": -26,
      "y": 3,
      "z": 11,
      "name": "Cloth_Block_Wool_Blue"
    },
    {
      "x": -26,
      "y": 9,
      "z": 11,
      "name": "Cloth_Block_Wool_Black"
    },
    {
      "x": -26,
      "y": 3,
      "z": 12,
      "name": "Cloth_Block_Wool_Blue"
    },
    {
      "x": -26,
      "y": 9,
      "z": 12,
      "name": "Cloth_Block_Wool_Black"
    },
    {
      "x": -26,
      "y": 2,
      "z": 13,
      "name": "Laser_Tag_Marker_Team_Spawn1",
      "components": {
        "Components": {
          "LaserTagMarkerTeamSpawnerComponent": {
            "TeamId": 1,
            "Position": {
              "X": 0,
              "Y": 0,
              "Z": 0
            }
          },
          "PlacedByInteraction": {
            "WhoPlacedUuid": {
              "$binary": "AuYy7aUASF6e9/O1FVNSzw==",
              "$type": "04"
            }
          },
          "RespawnBlock": {}
        }
      }
    },
    {
      "x": -26,
      "y": 3,
      "z": 13,
      "name": "Cloth_Block_Wool_Blue"
    },
    {
      "x": -26,
      "y": 9,
      "z": 13,
      "name": "Cloth_Block_Wool_Black"
    },
    {
      "x": -26,
      "y": 3,
      "z": 14,
      "name": "Cloth_Block_Wool_Blue"
    },
    {
      "x": -26,
      "y": 9,
      "z": 14,
      "name": "Cloth_Block_Wool_Black"
    },
    {
      "x": -26,
      "y": 2,
      "z": 15,
      "name": "Laser_Tag_Marker_Team_Spawn1",
      "components": {
        "Components": {
          "LaserTagMarkerTeamSpawnerComponent": {
            "TeamId": 1,
            "Position": {
              "X": 0,
              "Y": 0,
              "Z": 0
            }
          },
          "PlacedByInteraction": {
            "WhoPlacedUuid": {
              "$binary": "AuYy7aUASF6e9/O1FVNSzw==",
              "$type": "04"
            }
          },
          "RespawnBlock": {}
        }
      }
    },
    {
      "x": -26,
      "y": 3,
      "z": 15,
      "name": "Cloth_Block_Wool_Blue"
    },
    {
      "x": -26,
      "y": 9,
      "z": 15,
      "name": "Cloth_Block_Wool_Black"
    },
    {
      "x": -26,
      "y": 3,
      "z": 16,
      "name": "Cloth_Block_Wool_Blue"
    },
    {
      "x": -26,
      "y": 9,
      "z": 16,
      "name": "Cloth_Block_Wool_Black"
    },
    {
      "x": -26,
      "y": 3,
      "z": 17,
      "name": "Cloth_Block_Wool_Blue"
    },
    {
      "x": -26,
      "y": 9,
      "z": 17,
      "name": "Cloth_Block_Wool_Black"
    },
    {
      "x": -26,
      "y": 3,
      "z": 18,
      "name": "Cloth_Block_Wool_Blue"
    },
    {
      "x": -26,
      "y": 9,
      "z": 18,
      "name": "Cloth_Block_Wool_Black"
    },
    {
      "x": -26,
      "y": 3,
      "z": 19,
      "name": "Cloth_Block_Wool_Blue"
    },
    {
      "x": -26,
      "y": 9,
      "z": 19,
      "name": "Cloth_Block_Wool_Black"
    },
    {
      "x": -26,
      "y": 3,
      "z": 20,
      "name": "Cloth_Block_Wool_Blue"
    },
    {
      "x": -26,
      "y": 9,
      "z": 20,
      "name": "Cloth_Block_Wool_Black"
    },
    {
      "x": -26,
      "y": 3,
      "z": 21,
      "name": "Cloth_Block_Wool_Blue"
    },
    {
      "x": -26,
      "y": 9,
      "z": 21,
      "name": "Cloth_Block_Wool_Black"
    },
    {
      "x": -26,
      "y": 3,
      "z": 22,
      "name": "Cloth_Block_Wool_Blue"
    },
    {
      "x": -26,
      "y": 9,
      "z": 22,
      "name": "Cloth_Block_Wool_Black"
    },
    {
      "x": -26,
      "y": 3,
      "z": 23,
      "name": "Cloth_Block_Wool_Blue"
    },
    {
      "x": -26,
      "y": 9,
      "z": 23,
      "name": "Cloth_Block_Wool_Black"
    },
    {
      "x": -26,
      "y": 3,
      "z": 24,
      "name": "Cloth_Block_Wool_Black"
    },
    {
      "x": -26,
      "y": 9,
      "z": 24,
      "name": "Cloth_Block_Wool_Black"
    },
    {
      "x": -26,
      "y": 3,
      "z": 25,
      "name": "Cloth_Block_Wool_Black"
    },
    {
      "x": -26,
      "y": 4,
      "z": 25,
      "name": "Cloth_Block_Wool_Black"
    },
    {
      "x": -26,
      "y": 5,
      "z": 25,
      "name": "Cloth_Block_Wool_Black"
    },
    {
      "x": -26,
      "y": 6,
      "z": 25,
      "name": "Cloth_Block_Wool_Black"
    },
    {
      "x": -26,
      "y": 7,
      "z": 25,
      "name": "Cloth_Block_Wool_Black"
    },
    {
      "x": -26,
      "y": 8,
      "z": 25,
      "name": "Cloth_Block_Wool_Black"
    },
    {
      "x": -26,
      "y": 9,
      "z": 25,
      "name": "Cloth_Block_Wool_Black"
    },
    {
      "x": -25,
      "y": 3,
      "z": -25,
      "name": "Cloth_Block_Wool_Black"
    },
    {
      "x": -25,
      "y": 4,
      "z": -25,
      "name": "Cloth_Block_Wool_Black"
    },
    {
      "x": -25,
      "y": 5,
      "z": -25,
      "name": "Cloth_Block_Wool_Black"
    },
    {
      "x": -25,
      "y": 6,
      "z": -25,
      "name": "Cloth_Block_Wool_Black"
    },
    {
      "x": -25,
      "y": 7,
      "z": -25,
      "name": "Cloth_Block_Wool_Black"
    },
    {
      "x": -25,
      "y": 8,
      "z": -25,
      "name": "Cloth_Block_Wool_Black"
    },
    {
      "x": -25,
      "y": 9,
      "z": -25,
      "name": "Cloth_Block_Wool_Black"
    },
    {
      "x": -25,
      "y": 3,
      "z": -24,
      "name": "Cloth_Block_Wool_Black"
    },
    {
      "x": -25,
      "y": 9,
      "z": -24,
      "name": "Cloth_Block_Wool_Black"
    },
    {
      "x": -25,
      "y": 3,
      "z": -23,
      "name": "Cloth_Block_Wool_Blue"
    },
    {
      "x": -25,
      "y": 9,
      "z": -23,
      "name": "Cloth_Block_Wool_Black"
    },
    {
      "x": -25,
      "y": 3,
      "z": -22,
      "name": "Cloth_Block_Wool_Blue"
    },
    {
      "x": -25,
      "y": 9,
      "z": -22,
      "name": "Cloth_Block_Wool_Black"
    },
    {
      "x": -25,
      "y": 3,
      "z": -21,
      "name": "Cloth_Block_Wool_Blue"
    },
    {
      "x": -25,
      "y": 9,
      "z": -21,
      "name": "Cloth_Block_Wool_Black"
    },
    {
      "x": -25,
      "y": 3,
      "z": -20,
      "name": "Cloth_Block_Wool_Blue"
    },
    {
      "x": -25,
      "y": 9,
      "z": -20,
      "name": "Cloth_Block_Wool_Black"
    },
    {
      "x": -25,
      "y": 3,
      "z": -19,
      "name": "Cloth_Block_Wool_Blue"
    },
    {
      "x": -25,
      "y": 9,
      "z": -19,
      "name": "Cloth_Block_Wool_Black"
    },
    {
      "x": -25,
      "y": 3,
      "z": -18,
      "name": "Cloth_Block_Wool_Blue"
    },
    {
      "x": -25,
      "y": 9,
      "z": -18,
      "name": "Cloth_Block_Wool_Black"
    },
    {
      "x": -25,
      "y": 3,
      "z": -17,
      "name": "Cloth_Block_Wool_Blue"
    },
    {
      "x": -25,
      "y": 9,
      "z": -17,
      "name": "Cloth_Block_Wool_Black"
    },
    {
      "x": -25,
      "y": 3,
      "z": -16,
      "name": "Cloth_Block_Wool_Blue"
    },
    {
      "x": -25,
      "y": 9,
      "z": -16,
      "name": "Cloth_Block_Wool_Black"
    },
    {
      "x": -25,
      "y": 3,
      "z": -15,
      "name": "Cloth_Block_Wool_Blue"
    },
    {
      "x": -25,
      "y": 9,
      "z": -15,
      "name": "Cloth_Block_Wool_Black"
    },
    {
      "x": -25,
      "y": 3,
      "z": -14,
      "name": "Cloth_Block_Wool_Blue"
    },
    {
      "x": -25,
      "y": 9,
      "z": -14,
      "name": "Cloth_Block_Wool_Black"
    },
    {
      "x": -25,
      "y": 3,
      "z": -13,
      "name": "Cloth_Block_Wool_Blue"
    },
    {
      "x": -25,
      "y": 9,
      "z": -13,
      "name": "Cloth_Block_Wool_Black"
    },
    {
      "x": -25,
      "y": 3,
      "z": -12,
      "name": "Cloth_Block_Wool_Blue"
    },
    {
      "x": -25,
      "y": 9,
      "z": -12,
      "name": "Cloth_Block_Wool_Black"
    },
    {
      "x": -25,
      "y": 3,
      "z": -11,
      "name": "Cloth_Block_Wool_Blue"
    },
    {
      "x": -25,
      "y": 9,
      "z": -11,
      "name": "Cloth_Block_Wool_Black"
    },
    {
      "x": -25,
      "y": 3,
      "z": -10,
      "name": "Cloth_Block_Wool_Blue"
    },
    {
      "x": -25,
      "y": 9,
      "z": -10,
      "name": "Cloth_Block_Wool_Black"
    },
    {
      "x": -25,
      "y": 3,
      "z": -9,
      "name": "Cloth_Block_Wool_Blue"
    },
    {
      "x": -25,
      "y": 9,
      "z": -9,
      "name": "Cloth_Block_Wool_Black"
    },
    {
      "x": -25,
      "y": 3,
      "z": -8,
      "name": "Cloth_Block_Wool_Blue"
    },
    {
      "x": -25,
      "y": 9,
      "z": -8,
      "name": "Cloth_Block_Wool_Black"
    },
    {
      "x": -25,
      "y": 3,
      "z": -7,
      "name": "Cloth_Block_Wool_Blue"
    },
    {
      "x": -25,
      "y": 9,
      "z": -7,
      "name": "Cloth_Block_Wool_Black"
    },
    {
      "x": -25,
      "y": 3,
      "z": -6,
      "name": "Cloth_Block_Wool_Blue"
    },
    {
      "x": -25,
      "y": 9,
      "z": -6,
      "name": "Cloth_Block_Wool_Black"
    },
    {
      "x": -25,
      "y": 3,
      "z": -5,
      "name": "Cloth_Block_Wool_Blue"
    },
    {
      "x": -25,
      "y": 9,
      "z": -5,
      "name": "Cloth_Block_Wool_Black"
    },
    {
      "x": -25,
      "y": 3,
      "z": -4,
      "name": "Cloth_Block_Wool_Blue"
    },
    {
      "x": -25,
      "y": 9,
      "z": -4,
      "name": "Cloth_Block_Wool_Black"
    },
    {
      "x": -25,
      "y": 3,
      "z": -3,
      "name": "Cloth_Block_Wool_Blue"
    },
    {
      "x": -25,
      "y": 9,
      "z": -3,
      "name": "Cloth_Block_Wool_Black"
    },
    {
      "x": -25,
      "y": 3,
      "z": -2,
      "name": "Cloth_Block_Wool_Blue"
    },
    {
      "x": -25,
      "y": 9,
      "z": -2,
      "name": "Cloth_Block_Wool_Black"
    },
    {
      "x": -25,
      "y": 3,
      "z": -1,
      "name": "Cloth_Block_Wool_Blue"
    },
    {
      "x": -25,
      "y": 9,
      "z": -1,
      "name": "Cloth_Block_Wool_Black"
    },
    {
      "x": -25,
      "y": 3,
      "z": 0,
      "name": "Cloth_Block_Wool_Blue"
    },
    {
      "x": -25,
      "y": 9,
      "z": 0,
      "name": "Cloth_Block_Wool_Black"
    },
    {
      "x": -25,
      "y": 3,
      "z": 1,
      "name": "Cloth_Block_Wool_Blue"
    },
    {
      "x": -25,
      "y": 9,
      "z": 1,
      "name": "Cloth_Block_Wool_Black"
    },
    {
      "x": -25,
      "y": 3,
      "z": 2,
      "name": "Cloth_Block_Wool_Blue"
    },
    {
      "x": -25,
      "y": 9,
      "z": 2,
      "name": "Cloth_Block_Wool_Black"
    },
    {
      "x": -25,
      "y": 3,
      "z": 3,
      "name": "Cloth_Block_Wool_Blue"
    },
    {
      "x": -25,
      "y": 9,
      "z": 3,
      "name": "Cloth_Block_Wool_Black"
    },
    {
      "x": -25,
      "y": 3,
      "z": 4,
      "name": "Cloth_Block_Wool_Blue"
    },
    {
      "x": -25,
      "y": 9,
      "z": 4,
      "name": "Cloth_Block_Wool_Black"
    },
    {
      "x": -25,
      "y": 3,
      "z": 5,
      "name": "Cloth_Block_Wool_Blue"
    },
    {
      "x": -25,
      "y": 9,
      "z": 5,
      "name": "Cloth_Block_Wool_Black"
    },
    {
      "x": -25,
      "y": 3,
      "z": 6,
      "name": "Cloth_Block_Wool_Blue"
    },
    {
      "x": -25,
      "y": 9,
      "z": 6,
      "name": "Cloth_Block_Wool_Black"
    },
    {
      "x": -25,
      "y": 3,
      "z": 7,
      "name": "Cloth_Block_Wool_Blue"
    },
    {
      "x": -25,
      "y": 9,
      "z": 7,
      "name": "Cloth_Block_Wool_Black"
    },
    {
      "x": -25,
      "y": 3,
      "z": 8,
      "name": "Cloth_Block_Wool_Blue"
    },
    {
      "x": -25,
      "y": 9,
      "z": 8,
      "name": "Cloth_Block_Wool_Black"
    },
    {
      "x": -25,
      "y": 3,
      "z": 9,
      "name": "Cloth_Block_Wool_Blue"
    },
    {
      "x": -25,
      "y": 9,
      "z": 9,
      "name": "Cloth_Block_Wool_Black"
    },
    {
      "x": -25,
      "y": 3,
      "z": 10,
      "name": "Cloth_Block_Wool_Blue"
    },
    {
      "x": -25,
      "y": 9,
      "z": 10,
      "name": "Cloth_Block_Wool_Black"
    },
    {
      "x": -25,
      "y": 3,
      "z": 11,
      "name": "Cloth_Block_Wool_Blue"
    },
    {
      "x": -25,
      "y": 9,
      "z": 11,
      "name": "Cloth_Block_Wool_Black"
    },
    {
      "x": -25,
      "y": 3,
      "z": 12,
      "name": "Cloth_Block_Wool_Blue"
    },
    {
      "x": -25,
      "y": 9,
      "z": 12,
      "name": "Cloth_Block_Wool_Black"
    },
    {
      "x": -25,
      "y": 3,
      "z": 13,
      "name": "Cloth_Block_Wool_Blue"
    },
    {
      "x": -25,
      "y": 9,
      "z": 13,
      "name": "Cloth_Block_Wool_Black"
    },
    {
      "x": -25,
      "y": 3,
      "z": 14,
      "name": "Cloth_Block_Wool_Blue"
    },
    {
      "x": -25,
      "y": 9,
      "z": 14,
      "name": "Cloth_Block_Wool_Black"
    },
    {
      "x": -25,
      "y": 3,
      "z": 15,
      "name": "Cloth_Block_Wool_Blue"
    },
    {
      "x": -25,
      "y": 9,
      "z": 15,
      "name": "Cloth_Block_Wool_Black"
    },
    {
      "x": -25,
      "y": 3,
      "z": 16,
      "name": "Cloth_Block_Wool_Blue"
    },
    {
      "x": -25,
      "y": 9,
      "z": 16,
      "name": "Cloth_Block_Wool_Black"
    },
    {
      "x": -25,
      "y": 3,
      "z": 17,
      "name": "Cloth_Block_Wool_Blue"
    },
    {
      "x": -25,
      "y": 9,
      "z": 17,
      "name": "Cloth_Block_Wool_Black"
    },
    {
      "x": -25,
      "y": 3,
      "z": 18,
      "name": "Cloth_Block_Wool_Blue"
    },
    {
      "x": -25,
      "y": 9,
      "z": 18,
      "name": "Cloth_Block_Wool_Black"
    },
    {
      "x": -25,
      "y": 3,
      "z": 19,
      "name": "Cloth_Block_Wool_Blue"
    },
    {
      "x": -25,
      "y": 9,
      "z": 19,
      "name": "Cloth_Block_Wool_Black"
    },
    {
      "x": -25,
      "y": 3,
      "z": 20,
      "name": "Cloth_Block_Wool_Blue"
    },
    {
      "x": -25,
      "y": 9,
      "z": 20,
      "name": "Cloth_Block_Wool_Black"
    },
    {
      "x": -25,
      "y": 3,
      "z": 21,
      "name": "Cloth_Block_Wool_Blue"
    },
    {
      "x": -25,
      "y": 9,
      "z": 21,
      "name": "Cloth_Block_Wool_Black"
    },
    {
      "x": -25,
      "y": 3,
      "z": 22,
      "name": "Cloth_Block_Wool_Blue"
    },
    {
      "x": -25,
      "y": 9,
      "z": 22,
      "name": "Cloth_Block_Wool_Black"
    },
    {
      "x": -25,
      "y": 3,
      "z": 23,
      "name": "Cloth_Block_Wool_Blue"
    },
    {
      "x": -25,
      "y": 9,
      "z": 23,
      "name": "Cloth_Block_Wool_Black"
    },
    {
      "x": -25,
      "y": 3,
      "z": 24,
      "name": "Cloth_Block_Wool_Black"
    },
    {
      "x": -25,
      "y": 9,
      "z": 24,
      "name": "Cloth_Block_Wool_Black"
    },
    {
      "x": -25,
      "y": 3,
      "z": 25,
      "name": "Cloth_Block_Wool_Black"
    },
    {
      "x": -25,
      "y": 4,
      "z": 25,
      "name": "Cloth_Block_Wool_Black"
    },
    {
      "x": -25,
      "y": 5,
      "z": 25,
      "name": "Cloth_Block_Wool_Black"
    },
    {
      "x": -25,
      "y": 6,
      "z": 25,
      "name": "Cloth_Block_Wool_Black"
    },
    {
      "x": -25,
      "y": 7,
      "z": 25,
      "name": "Cloth_Block_Wool_Black"
    },
    {
      "x": -25,
      "y": 8,
      "z": 25,
      "name": "Cloth_Block_Wool_Black"
    },
    {
      "x": -25,
      "y": 9,
      "z": 25,
      "name": "Cloth_Block_Wool_Black"
    },
    {
      "x": -24,
      "y": 3,
      "z": -25,
      "name": "Cloth_Block_Wool_Black"
    },
    {
      "x": -24,
      "y": 4,
      "z": -25,
      "name": "Cloth_Block_Wool_Black"
    },
    {
      "x": -24,
      "y": 5,
      "z": -25,
      "name": "Cloth_Block_Wool_Black"
    },
    {
      "x": -24,
      "y": 6,
      "z": -25,
      "name": "Cloth_Block_Wool_Black"
    },
    {
      "x": -24,
      "y": 7,
      "z": -25,
      "name": "Cloth_Block_Wool_Black"
    },
    {
      "x": -24,
      "y": 8,
      "z": -25,
      "name": "Cloth_Block_Wool_Black"
    },
    {
      "x": -24,
      "y": 9,
      "z": -25,
      "name": "Cloth_Block_Wool_Black"
    },
    {
      "x": -24,
      "y": 3,
      "z": -24,
      "name": "Cloth_Block_Wool_Black"
    },
    {
      "x": -24,
      "y": 9,
      "z": -24,
      "name": "Cloth_Block_Wool_Black"
    },
    {
      "x": -24,
      "y": 2,
      "z": -23,
      "name": "Cloth_Block_Wool_Black"
    },
    {
      "x": -24,
      "y": 3,
      "z": -23,
      "name": "Cloth_Block_Wool_Blue"
    },
    {
      "x": -24,
      "y": 9,
      "z": -23,
      "name": "Cloth_Block_Wool_Black"
    },
    {
      "x": -24,
      "y": 1,
      "z": -22,
      "name": "Cloth_Block_Wool_Black"
    },
    {
      "x": -24,
      "y": 2,
      "z": -22,
      "name": "Cloth_Block_Wool_Black"
    },
    {
      "x": -24,
      "y": 3,
      "z": -22,
      "name": "Cloth_Block_Wool_Blue"
    },
    {
      "x": -24,
      "y": 9,
      "z": -22,
      "name": "Cloth_Block_Wool_Black"
    },
    {
      "x": -24,
      "y": 2,
      "z": -21,
      "name": "Cloth_Block_Wool_Black"
    },
    {
      "x": -24,
      "y": 3,
      "z": -21,
      "name": "Cloth_Block_Wool_Blue"
    },
    {
      "x": -24,
      "y": 9,
      "z": -21,
      "name": "Cloth_Block_Wool_Black"
    },
    {
      "x": -24,
      "y": 3,
      "z": -20,
      "name": "Cloth_Block_Wool_Blue"
    },
    {
      "x": -24,
      "y": 9,
      "z": -20,
      "name": "Cloth_Block_Wool_Black"
    },
    {
      "x": -24,
      "y": 3,
      "z": -19,
      "name": "Cloth_Block_Wool_Blue"
    },
    {
      "x": -24,
      "y": 9,
      "z": -19,
      "name": "Cloth_Block_Wool_Black"
    },
    {
      "x": -24,
      "y": 3,
      "z": -18,
      "name": "Cloth_Block_Wool_Blue"
    },
    {
      "x": -24,
      "y": 9,
      "z": -18,
      "name": "Cloth_Block_Wool_Black"
    },
    {
      "x": -24,
      "y": 3,
      "z": -17,
      "name": "Cloth_Block_Wool_Blue"
    },
    {
      "x": -24,
      "y": 9,
      "z": -17,
      "name": "Cloth_Block_Wool_Black"
    },
    {
      "x": -24,
      "y": 3,
      "z": -16,
      "name": "Cloth_Block_Wool_Blue"
    },
    {
      "x": -24,
      "y": 9,
      "z": -16,
      "name": "Cloth_Block_Wool_Black"
    },
    {
      "x": -24,
      "y": 3,
      "z": -15,
      "name": "Cloth_Block_Wool_Blue"
    },
    {
      "x": -24,
      "y": 9,
      "z": -15,
      "name": "Cloth_Block_Wool_Black"
    },
    {
      "x": -24,
      "y": 3,
      "z": -14,
      "name": "Cloth_Block_Wool_Blue"
    },
    {
      "x": -24,
      "y": 9,
      "z": -14,
      "name": "Cloth_Block_Wool_Black"
    },
    {
      "x": -24,
      "y": 3,
      "z": -13,
      "name": "Cloth_Block_Wool_Blue"
    },
    {
      "x": -24,
      "y": 9,
      "z": -13,
      "name": "Cloth_Block_Wool_Black"
    },
    {
      "x": -24,
      "y": 3,
      "z": -12,
      "name": "Cloth_Block_Wool_Blue"
    },
    {
      "x": -24,
      "y": 9,
      "z": -12,
      "name": "Cloth_Block_Wool_Black"
    },
    {
      "x": -24,
      "y": 3,
      "z": -11,
      "name": "Cloth_Block_Wool_Blue"
    },
    {
      "x": -24,
      "y": 9,
      "z": -11,
      "name": "Cloth_Block_Wool_Black"
    },
    {
      "x": -24,
      "y": 3,
      "z": -10,
      "name": "Cloth_Block_Wool_Blue"
    },
    {
      "x": -24,
      "y": 9,
      "z": -10,
      "name": "Cloth_Block_Wool_Black"
    },
    {
      "x": -24,
      "y": 3,
      "z": -9,
      "name": "Cloth_Block_Wool_Blue"
    },
    {
      "x": -24,
      "y": 9,
      "z": -9,
      "name": "Cloth_Block_Wool_Black"
    },
    {
      "x": -24,
      "y": 3,
      "z": -8,
      "name": "Cloth_Block_Wool_Blue"
    },
    {
      "x": -24,
      "y": 9,
      "z": -8,
      "name": "Cloth_Block_Wool_Black"
    },
    {
      "x": -24,
      "y": 3,
      "z": -7,
      "name": "Cloth_Block_Wool_Blue"
    },
    {
      "x": -24,
      "y": 9,
      "z": -7,
      "name": "Cloth_Block_Wool_Black"
    },
    {
      "x": -24,
      "y": 3,
      "z": -6,
      "name": "Cloth_Block_Wool_Blue"
    },
    {
      "x": -24,
      "y": 9,
      "z": -6,
      "name": "Cloth_Block_Wool_Black"
    },
    {
      "x": -24,
      "y": 3,
      "z": -5,
      "name": "Cloth_Block_Wool_Blue"
    },
    {
      "x": -24,
      "y": 9,
      "z": -5,
      "name": "Cloth_Block_Wool_Black"
    },
    {
      "x": -24,
      "y": 3,
      "z": -4,
      "name": "Cloth_Block_Wool_Blue"
    },
    {
      "x": -24,
      "y": 9,
      "z": -4,
      "name": "Cloth_Block_Wool_Black"
    },
    {
      "x": -24,
      "y": 3,
      "z": -3,
      "name": "Cloth_Block_Wool_Blue"
    },
    {
      "x": -24,
      "y": 9,
      "z": -3,
      "name": "Cloth_Block_Wool_Black"
    },
    {
      "x": -24,
      "y": 3,
      "z": -2,
      "name": "Cloth_Block_Wool_Blue"
    },
    {
      "x": -24,
      "y": 9,
      "z": -2,
      "name": "Cloth_Block_Wool_Black"
    },
    {
      "x": -24,
      "y": 2,
      "z": -1,
      "name": "Cloth_Block_Wool_Black"
    },
    {
      "x": -24,
      "y": 3,
      "z": -1,
      "name": "Cloth_Block_Wool_Blue"
    },
    {
      "x": -24,
      "y": 9,
      "z": -1,
      "name": "Cloth_Block_Wool_Black"
    },
    {
      "x": -24,
      "y": 1,
      "z": 0,
      "name": "Cloth_Block_Wool_Black"
    },
    {
      "x": -24,
      "y": 2,
      "z": 0,
      "name": "Cloth_Block_Wool_Black"
    },
    {
      "x": -24,
      "y": 3,
      "z": 0,
      "name": "Cloth_Block_Wool_Blue"
    },
    {
      "x": -24,
      "y": 9,
      "z": 0,
      "name": "Cloth_Block_Wool_Black"
    },
    {
      "x": -24,
      "y": 2,
      "z": 1,
      "name": "Cloth_Block_Wool_Black"
    },
    {
      "x": -24,
      "y": 3,
      "z": 1,
      "name": "Cloth_Block_Wool_Blue"
    },
    {
      "x": -24,
      "y": 9,
      "z": 1,
      "name": "Cloth_Block_Wool_Black"
    },
    {
      "x": -24,
      "y": 3,
      "z": 2,
      "name": "Cloth_Block_Wool_Blue"
    },
    {
      "x": -24,
      "y": 9,
      "z": 2,
      "name": "Cloth_Block_Wool_Black"
    },
    {
      "x": -24,
      "y": 3,
      "z": 3,
      "name": "Cloth_Block_Wool_Blue"
    },
    {
      "x": -24,
      "y": 9,
      "z": 3,
      "name": "Cloth_Block_Wool_Black"
    },
    {
      "x": -24,
      "y": 3,
      "z": 4,
      "name": "Cloth_Block_Wool_Blue"
    },
    {
      "x": -24,
      "y": 9,
      "z": 4,
      "name": "Cloth_Block_Wool_Black"
    },
    {
      "x": -24,
      "y": 3,
      "z": 5,
      "name": "Cloth_Block_Wool_Blue"
    },
    {
      "x": -24,
      "y": 9,
      "z": 5,
      "name": "Cloth_Block_Wool_Black"
    },
    {
      "x": -24,
      "y": 3,
      "z": 6,
      "name": "Cloth_Block_Wool_Blue"
    },
    {
      "x": -24,
      "y": 9,
      "z": 6,
      "name": "Cloth_Block_Wool_Black"
    },
    {
      "x": -24,
      "y": 3,
      "z": 7,
      "name": "Cloth_Block_Wool_Blue"
    },
    {
      "x": -24,
      "y": 9,
      "z": 7,
      "name": "Cloth_Block_Wool_Black"
    },
    {
      "x": -24,
      "y": 3,
      "z": 8,
      "name": "Cloth_Block_Wool_Blue"
    },
    {
      "x": -24,
      "y": 9,
      "z": 8,
      "name": "Cloth_Block_Wool_Black"
    },
    {
      "x": -24,
      "y": 3,
      "z": 9,
      "name": "Cloth_Block_Wool_Blue"
    },
    {
      "x": -24,
      "y": 9,
      "z": 9,
      "name": "Cloth_Block_Wool_Black"
    },
    {
      "x": -24,
      "y": 3,
      "z": 10,
      "name": "Cloth_Block_Wool_Blue"
    },
    {
      "x": -24,
      "y": 9,
      "z": 10,
      "name": "Cloth_Block_Wool_Black"
    },
    {
      "x": -24,
      "y": 3,
      "z": 11,
      "name": "Cloth_Block_Wool_Blue"
    },
    {
      "x": -24,
      "y": 9,
      "z": 11,
      "name": "Cloth_Block_Wool_Black"
    },
    {
      "x": -24,
      "y": 3,
      "z": 12,
      "name": "Cloth_Block_Wool_Blue"
    },
    {
      "x": -24,
      "y": 9,
      "z": 12,
      "name": "Cloth_Block_Wool_Black"
    },
    {
      "x": -24,
      "y": 3,
      "z": 13,
      "name": "Cloth_Block_Wool_Blue"
    },
    {
      "x": -24,
      "y": 9,
      "z": 13,
      "name": "Cloth_Block_Wool_Black"
    },
    {
      "x": -24,
      "y": 3,
      "z": 14,
      "name": "Cloth_Block_Wool_Blue"
    },
    {
      "x": -24,
      "y": 9,
      "z": 14,
      "name": "Cloth_Block_Wool_Black"
    },
    {
      "x": -24,
      "y": 3,
      "z": 15,
      "name": "Cloth_Block_Wool_Blue"
    },
    {
      "x": -24,
      "y": 9,
      "z": 15,
      "name": "Cloth_Block_Wool_Black"
    },
    {
      "x": -24,
      "y": 3,
      "z": 16,
      "name": "Cloth_Block_Wool_Blue"
    },
    {
      "x": -24,
      "y": 9,
      "z": 16,
      "name": "Cloth_Block_Wool_Black"
    },
    {
      "x": -24,
      "y": 3,
      "z": 17,
      "name": "Cloth_Block_Wool_Blue"
    },
    {
      "x": -24,
      "y": 9,
      "z": 17,
      "name": "Cloth_Block_Wool_Black"
    },
    {
      "x": -24,
      "y": 3,
      "z": 18,
      "name": "Cloth_Block_Wool_Blue"
    },
    {
      "x": -24,
      "y": 9,
      "z": 18,
      "name": "Cloth_Block_Wool_Black"
    },
    {
      "x": -24,
      "y": 3,
      "z": 19,
      "name": "Cloth_Block_Wool_Blue"
    },
    {
      "x": -24,
      "y": 9,
      "z": 19,
      "name": "Cloth_Block_Wool_Black"
    },
    {
      "x": -24,
      "y": 3,
      "z": 20,
      "name": "Cloth_Block_Wool_Blue"
    },
    {
      "x": -24,
      "y": 9,
      "z": 20,
      "name": "Cloth_Block_Wool_Black"
    },
    {
      "x": -24,
      "y": 3,
      "z": 21,
      "name": "Cloth_Block_Wool_Blue"
    },
    {
      "x": -24,
      "y": 9,
      "z": 21,
      "name": "Cloth_Block_Wool_Black"
    },
    {
      "x": -24,
      "y": 2,
      "z": 22,
      "name": "Cloth_Block_Wool_Black"
    },
    {
      "x": -24,
      "y": 3,
      "z": 22,
      "name": "Cloth_Block_Wool_Blue"
    },
    {
      "x": -24,
      "y": 9,
      "z": 22,
      "name": "Cloth_Block_Wool_Black"
    },
    {
      "x": -24,
      "y": 2,
      "z": 23,
      "name": "Cloth_Block_Wool_Black"
    },
    {
      "x": -24,
      "y": 3,
      "z": 23,
      "name": "Cloth_Block_Wool_Blue"
    },
    {
      "x": -24,
      "y": 9,
      "z": 23,
      "name": "Cloth_Block_Wool_Black"
    },
    {
      "x": -24,
      "y": 3,
      "z": 24,
      "name": "Cloth_Block_Wool_Black"
    },
    {
      "x": -24,
      "y": 9,
      "z": 24,
      "name": "Cloth_Block_Wool_Black"
    },
    {
      "x": -24,
      "y": 3,
      "z": 25,
      "name": "Cloth_Block_Wool_Black"
    },
    {
      "x": -24,
      "y": 4,
      "z": 25,
      "name": "Cloth_Block_Wool_Black"
    },
    {
      "x": -24,
      "y": 5,
      "z": 25,
      "name": "Cloth_Block_Wool_Black"
    },
    {
      "x": -24,
      "y": 6,
      "z": 25,
      "name": "Cloth_Block_Wool_Black"
    },
    {
      "x": -24,
      "y": 7,
      "z": 25,
      "name": "Cloth_Block_Wool_Black"
    },
    {
      "x": -24,
      "y": 8,
      "z": 25,
      "name": "Cloth_Block_Wool_Black"
    },
    {
      "x": -24,
      "y": 9,
      "z": 25,
      "name": "Cloth_Block_Wool_Black"
    },
    {
      "x": -23,
      "y": 3,
      "z": -25,
      "name": "Cloth_Block_Wool_Black"
    },
    {
      "x": -23,
      "y": 4,
      "z": -25,
      "name": "Cloth_Block_Wool_Black"
    },
    {
      "x": -23,
      "y": 5,
      "z": -25,
      "name": "Cloth_Block_Wool_Black"
    },
    {
      "x": -23,
      "y": 6,
      "z": -25,
      "name": "Cloth_Block_Wool_Black"
    },
    {
      "x": -23,
      "y": 7,
      "z": -25,
      "name": "Cloth_Block_Wool_Black"
    },
    {
      "x": -23,
      "y": 8,
      "z": -25,
      "name": "Cloth_Block_Wool_Black"
    },
    {
      "x": -23,
      "y": 9,
      "z": -25,
      "name": "Cloth_Block_Wool_Black"
    },
    {
      "x": -23,
      "y": 3,
      "z": -24,
      "name": "Cloth_Block_Wool_Black"
    },
    {
      "x": -23,
      "y": 9,
      "z": -24,
      "name": "Cloth_Block_Wool_Black"
    },
    {
      "x": -23,
      "y": 2,
      "z": -23,
      "name": "Cloth_Block_Wool_Black"
    },
    {
      "x": -23,
      "y": 3,
      "z": -23,
      "name": "Cloth_Block_Wool_Black"
    },
    {
      "x": -23,
      "y": 9,
      "z": -23,
      "name": "Cloth_Block_Wool_Black"
    },
    {
      "x": -23,
      "y": 1,
      "z": -22,
      "name": "Cloth_Block_Wool_Black"
    },
    {
      "x": -23,
      "y": 2,
      "z": -22,
      "name": "Blue_Led_Beam",
      "rotation": 5
    },
    {
      "x": -23,
      "y": 3,
      "z": -22,
      "name": "Cloth_Block_Wool_Black"
    },
    {
      "x": -23,
      "y": 9,
      "z": -22,
      "name": "Cloth_Block_Wool_Black"
    },
    {
      "x": -23,
      "y": 2,
      "z": -21,
      "name": "Cloth_Block_Wool_Black"
    },
    {
      "x": -23,
      "y": 3,
      "z": -21,
      "name": "Cloth_Block_Wool_Black"
    },
    {
      "x": -23,
      "y": 9,
      "z": -21,
      "name": "Cloth_Block_Wool_Black"
    },
    {
      "x": -23,
      "y": 3,
      "z": -20,
      "name": "Cloth_Block_Wool_Black"
    },
    {
      "x": -23,
      "y": 9,
      "z": -20,
      "name": "Cloth_Block_Wool_Black"
    },
    {
      "x": -23,
      "y": 3,
      "z": -19,
      "name": "Cloth_Block_Wool_Black"
    },
    {
      "x": -23,
      "y": 9,
      "z": -19,
      "name": "Cloth_Block_Wool_Black"
    },
    {
      "x": -23,
      "y": 3,
      "z": -18,
      "name": "Cloth_Block_Wool_Black"
    },
    {
      "x": -23,
      "y": 9,
      "z": -18,
      "name": "Cloth_Block_Wool_Black"
    },
    {
      "x": -23,
      "y": 3,
      "z": -17,
      "name": "Cloth_Block_Wool_Black"
    },
    {
      "x": -23,
      "y": 9,
      "z": -17,
      "name": "Cloth_Block_Wool_Black"
    },
    {
      "x": -23,
      "y": 3,
      "z": -16,
      "name": "Cloth_Block_Wool_Black"
    },
    {
      "x": -23,
      "y": 9,
      "z": -16,
      "name": "Cloth_Block_Wool_Black"
    },
    {
      "x": -23,
      "y": 3,
      "z": -15,
      "name": "Cloth_Block_Wool_Black"
    },
    {
      "x": -23,
      "y": 9,
      "z": -15,
      "name": "Cloth_Block_Wool_Black"
    },
    {
      "x": -23,
      "y": 3,
      "z": -14,
      "name": "Cloth_Block_Wool_Black"
    },
    {
      "x": -23,
      "y": 9,
      "z": -14,
      "name": "Cloth_Block_Wool_Black"
    },
    {
      "x": -23,
      "y": 3,
      "z": -13,
      "name": "Cloth_Block_Wool_Black"
    },
    {
      "x": -23,
      "y": 9,
      "z": -13,
      "name": "Cloth_Block_Wool_Black"
    },
    {
      "x": -23,
      "y": 3,
      "z": -12,
      "name": "Cloth_Block_Wool_Black"
    },
    {
      "x": -23,
      "y": 9,
      "z": -12,
      "name": "Cloth_Block_Wool_Black"
    },
    {
      "x": -23,
      "y": 3,
      "z": -11,
      "name": "Cloth_Block_Wool_Black"
    },
    {
      "x": -23,
      "y": 9,
      "z": -11,
      "name": "Cloth_Block_Wool_Black"
    },
    {
      "x": -23,
      "y": 3,
      "z": -10,
      "name": "Cloth_Block_Wool_Black"
    },
    {
      "x": -23,
      "y": 9,
      "z": -10,
      "name": "Cloth_Block_Wool_Black"
    },
    {
      "x": -23,
      "y": 3,
      "z": -9,
      "name": "Cloth_Block_Wool_Black"
    },
    {
      "x": -23,
      "y": 9,
      "z": -9,
      "name": "Cloth_Block_Wool_Black"
    },
    {
      "x": -23,
      "y": 3,
      "z": -8,
      "name": "Cloth_Block_Wool_Black"
    },
    {
      "x": -23,
      "y": 9,
      "z": -8,
      "name": "Cloth_Block_Wool_Black"
    },
    {
      "x": -23,
      "y": 3,
      "z": -7,
      "name": "Cloth_Block_Wool_Black"
    },
    {
      "x": -23,
      "y": 9,
      "z": -7,
      "name": "Cloth_Block_Wool_Black"
    },
    {
      "x": -23,
      "y": 3,
      "z": -6,
      "name": "Cloth_Block_Wool_Black"
    },
    {
      "x": -23,
      "y": 9,
      "z": -6,
      "name": "Cloth_Block_Wool_Black"
    },
    {
      "x": -23,
      "y": 3,
      "z": -5,
      "name": "Cloth_Block_Wool_Black"
    },
    {
      "x": -23,
      "y": 9,
      "z": -5,
      "name": "Cloth_Block_Wool_Black"
    },
    {
      "x": -23,
      "y": 3,
      "z": -4,
      "name": "Cloth_Block_Wool_Black"
    },
    {
      "x": -23,
      "y": 9,
      "z": -4,
      "name": "Cloth_Block_Wool_Black"
    },
    {
      "x": -23,
      "y": 3,
      "z": -3,
      "name": "Cloth_Block_Wool_Black"
    },
    {
      "x": -23,
      "y": 9,
      "z": -3,
      "name": "Cloth_Block_Wool_Black"
    },
    {
      "x": -23,
      "y": 3,
      "z": -2,
      "name": "Cloth_Block_Wool_Black"
    },
    {
      "x": -23,
      "y": 9,
      "z": -2,
      "name": "Cloth_Block_Wool_Black"
    },
    {
      "x": -23,
      "y": 2,
      "z": -1,
      "name": "Cloth_Block_Wool_Black"
    },
    {
      "x": -23,
      "y": 3,
      "z": -1,
      "name": "Cloth_Block_Wool_Black"
    },
    {
      "x": -23,
      "y": 9,
      "z": -1,
      "name": "Cloth_Block_Wool_Black"
    },
    {
      "x": -23,
      "y": 1,
      "z": 0,
      "name": "Cloth_Block_Wool_Black"
    },
    {
      "x": -23,
      "y": 2,
      "z": 0,
      "name": "Blue_Led_Beam",
      "rotation": 5
    },
    {
